[2021-09-05 22:13:27.029 DEBUG     yangsuite.ysdevices.devprofile : 184]
Device profile list (filter: None): [{'name': 'CiscoIOSXR', 'key': 'ciscoiosxr', 'description': 'WJ'}]
[2021-09-05 22:16:23.514 DEBUG     yangsuite.ysdevices.devprofile : 184]
Device profile list (filter: None): [{'name': 'CiscoIOSXR', 'key': 'ciscoiosxr', 'description': 'WJ'}]
[2021-09-05 22:16:46.569 DEBUG                    django.template : 878]
Exception while resolving variable 'min' in template 'ysdevices/device_form.html'.
Traceback (most recent call last):
  File "/usr/local/lib/python3.6/dist-packages/django/template/base.py", line 835, in _resolve_lookup
    current = current[bit]
KeyError: 'min'

During handling of the above exception, another exception occurred:

Traceback (most recent call last):
  File "/usr/local/lib/python3.6/dist-packages/django/template/base.py", line 843, in _resolve_lookup
    current = getattr(current, bit)
AttributeError: 'dict' object has no attribute 'min'

During handling of the above exception, another exception occurred:

Traceback (most recent call last):
  File "/usr/local/lib/python3.6/dist-packages/django/template/base.py", line 849, in _resolve_lookup
    current = current[int(bit)]
ValueError: invalid literal for int() with base 10: 'min'

During handling of the above exception, another exception occurred:

Traceback (most recent call last):
  File "/usr/local/lib/python3.6/dist-packages/django/template/base.py", line 856, in _resolve_lookup
    (bit, current))  # missing attribute
django.template.base.VariableDoesNotExist: Failed lookup for key [min] in {'label': 'Profile Name', 'type': 'string', 'description': 'Name of this device profile', 'minLength': 1, 'required': True, 'default': 'CiscoIOSXR'}
[2021-09-05 22:16:46.573 DEBUG                    django.template : 878]
Exception while resolving variable 'max' in template 'ysdevices/device_form.html'.
Traceback (most recent call last):
  File "/usr/local/lib/python3.6/dist-packages/django/template/base.py", line 835, in _resolve_lookup
    current = current[bit]
KeyError: 'max'

During handling of the above exception, another exception occurred:

Traceback (most recent call last):
  File "/usr/local/lib/python3.6/dist-packages/django/template/base.py", line 843, in _resolve_lookup
    current = getattr(current, bit)
AttributeError: 'dict' object has no attribute 'max'

During handling of the above exception, another exception occurred:

Traceback (most recent call last):
  File "/usr/local/lib/python3.6/dist-packages/django/template/base.py", line 849, in _resolve_lookup
    current = current[int(bit)]
ValueError: invalid literal for int() with base 10: 'max'

During handling of the above exception, another exception occurred:

Traceback (most recent call last):
  File "/usr/local/lib/python3.6/dist-packages/django/template/base.py", line 856, in _resolve_lookup
    (bit, current))  # missing attribute
django.template.base.VariableDoesNotExist: Failed lookup for key [max] in {'label': 'Profile Name', 'type': 'string', 'description': 'Name of this device profile', 'minLength': 1, 'required': True, 'default': 'CiscoIOSXR'}
[2021-09-05 22:16:46.573 DEBUG                    django.template : 878]
Exception while resolving variable 'maxLength' in template 'ysdevices/device_form.html'.
Traceback (most recent call last):
  File "/usr/local/lib/python3.6/dist-packages/django/template/base.py", line 835, in _resolve_lookup
    current = current[bit]
KeyError: 'maxLength'

During handling of the above exception, another exception occurred:

Traceback (most recent call last):
  File "/usr/local/lib/python3.6/dist-packages/django/template/base.py", line 843, in _resolve_lookup
    current = getattr(current, bit)
AttributeError: 'dict' object has no attribute 'maxLength'

During handling of the above exception, another exception occurred:

Traceback (most recent call last):
  File "/usr/local/lib/python3.6/dist-packages/django/template/base.py", line 849, in _resolve_lookup
    current = current[int(bit)]
ValueError: invalid literal for int() with base 10: 'maxLength'

During handling of the above exception, another exception occurred:

Traceback (most recent call last):
  File "/usr/local/lib/python3.6/dist-packages/django/template/base.py", line 856, in _resolve_lookup
    (bit, current))  # missing attribute
django.template.base.VariableDoesNotExist: Failed lookup for key [maxLength] in {'label': 'Profile Name', 'type': 'string', 'description': 'Name of this device profile', 'minLength': 1, 'required': True, 'default': 'CiscoIOSXR'}
[2021-09-05 22:16:46.575 DEBUG                    django.template : 878]
Exception while resolving variable 'step' in template 'ysdevices/device_form.html'.
Traceback (most recent call last):
  File "/usr/local/lib/python3.6/dist-packages/django/template/base.py", line 835, in _resolve_lookup
    current = current[bit]
KeyError: 'step'

During handling of the above exception, another exception occurred:

Traceback (most recent call last):
  File "/usr/local/lib/python3.6/dist-packages/django/template/base.py", line 843, in _resolve_lookup
    current = getattr(current, bit)
AttributeError: 'dict' object has no attribute 'step'

During handling of the above exception, another exception occurred:

Traceback (most recent call last):
  File "/usr/local/lib/python3.6/dist-packages/django/template/base.py", line 849, in _resolve_lookup
    current = current[int(bit)]
ValueError: invalid literal for int() with base 10: 'step'

During handling of the above exception, another exception occurred:

Traceback (most recent call last):
  File "/usr/local/lib/python3.6/dist-packages/django/template/base.py", line 856, in _resolve_lookup
    (bit, current))  # missing attribute
django.template.base.VariableDoesNotExist: Failed lookup for key [step] in {'label': 'Profile Name', 'type': 'string', 'description': 'Name of this device profile', 'minLength': 1, 'required': True, 'default': 'CiscoIOSXR'}
[2021-09-05 22:16:46.575 DEBUG                    django.template : 878]
Exception while resolving variable 'min' in template 'ysdevices/device_form.html'.
Traceback (most recent call last):
  File "/usr/local/lib/python3.6/dist-packages/django/template/base.py", line 835, in _resolve_lookup
    current = current[bit]
KeyError: 'min'

During handling of the above exception, another exception occurred:

Traceback (most recent call last):
  File "/usr/local/lib/python3.6/dist-packages/django/template/base.py", line 843, in _resolve_lookup
    current = getattr(current, bit)
AttributeError: 'dict' object has no attribute 'min'

During handling of the above exception, another exception occurred:

Traceback (most recent call last):
  File "/usr/local/lib/python3.6/dist-packages/django/template/base.py", line 849, in _resolve_lookup
    current = current[int(bit)]
ValueError: invalid literal for int() with base 10: 'min'

During handling of the above exception, another exception occurred:

Traceback (most recent call last):
  File "/usr/local/lib/python3.6/dist-packages/django/template/base.py", line 856, in _resolve_lookup
    (bit, current))  # missing attribute
django.template.base.VariableDoesNotExist: Failed lookup for key [min] in {'type': 'string', 'description': 'Verbose description', 'default': 'WJ'}
[2021-09-05 22:16:46.575 DEBUG                    django.template : 878]
Exception while resolving variable 'minLength' in template 'ysdevices/device_form.html'.
Traceback (most recent call last):
  File "/usr/local/lib/python3.6/dist-packages/django/template/base.py", line 835, in _resolve_lookup
    current = current[bit]
KeyError: 'minLength'

During handling of the above exception, another exception occurred:

Traceback (most recent call last):
  File "/usr/local/lib/python3.6/dist-packages/django/template/base.py", line 843, in _resolve_lookup
    current = getattr(current, bit)
AttributeError: 'dict' object has no attribute 'minLength'

During handling of the above exception, another exception occurred:

Traceback (most recent call last):
  File "/usr/local/lib/python3.6/dist-packages/django/template/base.py", line 849, in _resolve_lookup
    current = current[int(bit)]
ValueError: invalid literal for int() with base 10: 'minLength'

During handling of the above exception, another exception occurred:

Traceback (most recent call last):
  File "/usr/local/lib/python3.6/dist-packages/django/template/base.py", line 856, in _resolve_lookup
    (bit, current))  # missing attribute
django.template.base.VariableDoesNotExist: Failed lookup for key [minLength] in {'type': 'string', 'description': 'Verbose description', 'default': 'WJ'}
[2021-09-05 22:16:46.576 DEBUG                    django.template : 878]
Exception while resolving variable 'max' in template 'ysdevices/device_form.html'.
Traceback (most recent call last):
  File "/usr/local/lib/python3.6/dist-packages/django/template/base.py", line 835, in _resolve_lookup
    current = current[bit]
KeyError: 'max'

During handling of the above exception, another exception occurred:

Traceback (most recent call last):
  File "/usr/local/lib/python3.6/dist-packages/django/template/base.py", line 843, in _resolve_lookup
    current = getattr(current, bit)
AttributeError: 'dict' object has no attribute 'max'

During handling of the above exception, another exception occurred:

Traceback (most recent call last):
  File "/usr/local/lib/python3.6/dist-packages/django/template/base.py", line 849, in _resolve_lookup
    current = current[int(bit)]
ValueError: invalid literal for int() with base 10: 'max'

During handling of the above exception, another exception occurred:

Traceback (most recent call last):
  File "/usr/local/lib/python3.6/dist-packages/django/template/base.py", line 856, in _resolve_lookup
    (bit, current))  # missing attribute
django.template.base.VariableDoesNotExist: Failed lookup for key [max] in {'type': 'string', 'description': 'Verbose description', 'default': 'WJ'}
[2021-09-05 22:16:46.576 DEBUG                    django.template : 878]
Exception while resolving variable 'maxLength' in template 'ysdevices/device_form.html'.
Traceback (most recent call last):
  File "/usr/local/lib/python3.6/dist-packages/django/template/base.py", line 835, in _resolve_lookup
    current = current[bit]
KeyError: 'maxLength'

During handling of the above exception, another exception occurred:

Traceback (most recent call last):
  File "/usr/local/lib/python3.6/dist-packages/django/template/base.py", line 843, in _resolve_lookup
    current = getattr(current, bit)
AttributeError: 'dict' object has no attribute 'maxLength'

During handling of the above exception, another exception occurred:

Traceback (most recent call last):
  File "/usr/local/lib/python3.6/dist-packages/django/template/base.py", line 849, in _resolve_lookup
    current = current[int(bit)]
ValueError: invalid literal for int() with base 10: 'maxLength'

During handling of the above exception, another exception occurred:

Traceback (most recent call last):
  File "/usr/local/lib/python3.6/dist-packages/django/template/base.py", line 856, in _resolve_lookup
    (bit, current))  # missing attribute
django.template.base.VariableDoesNotExist: Failed lookup for key [maxLength] in {'type': 'string', 'description': 'Verbose description', 'default': 'WJ'}
[2021-09-05 22:16:46.576 DEBUG                    django.template : 878]
Exception while resolving variable 'step' in template 'ysdevices/device_form.html'.
Traceback (most recent call last):
  File "/usr/local/lib/python3.6/dist-packages/django/template/base.py", line 835, in _resolve_lookup
    current = current[bit]
KeyError: 'step'

During handling of the above exception, another exception occurred:

Traceback (most recent call last):
  File "/usr/local/lib/python3.6/dist-packages/django/template/base.py", line 843, in _resolve_lookup
    current = getattr(current, bit)
AttributeError: 'dict' object has no attribute 'step'

During handling of the above exception, another exception occurred:

Traceback (most recent call last):
  File "/usr/local/lib/python3.6/dist-packages/django/template/base.py", line 849, in _resolve_lookup
    current = current[int(bit)]
ValueError: invalid literal for int() with base 10: 'step'

During handling of the above exception, another exception occurred:

Traceback (most recent call last):
  File "/usr/local/lib/python3.6/dist-packages/django/template/base.py", line 856, in _resolve_lookup
    (bit, current))  # missing attribute
django.template.base.VariableDoesNotExist: Failed lookup for key [step] in {'type': 'string', 'description': 'Verbose description', 'default': 'WJ'}
[2021-09-05 22:16:46.576 DEBUG                    django.template : 878]
Exception while resolving variable 'required' in template 'ysdevices/device_form.html'.
Traceback (most recent call last):
  File "/usr/local/lib/python3.6/dist-packages/django/template/base.py", line 835, in _resolve_lookup
    current = current[bit]
KeyError: 'required'

During handling of the above exception, another exception occurred:

Traceback (most recent call last):
  File "/usr/local/lib/python3.6/dist-packages/django/template/base.py", line 843, in _resolve_lookup
    current = getattr(current, bit)
AttributeError: 'dict' object has no attribute 'required'

During handling of the above exception, another exception occurred:

Traceback (most recent call last):
  File "/usr/local/lib/python3.6/dist-packages/django/template/base.py", line 849, in _resolve_lookup
    current = current[int(bit)]
ValueError: invalid literal for int() with base 10: 'required'

During handling of the above exception, another exception occurred:

Traceback (most recent call last):
  File "/usr/local/lib/python3.6/dist-packages/django/template/base.py", line 856, in _resolve_lookup
    (bit, current))  # missing attribute
django.template.base.VariableDoesNotExist: Failed lookup for key [required] in {'type': 'string', 'description': 'Verbose description', 'default': 'WJ'}
[2021-09-05 22:16:46.577 DEBUG                    django.template : 878]
Exception while resolving variable 'label' in template 'ysdevices/device_form.html'.
Traceback (most recent call last):
  File "/usr/local/lib/python3.6/dist-packages/django/template/base.py", line 835, in _resolve_lookup
    current = current[bit]
KeyError: 'label'

During handling of the above exception, another exception occurred:

Traceback (most recent call last):
  File "/usr/local/lib/python3.6/dist-packages/django/template/base.py", line 843, in _resolve_lookup
    current = getattr(current, bit)
AttributeError: 'dict' object has no attribute 'label'

During handling of the above exception, another exception occurred:

Traceback (most recent call last):
  File "/usr/local/lib/python3.6/dist-packages/django/template/base.py", line 849, in _resolve_lookup
    current = current[int(bit)]
ValueError: invalid literal for int() with base 10: 'label'

During handling of the above exception, another exception occurred:

Traceback (most recent call last):
  File "/usr/local/lib/python3.6/dist-packages/django/template/base.py", line 856, in _resolve_lookup
    (bit, current))  # missing attribute
django.template.base.VariableDoesNotExist: Failed lookup for key [label] in {'type': 'string', 'description': 'Verbose description', 'default': 'WJ'}
[2021-09-05 22:16:46.577 DEBUG                    django.template : 878]
Exception while resolving variable 'required' in template 'ysdevices/device_form.html'.
Traceback (most recent call last):
  File "/usr/local/lib/python3.6/dist-packages/django/template/base.py", line 835, in _resolve_lookup
    current = current[bit]
KeyError: 'required'

During handling of the above exception, another exception occurred:

Traceback (most recent call last):
  File "/usr/local/lib/python3.6/dist-packages/django/template/base.py", line 843, in _resolve_lookup
    current = getattr(current, bit)
AttributeError: 'dict' object has no attribute 'required'

During handling of the above exception, another exception occurred:

Traceback (most recent call last):
  File "/usr/local/lib/python3.6/dist-packages/django/template/base.py", line 849, in _resolve_lookup
    current = current[int(bit)]
ValueError: invalid literal for int() with base 10: 'required'

During handling of the above exception, another exception occurred:

Traceback (most recent call last):
  File "/usr/local/lib/python3.6/dist-packages/django/template/base.py", line 856, in _resolve_lookup
    (bit, current))  # missing attribute
django.template.base.VariableDoesNotExist: Failed lookup for key [required] in {'type': 'string', 'description': 'Verbose description', 'default': 'WJ'}
[2021-09-05 22:16:46.577 DEBUG                    django.template : 878]
Exception while resolving variable 'min' in template 'ysdevices/device_form.html'.
Traceback (most recent call last):
  File "/usr/local/lib/python3.6/dist-packages/django/template/base.py", line 835, in _resolve_lookup
    current = current[bit]
KeyError: 'min'

During handling of the above exception, another exception occurred:

Traceback (most recent call last):
  File "/usr/local/lib/python3.6/dist-packages/django/template/base.py", line 843, in _resolve_lookup
    current = getattr(current, bit)
AttributeError: 'dict' object has no attribute 'min'

During handling of the above exception, another exception occurred:

Traceback (most recent call last):
  File "/usr/local/lib/python3.6/dist-packages/django/template/base.py", line 849, in _resolve_lookup
    current = current[int(bit)]
ValueError: invalid literal for int() with base 10: 'min'

During handling of the above exception, another exception occurred:

Traceback (most recent call last):
  File "/usr/local/lib/python3.6/dist-packages/django/template/base.py", line 856, in _resolve_lookup
    (bit, current))  # missing attribute
django.template.base.VariableDoesNotExist: Failed lookup for key [min] in {'type': 'string', 'description': 'Address or hostname to use as default for all protocols', 'required': True, 'default': '10.0.0.1'}
[2021-09-05 22:16:46.578 DEBUG                    django.template : 878]
Exception while resolving variable 'minLength' in template 'ysdevices/device_form.html'.
Traceback (most recent call last):
  File "/usr/local/lib/python3.6/dist-packages/django/template/base.py", line 835, in _resolve_lookup
    current = current[bit]
KeyError: 'minLength'

During handling of the above exception, another exception occurred:

Traceback (most recent call last):
  File "/usr/local/lib/python3.6/dist-packages/django/template/base.py", line 843, in _resolve_lookup
    current = getattr(current, bit)
AttributeError: 'dict' object has no attribute 'minLength'

During handling of the above exception, another exception occurred:

Traceback (most recent call last):
  File "/usr/local/lib/python3.6/dist-packages/django/template/base.py", line 849, in _resolve_lookup
    current = current[int(bit)]
ValueError: invalid literal for int() with base 10: 'minLength'

During handling of the above exception, another exception occurred:

Traceback (most recent call last):
  File "/usr/local/lib/python3.6/dist-packages/django/template/base.py", line 856, in _resolve_lookup
    (bit, current))  # missing attribute
django.template.base.VariableDoesNotExist: Failed lookup for key [minLength] in {'type': 'string', 'description': 'Address or hostname to use as default for all protocols', 'required': True, 'default': '10.0.0.1'}
[2021-09-05 22:16:46.581 DEBUG                    django.template : 878]
Exception while resolving variable 'max' in template 'ysdevices/device_form.html'.
Traceback (most recent call last):
  File "/usr/local/lib/python3.6/dist-packages/django/template/base.py", line 835, in _resolve_lookup
    current = current[bit]
KeyError: 'max'

During handling of the above exception, another exception occurred:

Traceback (most recent call last):
  File "/usr/local/lib/python3.6/dist-packages/django/template/base.py", line 843, in _resolve_lookup
    current = getattr(current, bit)
AttributeError: 'dict' object has no attribute 'max'

During handling of the above exception, another exception occurred:

Traceback (most recent call last):
  File "/usr/local/lib/python3.6/dist-packages/django/template/base.py", line 849, in _resolve_lookup
    current = current[int(bit)]
ValueError: invalid literal for int() with base 10: 'max'

During handling of the above exception, another exception occurred:

Traceback (most recent call last):
  File "/usr/local/lib/python3.6/dist-packages/django/template/base.py", line 856, in _resolve_lookup
    (bit, current))  # missing attribute
django.template.base.VariableDoesNotExist: Failed lookup for key [max] in {'type': 'string', 'description': 'Address or hostname to use as default for all protocols', 'required': True, 'default': '10.0.0.1'}
[2021-09-05 22:16:46.581 DEBUG                    django.template : 878]
Exception while resolving variable 'maxLength' in template 'ysdevices/device_form.html'.
Traceback (most recent call last):
  File "/usr/local/lib/python3.6/dist-packages/django/template/base.py", line 835, in _resolve_lookup
    current = current[bit]
KeyError: 'maxLength'

During handling of the above exception, another exception occurred:

Traceback (most recent call last):
  File "/usr/local/lib/python3.6/dist-packages/django/template/base.py", line 843, in _resolve_lookup
    current = getattr(current, bit)
AttributeError: 'dict' object has no attribute 'maxLength'

During handling of the above exception, another exception occurred:

Traceback (most recent call last):
  File "/usr/local/lib/python3.6/dist-packages/django/template/base.py", line 849, in _resolve_lookup
    current = current[int(bit)]
ValueError: invalid literal for int() with base 10: 'maxLength'

During handling of the above exception, another exception occurred:

Traceback (most recent call last):
  File "/usr/local/lib/python3.6/dist-packages/django/template/base.py", line 856, in _resolve_lookup
    (bit, current))  # missing attribute
django.template.base.VariableDoesNotExist: Failed lookup for key [maxLength] in {'type': 'string', 'description': 'Address or hostname to use as default for all protocols', 'required': True, 'default': '10.0.0.1'}
[2021-09-05 22:16:46.581 DEBUG                    django.template : 878]
Exception while resolving variable 'step' in template 'ysdevices/device_form.html'.
Traceback (most recent call last):
  File "/usr/local/lib/python3.6/dist-packages/django/template/base.py", line 835, in _resolve_lookup
    current = current[bit]
KeyError: 'step'

During handling of the above exception, another exception occurred:

Traceback (most recent call last):
  File "/usr/local/lib/python3.6/dist-packages/django/template/base.py", line 843, in _resolve_lookup
    current = getattr(current, bit)
AttributeError: 'dict' object has no attribute 'step'

During handling of the above exception, another exception occurred:

Traceback (most recent call last):
  File "/usr/local/lib/python3.6/dist-packages/django/template/base.py", line 849, in _resolve_lookup
    current = current[int(bit)]
ValueError: invalid literal for int() with base 10: 'step'

During handling of the above exception, another exception occurred:

Traceback (most recent call last):
  File "/usr/local/lib/python3.6/dist-packages/django/template/base.py", line 856, in _resolve_lookup
    (bit, current))  # missing attribute
django.template.base.VariableDoesNotExist: Failed lookup for key [step] in {'type': 'string', 'description': 'Address or hostname to use as default for all protocols', 'required': True, 'default': '10.0.0.1'}
[2021-09-05 22:16:46.581 DEBUG                    django.template : 878]
Exception while resolving variable 'label' in template 'ysdevices/device_form.html'.
Traceback (most recent call last):
  File "/usr/local/lib/python3.6/dist-packages/django/template/base.py", line 835, in _resolve_lookup
    current = current[bit]
KeyError: 'label'

During handling of the above exception, another exception occurred:

Traceback (most recent call last):
  File "/usr/local/lib/python3.6/dist-packages/django/template/base.py", line 843, in _resolve_lookup
    current = getattr(current, bit)
AttributeError: 'dict' object has no attribute 'label'

During handling of the above exception, another exception occurred:

Traceback (most recent call last):
  File "/usr/local/lib/python3.6/dist-packages/django/template/base.py", line 849, in _resolve_lookup
    current = current[int(bit)]
ValueError: invalid literal for int() with base 10: 'label'

During handling of the above exception, another exception occurred:

Traceback (most recent call last):
  File "/usr/local/lib/python3.6/dist-packages/django/template/base.py", line 856, in _resolve_lookup
    (bit, current))  # missing attribute
django.template.base.VariableDoesNotExist: Failed lookup for key [label] in {'type': 'string', 'description': 'Address or hostname to use as default for all protocols', 'required': True, 'default': '10.0.0.1'}
[2021-09-05 22:16:46.583 DEBUG                    django.template : 878]
Exception while resolving variable 'min' in template 'ysdevices/device_form.html'.
Traceback (most recent call last):
  File "/usr/local/lib/python3.6/dist-packages/django/template/base.py", line 835, in _resolve_lookup
    current = current[bit]
KeyError: 'min'

During handling of the above exception, another exception occurred:

Traceback (most recent call last):
  File "/usr/local/lib/python3.6/dist-packages/django/template/base.py", line 843, in _resolve_lookup
    current = getattr(current, bit)
AttributeError: 'dict' object has no attribute 'min'

During handling of the above exception, another exception occurred:

Traceback (most recent call last):
  File "/usr/local/lib/python3.6/dist-packages/django/template/base.py", line 849, in _resolve_lookup
    current = current[int(bit)]
ValueError: invalid literal for int() with base 10: 'min'

During handling of the above exception, another exception occurred:

Traceback (most recent call last):
  File "/usr/local/lib/python3.6/dist-packages/django/template/base.py", line 856, in _resolve_lookup
    (bit, current))  # missing attribute
django.template.base.VariableDoesNotExist: Failed lookup for key [min] in {'type': 'string', 'description': 'Username used as default for all protocols', 'maxLength': 50, 'default': 'admin'}
[2021-09-05 22:16:46.583 DEBUG                    django.template : 878]
Exception while resolving variable 'minLength' in template 'ysdevices/device_form.html'.
Traceback (most recent call last):
  File "/usr/local/lib/python3.6/dist-packages/django/template/base.py", line 835, in _resolve_lookup
    current = current[bit]
KeyError: 'minLength'

During handling of the above exception, another exception occurred:

Traceback (most recent call last):
  File "/usr/local/lib/python3.6/dist-packages/django/template/base.py", line 843, in _resolve_lookup
    current = getattr(current, bit)
AttributeError: 'dict' object has no attribute 'minLength'

During handling of the above exception, another exception occurred:

Traceback (most recent call last):
  File "/usr/local/lib/python3.6/dist-packages/django/template/base.py", line 849, in _resolve_lookup
    current = current[int(bit)]
ValueError: invalid literal for int() with base 10: 'minLength'

During handling of the above exception, another exception occurred:

Traceback (most recent call last):
  File "/usr/local/lib/python3.6/dist-packages/django/template/base.py", line 856, in _resolve_lookup
    (bit, current))  # missing attribute
django.template.base.VariableDoesNotExist: Failed lookup for key [minLength] in {'type': 'string', 'description': 'Username used as default for all protocols', 'maxLength': 50, 'default': 'admin'}
[2021-09-05 22:16:46.584 DEBUG                    django.template : 878]
Exception while resolving variable 'max' in template 'ysdevices/device_form.html'.
Traceback (most recent call last):
  File "/usr/local/lib/python3.6/dist-packages/django/template/base.py", line 835, in _resolve_lookup
    current = current[bit]
KeyError: 'max'

During handling of the above exception, another exception occurred:

Traceback (most recent call last):
  File "/usr/local/lib/python3.6/dist-packages/django/template/base.py", line 843, in _resolve_lookup
    current = getattr(current, bit)
AttributeError: 'dict' object has no attribute 'max'

During handling of the above exception, another exception occurred:

Traceback (most recent call last):
  File "/usr/local/lib/python3.6/dist-packages/django/template/base.py", line 849, in _resolve_lookup
    current = current[int(bit)]
ValueError: invalid literal for int() with base 10: 'max'

During handling of the above exception, another exception occurred:

Traceback (most recent call last):
  File "/usr/local/lib/python3.6/dist-packages/django/template/base.py", line 856, in _resolve_lookup
    (bit, current))  # missing attribute
django.template.base.VariableDoesNotExist: Failed lookup for key [max] in {'type': 'string', 'description': 'Username used as default for all protocols', 'maxLength': 50, 'default': 'admin'}
[2021-09-05 22:16:46.584 DEBUG                    django.template : 878]
Exception while resolving variable 'step' in template 'ysdevices/device_form.html'.
Traceback (most recent call last):
  File "/usr/local/lib/python3.6/dist-packages/django/template/base.py", line 835, in _resolve_lookup
    current = current[bit]
KeyError: 'step'

During handling of the above exception, another exception occurred:

Traceback (most recent call last):
  File "/usr/local/lib/python3.6/dist-packages/django/template/base.py", line 843, in _resolve_lookup
    current = getattr(current, bit)
AttributeError: 'dict' object has no attribute 'step'

During handling of the above exception, another exception occurred:

Traceback (most recent call last):
  File "/usr/local/lib/python3.6/dist-packages/django/template/base.py", line 849, in _resolve_lookup
    current = current[int(bit)]
ValueError: invalid literal for int() with base 10: 'step'

During handling of the above exception, another exception occurred:

Traceback (most recent call last):
  File "/usr/local/lib/python3.6/dist-packages/django/template/base.py", line 856, in _resolve_lookup
    (bit, current))  # missing attribute
django.template.base.VariableDoesNotExist: Failed lookup for key [step] in {'type': 'string', 'description': 'Username used as default for all protocols', 'maxLength': 50, 'default': 'admin'}
[2021-09-05 22:16:46.584 DEBUG                    django.template : 878]
Exception while resolving variable 'required' in template 'ysdevices/device_form.html'.
Traceback (most recent call last):
  File "/usr/local/lib/python3.6/dist-packages/django/template/base.py", line 835, in _resolve_lookup
    current = current[bit]
KeyError: 'required'

During handling of the above exception, another exception occurred:

Traceback (most recent call last):
  File "/usr/local/lib/python3.6/dist-packages/django/template/base.py", line 843, in _resolve_lookup
    current = getattr(current, bit)
AttributeError: 'dict' object has no attribute 'required'

During handling of the above exception, another exception occurred:

Traceback (most recent call last):
  File "/usr/local/lib/python3.6/dist-packages/django/template/base.py", line 849, in _resolve_lookup
    current = current[int(bit)]
ValueError: invalid literal for int() with base 10: 'required'

During handling of the above exception, another exception occurred:

Traceback (most recent call last):
  File "/usr/local/lib/python3.6/dist-packages/django/template/base.py", line 856, in _resolve_lookup
    (bit, current))  # missing attribute
django.template.base.VariableDoesNotExist: Failed lookup for key [required] in {'type': 'string', 'description': 'Username used as default for all protocols', 'maxLength': 50, 'default': 'admin'}
[2021-09-05 22:16:46.585 DEBUG                    django.template : 878]
Exception while resolving variable 'label' in template 'ysdevices/device_form.html'.
Traceback (most recent call last):
  File "/usr/local/lib/python3.6/dist-packages/django/template/base.py", line 835, in _resolve_lookup
    current = current[bit]
KeyError: 'label'

During handling of the above exception, another exception occurred:

Traceback (most recent call last):
  File "/usr/local/lib/python3.6/dist-packages/django/template/base.py", line 843, in _resolve_lookup
    current = getattr(current, bit)
AttributeError: 'dict' object has no attribute 'label'

During handling of the above exception, another exception occurred:

Traceback (most recent call last):
  File "/usr/local/lib/python3.6/dist-packages/django/template/base.py", line 849, in _resolve_lookup
    current = current[int(bit)]
ValueError: invalid literal for int() with base 10: 'label'

During handling of the above exception, another exception occurred:

Traceback (most recent call last):
  File "/usr/local/lib/python3.6/dist-packages/django/template/base.py", line 856, in _resolve_lookup
    (bit, current))  # missing attribute
django.template.base.VariableDoesNotExist: Failed lookup for key [label] in {'type': 'string', 'description': 'Username used as default for all protocols', 'maxLength': 50, 'default': 'admin'}
[2021-09-05 22:16:46.585 DEBUG                    django.template : 878]
Exception while resolving variable 'required' in template 'ysdevices/device_form.html'.
Traceback (most recent call last):
  File "/usr/local/lib/python3.6/dist-packages/django/template/base.py", line 835, in _resolve_lookup
    current = current[bit]
KeyError: 'required'

During handling of the above exception, another exception occurred:

Traceback (most recent call last):
  File "/usr/local/lib/python3.6/dist-packages/django/template/base.py", line 843, in _resolve_lookup
    current = getattr(current, bit)
AttributeError: 'dict' object has no attribute 'required'

During handling of the above exception, another exception occurred:

Traceback (most recent call last):
  File "/usr/local/lib/python3.6/dist-packages/django/template/base.py", line 849, in _resolve_lookup
    current = current[int(bit)]
ValueError: invalid literal for int() with base 10: 'required'

During handling of the above exception, another exception occurred:

Traceback (most recent call last):
  File "/usr/local/lib/python3.6/dist-packages/django/template/base.py", line 856, in _resolve_lookup
    (bit, current))  # missing attribute
django.template.base.VariableDoesNotExist: Failed lookup for key [required] in {'type': 'string', 'description': 'Username used as default for all protocols', 'maxLength': 50, 'default': 'admin'}
[2021-09-05 22:16:46.585 DEBUG                    django.template : 878]
Exception while resolving variable 'min' in template 'ysdevices/device_form.html'.
Traceback (most recent call last):
  File "/usr/local/lib/python3.6/dist-packages/django/template/base.py", line 835, in _resolve_lookup
    current = current[bit]
KeyError: 'min'

During handling of the above exception, another exception occurred:

Traceback (most recent call last):
  File "/usr/local/lib/python3.6/dist-packages/django/template/base.py", line 843, in _resolve_lookup
    current = getattr(current, bit)
AttributeError: 'dict' object has no attribute 'min'

During handling of the above exception, another exception occurred:

Traceback (most recent call last):
  File "/usr/local/lib/python3.6/dist-packages/django/template/base.py", line 849, in _resolve_lookup
    current = current[int(bit)]
ValueError: invalid literal for int() with base 10: 'min'

During handling of the above exception, another exception occurred:

Traceback (most recent call last):
  File "/usr/local/lib/python3.6/dist-packages/django/template/base.py", line 856, in _resolve_lookup
    (bit, current))  # missing attribute
django.template.base.VariableDoesNotExist: Failed lookup for key [min] in {'type': 'password', 'description': 'Password used as default for all protocols', 'maxLength': 50, 'default': '_placeholder_'}
[2021-09-05 22:16:46.585 DEBUG                    django.template : 878]
Exception while resolving variable 'minLength' in template 'ysdevices/device_form.html'.
Traceback (most recent call last):
  File "/usr/local/lib/python3.6/dist-packages/django/template/base.py", line 835, in _resolve_lookup
    current = current[bit]
KeyError: 'minLength'

During handling of the above exception, another exception occurred:

Traceback (most recent call last):
  File "/usr/local/lib/python3.6/dist-packages/django/template/base.py", line 843, in _resolve_lookup
    current = getattr(current, bit)
AttributeError: 'dict' object has no attribute 'minLength'

During handling of the above exception, another exception occurred:

Traceback (most recent call last):
  File "/usr/local/lib/python3.6/dist-packages/django/template/base.py", line 849, in _resolve_lookup
    current = current[int(bit)]
ValueError: invalid literal for int() with base 10: 'minLength'

During handling of the above exception, another exception occurred:

Traceback (most recent call last):
  File "/usr/local/lib/python3.6/dist-packages/django/template/base.py", line 856, in _resolve_lookup
    (bit, current))  # missing attribute
django.template.base.VariableDoesNotExist: Failed lookup for key [minLength] in {'type': 'password', 'description': 'Password used as default for all protocols', 'maxLength': 50, 'default': '_placeholder_'}
[2021-09-05 22:16:46.586 DEBUG                    django.template : 878]
Exception while resolving variable 'max' in template 'ysdevices/device_form.html'.
Traceback (most recent call last):
  File "/usr/local/lib/python3.6/dist-packages/django/template/base.py", line 835, in _resolve_lookup
    current = current[bit]
KeyError: 'max'

During handling of the above exception, another exception occurred:

Traceback (most recent call last):
  File "/usr/local/lib/python3.6/dist-packages/django/template/base.py", line 843, in _resolve_lookup
    current = getattr(current, bit)
AttributeError: 'dict' object has no attribute 'max'

During handling of the above exception, another exception occurred:

Traceback (most recent call last):
  File "/usr/local/lib/python3.6/dist-packages/django/template/base.py", line 849, in _resolve_lookup
    current = current[int(bit)]
ValueError: invalid literal for int() with base 10: 'max'

During handling of the above exception, another exception occurred:

Traceback (most recent call last):
  File "/usr/local/lib/python3.6/dist-packages/django/template/base.py", line 856, in _resolve_lookup
    (bit, current))  # missing attribute
django.template.base.VariableDoesNotExist: Failed lookup for key [max] in {'type': 'password', 'description': 'Password used as default for all protocols', 'maxLength': 50, 'default': '_placeholder_'}
[2021-09-05 22:16:46.591 DEBUG                    django.template : 878]
Exception while resolving variable 'step' in template 'ysdevices/device_form.html'.
Traceback (most recent call last):
  File "/usr/local/lib/python3.6/dist-packages/django/template/base.py", line 835, in _resolve_lookup
    current = current[bit]
KeyError: 'step'

During handling of the above exception, another exception occurred:

Traceback (most recent call last):
  File "/usr/local/lib/python3.6/dist-packages/django/template/base.py", line 843, in _resolve_lookup
    current = getattr(current, bit)
AttributeError: 'dict' object has no attribute 'step'

During handling of the above exception, another exception occurred:

Traceback (most recent call last):
  File "/usr/local/lib/python3.6/dist-packages/django/template/base.py", line 849, in _resolve_lookup
    current = current[int(bit)]
ValueError: invalid literal for int() with base 10: 'step'

During handling of the above exception, another exception occurred:

Traceback (most recent call last):
  File "/usr/local/lib/python3.6/dist-packages/django/template/base.py", line 856, in _resolve_lookup
    (bit, current))  # missing attribute
django.template.base.VariableDoesNotExist: Failed lookup for key [step] in {'type': 'password', 'description': 'Password used as default for all protocols', 'maxLength': 50, 'default': '_placeholder_'}
[2021-09-05 22:16:46.591 DEBUG                    django.template : 878]
Exception while resolving variable 'required' in template 'ysdevices/device_form.html'.
Traceback (most recent call last):
  File "/usr/local/lib/python3.6/dist-packages/django/template/base.py", line 835, in _resolve_lookup
    current = current[bit]
KeyError: 'required'

During handling of the above exception, another exception occurred:

Traceback (most recent call last):
  File "/usr/local/lib/python3.6/dist-packages/django/template/base.py", line 843, in _resolve_lookup
    current = getattr(current, bit)
AttributeError: 'dict' object has no attribute 'required'

During handling of the above exception, another exception occurred:

Traceback (most recent call last):
  File "/usr/local/lib/python3.6/dist-packages/django/template/base.py", line 849, in _resolve_lookup
    current = current[int(bit)]
ValueError: invalid literal for int() with base 10: 'required'

During handling of the above exception, another exception occurred:

Traceback (most recent call last):
  File "/usr/local/lib/python3.6/dist-packages/django/template/base.py", line 856, in _resolve_lookup
    (bit, current))  # missing attribute
django.template.base.VariableDoesNotExist: Failed lookup for key [required] in {'type': 'password', 'description': 'Password used as default for all protocols', 'maxLength': 50, 'default': '_placeholder_'}
[2021-09-05 22:16:46.591 DEBUG                    django.template : 878]
Exception while resolving variable 'label' in template 'ysdevices/device_form.html'.
Traceback (most recent call last):
  File "/usr/local/lib/python3.6/dist-packages/django/template/base.py", line 835, in _resolve_lookup
    current = current[bit]
KeyError: 'label'

During handling of the above exception, another exception occurred:

Traceback (most recent call last):
  File "/usr/local/lib/python3.6/dist-packages/django/template/base.py", line 843, in _resolve_lookup
    current = getattr(current, bit)
AttributeError: 'dict' object has no attribute 'label'

During handling of the above exception, another exception occurred:

Traceback (most recent call last):
  File "/usr/local/lib/python3.6/dist-packages/django/template/base.py", line 849, in _resolve_lookup
    current = current[int(bit)]
ValueError: invalid literal for int() with base 10: 'label'

During handling of the above exception, another exception occurred:

Traceback (most recent call last):
  File "/usr/local/lib/python3.6/dist-packages/django/template/base.py", line 856, in _resolve_lookup
    (bit, current))  # missing attribute
django.template.base.VariableDoesNotExist: Failed lookup for key [label] in {'type': 'password', 'description': 'Password used as default for all protocols', 'maxLength': 50, 'default': '_placeholder_'}
[2021-09-05 22:16:46.592 DEBUG                    django.template : 878]
Exception while resolving variable 'required' in template 'ysdevices/device_form.html'.
Traceback (most recent call last):
  File "/usr/local/lib/python3.6/dist-packages/django/template/base.py", line 835, in _resolve_lookup
    current = current[bit]
KeyError: 'required'

During handling of the above exception, another exception occurred:

Traceback (most recent call last):
  File "/usr/local/lib/python3.6/dist-packages/django/template/base.py", line 843, in _resolve_lookup
    current = getattr(current, bit)
AttributeError: 'dict' object has no attribute 'required'

During handling of the above exception, another exception occurred:

Traceback (most recent call last):
  File "/usr/local/lib/python3.6/dist-packages/django/template/base.py", line 849, in _resolve_lookup
    current = current[int(bit)]
ValueError: invalid literal for int() with base 10: 'required'

During handling of the above exception, another exception occurred:

Traceback (most recent call last):
  File "/usr/local/lib/python3.6/dist-packages/django/template/base.py", line 856, in _resolve_lookup
    (bit, current))  # missing attribute
django.template.base.VariableDoesNotExist: Failed lookup for key [required] in {'type': 'password', 'description': 'Password used as default for all protocols', 'maxLength': 50, 'default': '_placeholder_'}
[2021-09-05 22:16:46.592 DEBUG                    django.template : 878]
Exception while resolving variable 'min' in template 'ysdevices/device_form.html'.
Traceback (most recent call last):
  File "/usr/local/lib/python3.6/dist-packages/django/template/base.py", line 835, in _resolve_lookup
    current = current[bit]
KeyError: 'min'

During handling of the above exception, another exception occurred:

Traceback (most recent call last):
  File "/usr/local/lib/python3.6/dist-packages/django/template/base.py", line 843, in _resolve_lookup
    current = getattr(current, bit)
AttributeError: 'dict' object has no attribute 'min'

During handling of the above exception, another exception occurred:

Traceback (most recent call last):
  File "/usr/local/lib/python3.6/dist-packages/django/template/base.py", line 849, in _resolve_lookup
    current = current[int(bit)]
ValueError: invalid literal for int() with base 10: 'min'

During handling of the above exception, another exception occurred:

Traceback (most recent call last):
  File "/usr/local/lib/python3.6/dist-packages/django/template/base.py", line 856, in _resolve_lookup
    (bit, current))  # missing attribute
django.template.base.VariableDoesNotExist: Failed lookup for key [min] in {'type': 'int', 'description': 'Timeout (in seconds) as default for all protocols', 'default': 30, 'required': True}
[2021-09-05 22:16:46.592 DEBUG                    django.template : 878]
Exception while resolving variable 'minLength' in template 'ysdevices/device_form.html'.
Traceback (most recent call last):
  File "/usr/local/lib/python3.6/dist-packages/django/template/base.py", line 835, in _resolve_lookup
    current = current[bit]
KeyError: 'minLength'

During handling of the above exception, another exception occurred:

Traceback (most recent call last):
  File "/usr/local/lib/python3.6/dist-packages/django/template/base.py", line 843, in _resolve_lookup
    current = getattr(current, bit)
AttributeError: 'dict' object has no attribute 'minLength'

During handling of the above exception, another exception occurred:

Traceback (most recent call last):
  File "/usr/local/lib/python3.6/dist-packages/django/template/base.py", line 849, in _resolve_lookup
    current = current[int(bit)]
ValueError: invalid literal for int() with base 10: 'minLength'

During handling of the above exception, another exception occurred:

Traceback (most recent call last):
  File "/usr/local/lib/python3.6/dist-packages/django/template/base.py", line 856, in _resolve_lookup
    (bit, current))  # missing attribute
django.template.base.VariableDoesNotExist: Failed lookup for key [minLength] in {'type': 'int', 'description': 'Timeout (in seconds) as default for all protocols', 'default': 30, 'required': True}
[2021-09-05 22:16:46.592 DEBUG                    django.template : 878]
Exception while resolving variable 'max' in template 'ysdevices/device_form.html'.
Traceback (most recent call last):
  File "/usr/local/lib/python3.6/dist-packages/django/template/base.py", line 835, in _resolve_lookup
    current = current[bit]
KeyError: 'max'

During handling of the above exception, another exception occurred:

Traceback (most recent call last):
  File "/usr/local/lib/python3.6/dist-packages/django/template/base.py", line 843, in _resolve_lookup
    current = getattr(current, bit)
AttributeError: 'dict' object has no attribute 'max'

During handling of the above exception, another exception occurred:

Traceback (most recent call last):
  File "/usr/local/lib/python3.6/dist-packages/django/template/base.py", line 849, in _resolve_lookup
    current = current[int(bit)]
ValueError: invalid literal for int() with base 10: 'max'

During handling of the above exception, another exception occurred:

Traceback (most recent call last):
  File "/usr/local/lib/python3.6/dist-packages/django/template/base.py", line 856, in _resolve_lookup
    (bit, current))  # missing attribute
django.template.base.VariableDoesNotExist: Failed lookup for key [max] in {'type': 'int', 'description': 'Timeout (in seconds) as default for all protocols', 'default': 30, 'required': True}
[2021-09-05 22:16:46.593 DEBUG                    django.template : 878]
Exception while resolving variable 'maxLength' in template 'ysdevices/device_form.html'.
Traceback (most recent call last):
  File "/usr/local/lib/python3.6/dist-packages/django/template/base.py", line 835, in _resolve_lookup
    current = current[bit]
KeyError: 'maxLength'

During handling of the above exception, another exception occurred:

Traceback (most recent call last):
  File "/usr/local/lib/python3.6/dist-packages/django/template/base.py", line 843, in _resolve_lookup
    current = getattr(current, bit)
AttributeError: 'dict' object has no attribute 'maxLength'

During handling of the above exception, another exception occurred:

Traceback (most recent call last):
  File "/usr/local/lib/python3.6/dist-packages/django/template/base.py", line 849, in _resolve_lookup
    current = current[int(bit)]
ValueError: invalid literal for int() with base 10: 'maxLength'

During handling of the above exception, another exception occurred:

Traceback (most recent call last):
  File "/usr/local/lib/python3.6/dist-packages/django/template/base.py", line 856, in _resolve_lookup
    (bit, current))  # missing attribute
django.template.base.VariableDoesNotExist: Failed lookup for key [maxLength] in {'type': 'int', 'description': 'Timeout (in seconds) as default for all protocols', 'default': 30, 'required': True}
[2021-09-05 22:16:46.593 DEBUG                    django.template : 878]
Exception while resolving variable 'step' in template 'ysdevices/device_form.html'.
Traceback (most recent call last):
  File "/usr/local/lib/python3.6/dist-packages/django/template/base.py", line 835, in _resolve_lookup
    current = current[bit]
KeyError: 'step'

During handling of the above exception, another exception occurred:

Traceback (most recent call last):
  File "/usr/local/lib/python3.6/dist-packages/django/template/base.py", line 843, in _resolve_lookup
    current = getattr(current, bit)
AttributeError: 'dict' object has no attribute 'step'

During handling of the above exception, another exception occurred:

Traceback (most recent call last):
  File "/usr/local/lib/python3.6/dist-packages/django/template/base.py", line 849, in _resolve_lookup
    current = current[int(bit)]
ValueError: invalid literal for int() with base 10: 'step'

During handling of the above exception, another exception occurred:

Traceback (most recent call last):
  File "/usr/local/lib/python3.6/dist-packages/django/template/base.py", line 856, in _resolve_lookup
    (bit, current))  # missing attribute
django.template.base.VariableDoesNotExist: Failed lookup for key [step] in {'type': 'int', 'description': 'Timeout (in seconds) as default for all protocols', 'default': 30, 'required': True}
[2021-09-05 22:16:46.593 DEBUG                    django.template : 878]
Exception while resolving variable 'label' in template 'ysdevices/device_form.html'.
Traceback (most recent call last):
  File "/usr/local/lib/python3.6/dist-packages/django/template/base.py", line 835, in _resolve_lookup
    current = current[bit]
KeyError: 'label'

During handling of the above exception, another exception occurred:

Traceback (most recent call last):
  File "/usr/local/lib/python3.6/dist-packages/django/template/base.py", line 843, in _resolve_lookup
    current = getattr(current, bit)
AttributeError: 'dict' object has no attribute 'label'

During handling of the above exception, another exception occurred:

Traceback (most recent call last):
  File "/usr/local/lib/python3.6/dist-packages/django/template/base.py", line 849, in _resolve_lookup
    current = current[int(bit)]
ValueError: invalid literal for int() with base 10: 'label'

During handling of the above exception, another exception occurred:

Traceback (most recent call last):
  File "/usr/local/lib/python3.6/dist-packages/django/template/base.py", line 856, in _resolve_lookup
    (bit, current))  # missing attribute
django.template.base.VariableDoesNotExist: Failed lookup for key [label] in {'type': 'int', 'description': 'Timeout (in seconds) as default for all protocols', 'default': 30, 'required': True}
[2021-09-05 22:16:46.594 DEBUG                    django.template : 878]
Exception while resolving variable 'label' in template 'ysdevices/device_form.html'.
Traceback (most recent call last):
  File "/usr/local/lib/python3.6/dist-packages/django/template/base.py", line 835, in _resolve_lookup
    current = current[bit]
KeyError: 'label'

During handling of the above exception, another exception occurred:

Traceback (most recent call last):
  File "/usr/local/lib/python3.6/dist-packages/django/template/base.py", line 843, in _resolve_lookup
    current = getattr(current, bit)
AttributeError: 'dict' object has no attribute 'label'

During handling of the above exception, another exception occurred:

Traceback (most recent call last):
  File "/usr/local/lib/python3.6/dist-packages/django/template/base.py", line 849, in _resolve_lookup
    current = current[int(bit)]
ValueError: invalid literal for int() with base 10: 'label'

During handling of the above exception, another exception occurred:

Traceback (most recent call last):
  File "/usr/local/lib/python3.6/dist-packages/django/template/base.py", line 856, in _resolve_lookup
    (bit, current))  # missing attribute
django.template.base.VariableDoesNotExist: Failed lookup for key [label] in {'type': 'dict', 'description': 'Key/value pairs of data associated with device', 'keyLabel': 'Variable Name', 'valueLabel': 'Value', 'default': {}}
[2021-09-05 22:16:46.595 DEBUG                    django.template : 878]
Exception while resolving variable 'required' in template 'ysdevices/device_form.html'.
Traceback (most recent call last):
  File "/usr/local/lib/python3.6/dist-packages/django/template/base.py", line 835, in _resolve_lookup
    current = current[bit]
KeyError: 'required'

During handling of the above exception, another exception occurred:

Traceback (most recent call last):
  File "/usr/local/lib/python3.6/dist-packages/django/template/base.py", line 843, in _resolve_lookup
    current = getattr(current, bit)
AttributeError: 'dict' object has no attribute 'required'

During handling of the above exception, another exception occurred:

Traceback (most recent call last):
  File "/usr/local/lib/python3.6/dist-packages/django/template/base.py", line 849, in _resolve_lookup
    current = current[int(bit)]
ValueError: invalid literal for int() with base 10: 'required'

During handling of the above exception, another exception occurred:

Traceback (most recent call last):
  File "/usr/local/lib/python3.6/dist-packages/django/template/base.py", line 856, in _resolve_lookup
    (bit, current))  # missing attribute
django.template.base.VariableDoesNotExist: Failed lookup for key [required] in {'type': 'dict', 'description': 'Key/value pairs of data associated with device', 'keyLabel': 'Variable Name', 'valueLabel': 'Value', 'default': {}}
[2021-09-05 22:16:46.597 DEBUG                    django.template : 878]
Exception while resolving variable 'min' in template 'ysdevices/device_form.html'.
Traceback (most recent call last):
  File "/usr/local/lib/python3.6/dist-packages/django/template/base.py", line 835, in _resolve_lookup
    current = current[bit]
KeyError: 'min'

During handling of the above exception, another exception occurred:

Traceback (most recent call last):
  File "/usr/local/lib/python3.6/dist-packages/django/template/base.py", line 843, in _resolve_lookup
    current = getattr(current, bit)
AttributeError: 'dict' object has no attribute 'min'

During handling of the above exception, another exception occurred:

Traceback (most recent call last):
  File "/usr/local/lib/python3.6/dist-packages/django/template/base.py", line 849, in _resolve_lookup
    current = current[int(bit)]
ValueError: invalid literal for int() with base 10: 'min'

During handling of the above exception, another exception occurred:

Traceback (most recent call last):
  File "/usr/local/lib/python3.6/dist-packages/django/template/base.py", line 856, in _resolve_lookup
    (bit, current))  # missing attribute
django.template.base.VariableDoesNotExist: Failed lookup for key [min] in {'label': 'TLS host override', 'type': 'string', 'description': '0verride DNS (not recommeded).', 'minLength': 1, 'default': ''}
[2021-09-05 22:16:46.598 DEBUG                    django.template : 878]
Exception while resolving variable 'max' in template 'ysdevices/device_form.html'.
Traceback (most recent call last):
  File "/usr/local/lib/python3.6/dist-packages/django/template/base.py", line 835, in _resolve_lookup
    current = current[bit]
KeyError: 'max'

During handling of the above exception, another exception occurred:

Traceback (most recent call last):
  File "/usr/local/lib/python3.6/dist-packages/django/template/base.py", line 843, in _resolve_lookup
    current = getattr(current, bit)
AttributeError: 'dict' object has no attribute 'max'

During handling of the above exception, another exception occurred:

Traceback (most recent call last):
  File "/usr/local/lib/python3.6/dist-packages/django/template/base.py", line 849, in _resolve_lookup
    current = current[int(bit)]
ValueError: invalid literal for int() with base 10: 'max'

During handling of the above exception, another exception occurred:

Traceback (most recent call last):
  File "/usr/local/lib/python3.6/dist-packages/django/template/base.py", line 856, in _resolve_lookup
    (bit, current))  # missing attribute
django.template.base.VariableDoesNotExist: Failed lookup for key [max] in {'label': 'TLS host override', 'type': 'string', 'description': '0verride DNS (not recommeded).', 'minLength': 1, 'default': ''}
[2021-09-05 22:16:46.598 DEBUG                    django.template : 878]
Exception while resolving variable 'maxLength' in template 'ysdevices/device_form.html'.
Traceback (most recent call last):
  File "/usr/local/lib/python3.6/dist-packages/django/template/base.py", line 835, in _resolve_lookup
    current = current[bit]
KeyError: 'maxLength'

During handling of the above exception, another exception occurred:

Traceback (most recent call last):
  File "/usr/local/lib/python3.6/dist-packages/django/template/base.py", line 843, in _resolve_lookup
    current = getattr(current, bit)
AttributeError: 'dict' object has no attribute 'maxLength'

During handling of the above exception, another exception occurred:

Traceback (most recent call last):
  File "/usr/local/lib/python3.6/dist-packages/django/template/base.py", line 849, in _resolve_lookup
    current = current[int(bit)]
ValueError: invalid literal for int() with base 10: 'maxLength'

During handling of the above exception, another exception occurred:

Traceback (most recent call last):
  File "/usr/local/lib/python3.6/dist-packages/django/template/base.py", line 856, in _resolve_lookup
    (bit, current))  # missing attribute
django.template.base.VariableDoesNotExist: Failed lookup for key [maxLength] in {'label': 'TLS host override', 'type': 'string', 'description': '0verride DNS (not recommeded).', 'minLength': 1, 'default': ''}
[2021-09-05 22:16:46.598 DEBUG                    django.template : 878]
Exception while resolving variable 'step' in template 'ysdevices/device_form.html'.
Traceback (most recent call last):
  File "/usr/local/lib/python3.6/dist-packages/django/template/base.py", line 835, in _resolve_lookup
    current = current[bit]
KeyError: 'step'

During handling of the above exception, another exception occurred:

Traceback (most recent call last):
  File "/usr/local/lib/python3.6/dist-packages/django/template/base.py", line 843, in _resolve_lookup
    current = getattr(current, bit)
AttributeError: 'dict' object has no attribute 'step'

During handling of the above exception, another exception occurred:

Traceback (most recent call last):
  File "/usr/local/lib/python3.6/dist-packages/django/template/base.py", line 849, in _resolve_lookup
    current = current[int(bit)]
ValueError: invalid literal for int() with base 10: 'step'

During handling of the above exception, another exception occurred:

Traceback (most recent call last):
  File "/usr/local/lib/python3.6/dist-packages/django/template/base.py", line 856, in _resolve_lookup
    (bit, current))  # missing attribute
django.template.base.VariableDoesNotExist: Failed lookup for key [step] in {'label': 'TLS host override', 'type': 'string', 'description': '0verride DNS (not recommeded).', 'minLength': 1, 'default': ''}
[2021-09-05 22:16:46.598 DEBUG                    django.template : 878]
Exception while resolving variable 'required' in template 'ysdevices/device_form.html'.
Traceback (most recent call last):
  File "/usr/local/lib/python3.6/dist-packages/django/template/base.py", line 835, in _resolve_lookup
    current = current[bit]
KeyError: 'required'

During handling of the above exception, another exception occurred:

Traceback (most recent call last):
  File "/usr/local/lib/python3.6/dist-packages/django/template/base.py", line 843, in _resolve_lookup
    current = getattr(current, bit)
AttributeError: 'dict' object has no attribute 'required'

During handling of the above exception, another exception occurred:

Traceback (most recent call last):
  File "/usr/local/lib/python3.6/dist-packages/django/template/base.py", line 849, in _resolve_lookup
    current = current[int(bit)]
ValueError: invalid literal for int() with base 10: 'required'

During handling of the above exception, another exception occurred:

Traceback (most recent call last):
  File "/usr/local/lib/python3.6/dist-packages/django/template/base.py", line 856, in _resolve_lookup
    (bit, current))  # missing attribute
django.template.base.VariableDoesNotExist: Failed lookup for key [required] in {'label': 'TLS host override', 'type': 'string', 'description': '0verride DNS (not recommeded).', 'minLength': 1, 'default': ''}
[2021-09-05 22:16:46.599 DEBUG                    django.template : 878]
Exception while resolving variable 'required' in template 'ysdevices/device_form.html'.
Traceback (most recent call last):
  File "/usr/local/lib/python3.6/dist-packages/django/template/base.py", line 835, in _resolve_lookup
    current = current[bit]
KeyError: 'required'

During handling of the above exception, another exception occurred:

Traceback (most recent call last):
  File "/usr/local/lib/python3.6/dist-packages/django/template/base.py", line 843, in _resolve_lookup
    current = getattr(current, bit)
AttributeError: 'dict' object has no attribute 'required'

During handling of the above exception, another exception occurred:

Traceback (most recent call last):
  File "/usr/local/lib/python3.6/dist-packages/django/template/base.py", line 849, in _resolve_lookup
    current = current[int(bit)]
ValueError: invalid literal for int() with base 10: 'required'

During handling of the above exception, another exception occurred:

Traceback (most recent call last):
  File "/usr/local/lib/python3.6/dist-packages/django/template/base.py", line 856, in _resolve_lookup
    (bit, current))  # missing attribute
django.template.base.VariableDoesNotExist: Failed lookup for key [required] in {'label': 'TLS host override', 'type': 'string', 'description': '0verride DNS (not recommeded).', 'minLength': 1, 'default': ''}
[2021-09-05 22:16:46.599 DEBUG                    django.template : 878]
Exception while resolving variable 'required' in template 'ysdevices/device_form.html'.
Traceback (most recent call last):
  File "/usr/local/lib/python3.6/dist-packages/django/template/base.py", line 835, in _resolve_lookup
    current = current[bit]
KeyError: 'required'

During handling of the above exception, another exception occurred:

Traceback (most recent call last):
  File "/usr/local/lib/python3.6/dist-packages/django/template/base.py", line 843, in _resolve_lookup
    current = getattr(current, bit)
AttributeError: 'dict' object has no attribute 'required'

During handling of the above exception, another exception occurred:

Traceback (most recent call last):
  File "/usr/local/lib/python3.6/dist-packages/django/template/base.py", line 849, in _resolve_lookup
    current = current[int(bit)]
ValueError: invalid literal for int() with base 10: 'required'

During handling of the above exception, another exception occurred:

Traceback (most recent call last):
  File "/usr/local/lib/python3.6/dist-packages/django/template/base.py", line 856, in _resolve_lookup
    (bit, current))  # missing attribute
django.template.base.VariableDoesNotExist: Failed lookup for key [required] in {'label': 'TLS host override', 'type': 'string', 'description': '0verride DNS (not recommeded).', 'minLength': 1, 'default': ''}
[2021-09-05 22:16:46.599 DEBUG                    django.template : 878]
Exception while resolving variable 'description' in template 'ysdevices/device_form.html'.
Traceback (most recent call last):
  File "/usr/local/lib/python3.6/dist-packages/django/template/base.py", line 835, in _resolve_lookup
    current = current[bit]
KeyError: 'description'

During handling of the above exception, another exception occurred:

Traceback (most recent call last):
  File "/usr/local/lib/python3.6/dist-packages/django/template/base.py", line 843, in _resolve_lookup
    current = getattr(current, bit)
AttributeError: 'dict' object has no attribute 'description'

During handling of the above exception, another exception occurred:

Traceback (most recent call last):
  File "/usr/local/lib/python3.6/dist-packages/django/template/base.py", line 849, in _resolve_lookup
    current = current[int(bit)]
ValueError: invalid literal for int() with base 10: 'description'

During handling of the above exception, another exception occurred:

Traceback (most recent call last):
  File "/usr/local/lib/python3.6/dist-packages/django/template/base.py", line 856, in _resolve_lookup
    (bit, current))  # missing attribute
django.template.base.VariableDoesNotExist: Failed lookup for key [description] in {'label': 'Device supports gNMI', 'type': 'boolean', 'default': False}
[2021-09-05 22:16:46.600 DEBUG                    django.template : 878]
Exception while resolving variable 'description' in template 'ysdevices/device_form.html'.
Traceback (most recent call last):
  File "/usr/local/lib/python3.6/dist-packages/django/template/base.py", line 835, in _resolve_lookup
    current = current[bit]
KeyError: 'description'

During handling of the above exception, another exception occurred:

Traceback (most recent call last):
  File "/usr/local/lib/python3.6/dist-packages/django/template/base.py", line 843, in _resolve_lookup
    current = getattr(current, bit)
AttributeError: 'dict' object has no attribute 'description'

During handling of the above exception, another exception occurred:

Traceback (most recent call last):
  File "/usr/local/lib/python3.6/dist-packages/django/template/base.py", line 849, in _resolve_lookup
    current = current[int(bit)]
ValueError: invalid literal for int() with base 10: 'description'

During handling of the above exception, another exception occurred:

Traceback (most recent call last):
  File "/usr/local/lib/python3.6/dist-packages/django/template/base.py", line 856, in _resolve_lookup
    (bit, current))  # missing attribute
django.template.base.VariableDoesNotExist: Failed lookup for key [description] in {'label': 'Platform', 'type': 'enum', 'choices': [('iosxe', 'IOS XE'), ('iosxr', 'IOS XR'), ('iosnx', 'IOS NX')], 'required': True, 'default': 'iosxe'}
[2021-09-05 22:16:46.600 DEBUG                    django.template : 878]
Exception while resolving variable 'minLength' in template 'ysdevices/device_form.html'.
Traceback (most recent call last):
  File "/usr/local/lib/python3.6/dist-packages/django/template/base.py", line 835, in _resolve_lookup
    current = current[bit]
KeyError: 'minLength'

During handling of the above exception, another exception occurred:

Traceback (most recent call last):
  File "/usr/local/lib/python3.6/dist-packages/django/template/base.py", line 843, in _resolve_lookup
    current = getattr(current, bit)
AttributeError: 'dict' object has no attribute 'minLength'

During handling of the above exception, another exception occurred:

Traceback (most recent call last):
  File "/usr/local/lib/python3.6/dist-packages/django/template/base.py", line 849, in _resolve_lookup
    current = current[int(bit)]
ValueError: invalid literal for int() with base 10: 'minLength'

During handling of the above exception, another exception occurred:

Traceback (most recent call last):
  File "/usr/local/lib/python3.6/dist-packages/django/template/base.py", line 856, in _resolve_lookup
    (bit, current))  # missing attribute
django.template.base.VariableDoesNotExist: Failed lookup for key [minLength] in {'label': 'gNMI insecure port', 'type': 'int', 'description': 'Port number the device listens on', 'min': 1, 'max': 65535, 'default': 50052, 'required': True}
[2021-09-05 22:16:46.601 DEBUG                    django.template : 878]
Exception while resolving variable 'maxLength' in template 'ysdevices/device_form.html'.
Traceback (most recent call last):
  File "/usr/local/lib/python3.6/dist-packages/django/template/base.py", line 835, in _resolve_lookup
    current = current[bit]
KeyError: 'maxLength'

During handling of the above exception, another exception occurred:

Traceback (most recent call last):
  File "/usr/local/lib/python3.6/dist-packages/django/template/base.py", line 843, in _resolve_lookup
    current = getattr(current, bit)
AttributeError: 'dict' object has no attribute 'maxLength'

During handling of the above exception, another exception occurred:

Traceback (most recent call last):
  File "/usr/local/lib/python3.6/dist-packages/django/template/base.py", line 849, in _resolve_lookup
    current = current[int(bit)]
ValueError: invalid literal for int() with base 10: 'maxLength'

During handling of the above exception, another exception occurred:

Traceback (most recent call last):
  File "/usr/local/lib/python3.6/dist-packages/django/template/base.py", line 856, in _resolve_lookup
    (bit, current))  # missing attribute
django.template.base.VariableDoesNotExist: Failed lookup for key [maxLength] in {'label': 'gNMI insecure port', 'type': 'int', 'description': 'Port number the device listens on', 'min': 1, 'max': 65535, 'default': 50052, 'required': True}
[2021-09-05 22:16:46.601 DEBUG                    django.template : 878]
Exception while resolving variable 'step' in template 'ysdevices/device_form.html'.
Traceback (most recent call last):
  File "/usr/local/lib/python3.6/dist-packages/django/template/base.py", line 835, in _resolve_lookup
    current = current[bit]
KeyError: 'step'

During handling of the above exception, another exception occurred:

Traceback (most recent call last):
  File "/usr/local/lib/python3.6/dist-packages/django/template/base.py", line 843, in _resolve_lookup
    current = getattr(current, bit)
AttributeError: 'dict' object has no attribute 'step'

During handling of the above exception, another exception occurred:

Traceback (most recent call last):
  File "/usr/local/lib/python3.6/dist-packages/django/template/base.py", line 849, in _resolve_lookup
    current = current[int(bit)]
ValueError: invalid literal for int() with base 10: 'step'

During handling of the above exception, another exception occurred:

Traceback (most recent call last):
  File "/usr/local/lib/python3.6/dist-packages/django/template/base.py", line 856, in _resolve_lookup
    (bit, current))  # missing attribute
django.template.base.VariableDoesNotExist: Failed lookup for key [step] in {'label': 'gNMI insecure port', 'type': 'int', 'description': 'Port number the device listens on', 'min': 1, 'max': 65535, 'default': 50052, 'required': True}
[2021-09-05 22:16:46.601 DEBUG                    django.template : 878]
Exception while resolving variable 'minLength' in template 'ysdevices/device_form.html'.
Traceback (most recent call last):
  File "/usr/local/lib/python3.6/dist-packages/django/template/base.py", line 835, in _resolve_lookup
    current = current[bit]
KeyError: 'minLength'

During handling of the above exception, another exception occurred:

Traceback (most recent call last):
  File "/usr/local/lib/python3.6/dist-packages/django/template/base.py", line 843, in _resolve_lookup
    current = getattr(current, bit)
AttributeError: 'dict' object has no attribute 'minLength'

During handling of the above exception, another exception occurred:

Traceback (most recent call last):
  File "/usr/local/lib/python3.6/dist-packages/django/template/base.py", line 849, in _resolve_lookup
    current = current[int(bit)]
ValueError: invalid literal for int() with base 10: 'minLength'

During handling of the above exception, another exception occurred:

Traceback (most recent call last):
  File "/usr/local/lib/python3.6/dist-packages/django/template/base.py", line 856, in _resolve_lookup
    (bit, current))  # missing attribute
django.template.base.VariableDoesNotExist: Failed lookup for key [minLength] in {'label': 'gNMI secure port', 'type': 'int', 'description': 'Port number the device listens on', 'min': 1, 'max': 65535, 'default': 9339, 'required': True}
[2021-09-05 22:16:46.602 DEBUG                    django.template : 878]
Exception while resolving variable 'maxLength' in template 'ysdevices/device_form.html'.
Traceback (most recent call last):
  File "/usr/local/lib/python3.6/dist-packages/django/template/base.py", line 835, in _resolve_lookup
    current = current[bit]
KeyError: 'maxLength'

During handling of the above exception, another exception occurred:

Traceback (most recent call last):
  File "/usr/local/lib/python3.6/dist-packages/django/template/base.py", line 843, in _resolve_lookup
    current = getattr(current, bit)
AttributeError: 'dict' object has no attribute 'maxLength'

During handling of the above exception, another exception occurred:

Traceback (most recent call last):
  File "/usr/local/lib/python3.6/dist-packages/django/template/base.py", line 849, in _resolve_lookup
    current = current[int(bit)]
ValueError: invalid literal for int() with base 10: 'maxLength'

During handling of the above exception, another exception occurred:

Traceback (most recent call last):
  File "/usr/local/lib/python3.6/dist-packages/django/template/base.py", line 856, in _resolve_lookup
    (bit, current))  # missing attribute
django.template.base.VariableDoesNotExist: Failed lookup for key [maxLength] in {'label': 'gNMI secure port', 'type': 'int', 'description': 'Port number the device listens on', 'min': 1, 'max': 65535, 'default': 9339, 'required': True}
[2021-09-05 22:16:46.602 DEBUG                    django.template : 878]
Exception while resolving variable 'step' in template 'ysdevices/device_form.html'.
Traceback (most recent call last):
  File "/usr/local/lib/python3.6/dist-packages/django/template/base.py", line 835, in _resolve_lookup
    current = current[bit]
KeyError: 'step'

During handling of the above exception, another exception occurred:

Traceback (most recent call last):
  File "/usr/local/lib/python3.6/dist-packages/django/template/base.py", line 843, in _resolve_lookup
    current = getattr(current, bit)
AttributeError: 'dict' object has no attribute 'step'

During handling of the above exception, another exception occurred:

Traceback (most recent call last):
  File "/usr/local/lib/python3.6/dist-packages/django/template/base.py", line 849, in _resolve_lookup
    current = current[int(bit)]
ValueError: invalid literal for int() with base 10: 'step'

During handling of the above exception, another exception occurred:

Traceback (most recent call last):
  File "/usr/local/lib/python3.6/dist-packages/django/template/base.py", line 856, in _resolve_lookup
    (bit, current))  # missing attribute
django.template.base.VariableDoesNotExist: Failed lookup for key [step] in {'label': 'gNMI secure port', 'type': 'int', 'description': 'Port number the device listens on', 'min': 1, 'max': 65535, 'default': 9339, 'required': True}
[2021-09-05 22:16:46.602 DEBUG                    django.template : 878]
Exception while resolving variable 'description' in template 'ysdevices/device_form.html'.
Traceback (most recent call last):
  File "/usr/local/lib/python3.6/dist-packages/django/template/base.py", line 835, in _resolve_lookup
    current = current[bit]
KeyError: 'description'

During handling of the above exception, another exception occurred:

Traceback (most recent call last):
  File "/usr/local/lib/python3.6/dist-packages/django/template/base.py", line 843, in _resolve_lookup
    current = getattr(current, bit)
AttributeError: 'dict' object has no attribute 'description'

During handling of the above exception, another exception occurred:

Traceback (most recent call last):
  File "/usr/local/lib/python3.6/dist-packages/django/template/base.py", line 849, in _resolve_lookup
    current = current[int(bit)]
ValueError: invalid literal for int() with base 10: 'description'

During handling of the above exception, another exception occurred:

Traceback (most recent call last):
  File "/usr/local/lib/python3.6/dist-packages/django/template/base.py", line 856, in _resolve_lookup
    (bit, current))  # missing attribute
django.template.base.VariableDoesNotExist: Failed lookup for key [description] in {'label': 'Use TLS Certificate', 'type': 'boolean', 'default': False}
[2021-09-05 22:16:46.603 DEBUG                    django.template : 878]
Exception while resolving variable 'min' in template 'ysdevices/device_form.html'.
Traceback (most recent call last):
  File "/usr/local/lib/python3.6/dist-packages/django/template/base.py", line 835, in _resolve_lookup
    current = current[bit]
KeyError: 'min'

During handling of the above exception, another exception occurred:

Traceback (most recent call last):
  File "/usr/local/lib/python3.6/dist-packages/django/template/base.py", line 843, in _resolve_lookup
    current = getattr(current, bit)
AttributeError: 'dict' object has no attribute 'min'

During handling of the above exception, another exception occurred:

Traceback (most recent call last):
  File "/usr/local/lib/python3.6/dist-packages/django/template/base.py", line 849, in _resolve_lookup
    current = current[int(bit)]
ValueError: invalid literal for int() with base 10: 'min'

During handling of the above exception, another exception occurred:

Traceback (most recent call last):
  File "/usr/local/lib/python3.6/dist-packages/django/template/base.py", line 856, in _resolve_lookup
    (bit, current))  # missing attribute
django.template.base.VariableDoesNotExist: Failed lookup for key [min] in {'label': 'TLS host override', 'type': 'string', 'description': 'Set to CN of certificate (hostname requires DNS).', 'minLength': 1, 'default': ''}
[2021-09-05 22:16:46.603 DEBUG                    django.template : 878]
Exception while resolving variable 'max' in template 'ysdevices/device_form.html'.
Traceback (most recent call last):
  File "/usr/local/lib/python3.6/dist-packages/django/template/base.py", line 835, in _resolve_lookup
    current = current[bit]
KeyError: 'max'

During handling of the above exception, another exception occurred:

Traceback (most recent call last):
  File "/usr/local/lib/python3.6/dist-packages/django/template/base.py", line 843, in _resolve_lookup
    current = getattr(current, bit)
AttributeError: 'dict' object has no attribute 'max'

During handling of the above exception, another exception occurred:

Traceback (most recent call last):
  File "/usr/local/lib/python3.6/dist-packages/django/template/base.py", line 849, in _resolve_lookup
    current = current[int(bit)]
ValueError: invalid literal for int() with base 10: 'max'

During handling of the above exception, another exception occurred:

Traceback (most recent call last):
  File "/usr/local/lib/python3.6/dist-packages/django/template/base.py", line 856, in _resolve_lookup
    (bit, current))  # missing attribute
django.template.base.VariableDoesNotExist: Failed lookup for key [max] in {'label': 'TLS host override', 'type': 'string', 'description': 'Set to CN of certificate (hostname requires DNS).', 'minLength': 1, 'default': ''}
[2021-09-05 22:16:46.603 DEBUG                    django.template : 878]
Exception while resolving variable 'maxLength' in template 'ysdevices/device_form.html'.
Traceback (most recent call last):
  File "/usr/local/lib/python3.6/dist-packages/django/template/base.py", line 835, in _resolve_lookup
    current = current[bit]
KeyError: 'maxLength'

During handling of the above exception, another exception occurred:

Traceback (most recent call last):
  File "/usr/local/lib/python3.6/dist-packages/django/template/base.py", line 843, in _resolve_lookup
    current = getattr(current, bit)
AttributeError: 'dict' object has no attribute 'maxLength'

During handling of the above exception, another exception occurred:

Traceback (most recent call last):
  File "/usr/local/lib/python3.6/dist-packages/django/template/base.py", line 849, in _resolve_lookup
    current = current[int(bit)]
ValueError: invalid literal for int() with base 10: 'maxLength'

During handling of the above exception, another exception occurred:

Traceback (most recent call last):
  File "/usr/local/lib/python3.6/dist-packages/django/template/base.py", line 856, in _resolve_lookup
    (bit, current))  # missing attribute
django.template.base.VariableDoesNotExist: Failed lookup for key [maxLength] in {'label': 'TLS host override', 'type': 'string', 'description': 'Set to CN of certificate (hostname requires DNS).', 'minLength': 1, 'default': ''}
[2021-09-05 22:16:46.603 DEBUG                    django.template : 878]
Exception while resolving variable 'step' in template 'ysdevices/device_form.html'.
Traceback (most recent call last):
  File "/usr/local/lib/python3.6/dist-packages/django/template/base.py", line 835, in _resolve_lookup
    current = current[bit]
KeyError: 'step'

During handling of the above exception, another exception occurred:

Traceback (most recent call last):
  File "/usr/local/lib/python3.6/dist-packages/django/template/base.py", line 843, in _resolve_lookup
    current = getattr(current, bit)
AttributeError: 'dict' object has no attribute 'step'

During handling of the above exception, another exception occurred:

Traceback (most recent call last):
  File "/usr/local/lib/python3.6/dist-packages/django/template/base.py", line 849, in _resolve_lookup
    current = current[int(bit)]
ValueError: invalid literal for int() with base 10: 'step'

During handling of the above exception, another exception occurred:

Traceback (most recent call last):
  File "/usr/local/lib/python3.6/dist-packages/django/template/base.py", line 856, in _resolve_lookup
    (bit, current))  # missing attribute
django.template.base.VariableDoesNotExist: Failed lookup for key [step] in {'label': 'TLS host override', 'type': 'string', 'description': 'Set to CN of certificate (hostname requires DNS).', 'minLength': 1, 'default': ''}
[2021-09-05 22:16:46.604 DEBUG                    django.template : 878]
Exception while resolving variable 'required' in template 'ysdevices/device_form.html'.
Traceback (most recent call last):
  File "/usr/local/lib/python3.6/dist-packages/django/template/base.py", line 835, in _resolve_lookup
    current = current[bit]
KeyError: 'required'

During handling of the above exception, another exception occurred:

Traceback (most recent call last):
  File "/usr/local/lib/python3.6/dist-packages/django/template/base.py", line 843, in _resolve_lookup
    current = getattr(current, bit)
AttributeError: 'dict' object has no attribute 'required'

During handling of the above exception, another exception occurred:

Traceback (most recent call last):
  File "/usr/local/lib/python3.6/dist-packages/django/template/base.py", line 849, in _resolve_lookup
    current = current[int(bit)]
ValueError: invalid literal for int() with base 10: 'required'

During handling of the above exception, another exception occurred:

Traceback (most recent call last):
  File "/usr/local/lib/python3.6/dist-packages/django/template/base.py", line 856, in _resolve_lookup
    (bit, current))  # missing attribute
django.template.base.VariableDoesNotExist: Failed lookup for key [required] in {'label': 'TLS host override', 'type': 'string', 'description': 'Set to CN of certificate (hostname requires DNS).', 'minLength': 1, 'default': ''}
[2021-09-05 22:16:46.604 DEBUG                    django.template : 878]
Exception while resolving variable 'required' in template 'ysdevices/device_form.html'.
Traceback (most recent call last):
  File "/usr/local/lib/python3.6/dist-packages/django/template/base.py", line 835, in _resolve_lookup
    current = current[bit]
KeyError: 'required'

During handling of the above exception, another exception occurred:

Traceback (most recent call last):
  File "/usr/local/lib/python3.6/dist-packages/django/template/base.py", line 843, in _resolve_lookup
    current = getattr(current, bit)
AttributeError: 'dict' object has no attribute 'required'

During handling of the above exception, another exception occurred:

Traceback (most recent call last):
  File "/usr/local/lib/python3.6/dist-packages/django/template/base.py", line 849, in _resolve_lookup
    current = current[int(bit)]
ValueError: invalid literal for int() with base 10: 'required'

During handling of the above exception, another exception occurred:

Traceback (most recent call last):
  File "/usr/local/lib/python3.6/dist-packages/django/template/base.py", line 856, in _resolve_lookup
    (bit, current))  # missing attribute
django.template.base.VariableDoesNotExist: Failed lookup for key [required] in {'label': 'TLS host override', 'type': 'string', 'description': 'Set to CN of certificate (hostname requires DNS).', 'minLength': 1, 'default': ''}
[2021-09-05 22:16:46.604 DEBUG                    django.template : 878]
Exception while resolving variable 'required' in template 'ysdevices/device_form.html'.
Traceback (most recent call last):
  File "/usr/local/lib/python3.6/dist-packages/django/template/base.py", line 835, in _resolve_lookup
    current = current[bit]
KeyError: 'required'

During handling of the above exception, another exception occurred:

Traceback (most recent call last):
  File "/usr/local/lib/python3.6/dist-packages/django/template/base.py", line 843, in _resolve_lookup
    current = getattr(current, bit)
AttributeError: 'dict' object has no attribute 'required'

During handling of the above exception, another exception occurred:

Traceback (most recent call last):
  File "/usr/local/lib/python3.6/dist-packages/django/template/base.py", line 849, in _resolve_lookup
    current = current[int(bit)]
ValueError: invalid literal for int() with base 10: 'required'

During handling of the above exception, another exception occurred:

Traceback (most recent call last):
  File "/usr/local/lib/python3.6/dist-packages/django/template/base.py", line 856, in _resolve_lookup
    (bit, current))  # missing attribute
django.template.base.VariableDoesNotExist: Failed lookup for key [required] in {'label': 'TLS host override', 'type': 'string', 'description': 'Set to CN of certificate (hostname requires DNS).', 'minLength': 1, 'default': ''}
[2021-09-05 22:16:46.605 DEBUG                    django.template : 878]
Exception while resolving variable 'description' in template 'ysdevices/device_form.html'.
Traceback (most recent call last):
  File "/usr/local/lib/python3.6/dist-packages/django/template/base.py", line 835, in _resolve_lookup
    current = current[bit]
KeyError: 'description'

During handling of the above exception, another exception occurred:

Traceback (most recent call last):
  File "/usr/local/lib/python3.6/dist-packages/django/template/base.py", line 843, in _resolve_lookup
    current = getattr(current, bit)
AttributeError: 'dict' object has no attribute 'description'

During handling of the above exception, another exception occurred:

Traceback (most recent call last):
  File "/usr/local/lib/python3.6/dist-packages/django/template/base.py", line 849, in _resolve_lookup
    current = current[int(bit)]
ValueError: invalid literal for int() with base 10: 'description'

During handling of the above exception, another exception occurred:

Traceback (most recent call last):
  File "/usr/local/lib/python3.6/dist-packages/django/template/base.py", line 856, in _resolve_lookup
    (bit, current))  # missing attribute
django.template.base.VariableDoesNotExist: Failed lookup for key [description] in {'label': 'Device supports NETCONF', 'type': 'boolean', 'default': False}
[2021-09-05 22:16:46.606 DEBUG                    django.template : 878]
Exception while resolving variable 'minLength' in template 'ysdevices/device_form.html'.
Traceback (most recent call last):
  File "/usr/local/lib/python3.6/dist-packages/django/template/base.py", line 835, in _resolve_lookup
    current = current[bit]
KeyError: 'minLength'

During handling of the above exception, another exception occurred:

Traceback (most recent call last):
  File "/usr/local/lib/python3.6/dist-packages/django/template/base.py", line 843, in _resolve_lookup
    current = getattr(current, bit)
AttributeError: 'dict' object has no attribute 'minLength'

During handling of the above exception, another exception occurred:

Traceback (most recent call last):
  File "/usr/local/lib/python3.6/dist-packages/django/template/base.py", line 849, in _resolve_lookup
    current = current[int(bit)]
ValueError: invalid literal for int() with base 10: 'minLength'

During handling of the above exception, another exception occurred:

Traceback (most recent call last):
  File "/usr/local/lib/python3.6/dist-packages/django/template/base.py", line 856, in _resolve_lookup
    (bit, current))  # missing attribute
django.template.base.VariableDoesNotExist: Failed lookup for key [minLength] in {'label': 'NETCONF port', 'type': 'int', 'description': 'Port number NETCONF listens on', 'min': 1, 'max': 65535, 'default': 830, 'required': True}
[2021-09-05 22:16:46.606 DEBUG                    django.template : 878]
Exception while resolving variable 'maxLength' in template 'ysdevices/device_form.html'.
Traceback (most recent call last):
  File "/usr/local/lib/python3.6/dist-packages/django/template/base.py", line 835, in _resolve_lookup
    current = current[bit]
KeyError: 'maxLength'

During handling of the above exception, another exception occurred:

Traceback (most recent call last):
  File "/usr/local/lib/python3.6/dist-packages/django/template/base.py", line 843, in _resolve_lookup
    current = getattr(current, bit)
AttributeError: 'dict' object has no attribute 'maxLength'

During handling of the above exception, another exception occurred:

Traceback (most recent call last):
  File "/usr/local/lib/python3.6/dist-packages/django/template/base.py", line 849, in _resolve_lookup
    current = current[int(bit)]
ValueError: invalid literal for int() with base 10: 'maxLength'

During handling of the above exception, another exception occurred:

Traceback (most recent call last):
  File "/usr/local/lib/python3.6/dist-packages/django/template/base.py", line 856, in _resolve_lookup
    (bit, current))  # missing attribute
django.template.base.VariableDoesNotExist: Failed lookup for key [maxLength] in {'label': 'NETCONF port', 'type': 'int', 'description': 'Port number NETCONF listens on', 'min': 1, 'max': 65535, 'default': 830, 'required': True}
[2021-09-05 22:16:46.606 DEBUG                    django.template : 878]
Exception while resolving variable 'step' in template 'ysdevices/device_form.html'.
Traceback (most recent call last):
  File "/usr/local/lib/python3.6/dist-packages/django/template/base.py", line 835, in _resolve_lookup
    current = current[bit]
KeyError: 'step'

During handling of the above exception, another exception occurred:

Traceback (most recent call last):
  File "/usr/local/lib/python3.6/dist-packages/django/template/base.py", line 843, in _resolve_lookup
    current = getattr(current, bit)
AttributeError: 'dict' object has no attribute 'step'

During handling of the above exception, another exception occurred:

Traceback (most recent call last):
  File "/usr/local/lib/python3.6/dist-packages/django/template/base.py", line 849, in _resolve_lookup
    current = current[int(bit)]
ValueError: invalid literal for int() with base 10: 'step'

During handling of the above exception, another exception occurred:

Traceback (most recent call last):
  File "/usr/local/lib/python3.6/dist-packages/django/template/base.py", line 856, in _resolve_lookup
    (bit, current))  # missing attribute
django.template.base.VariableDoesNotExist: Failed lookup for key [step] in {'label': 'NETCONF port', 'type': 'int', 'description': 'Port number NETCONF listens on', 'min': 1, 'max': 65535, 'default': 830, 'required': True}
[2021-09-05 22:16:46.607 DEBUG                    django.template : 878]
Exception while resolving variable 'description' in template 'ysdevices/device_form.html'.
Traceback (most recent call last):
  File "/usr/local/lib/python3.6/dist-packages/django/template/base.py", line 835, in _resolve_lookup
    current = current[bit]
KeyError: 'description'

During handling of the above exception, another exception occurred:

Traceback (most recent call last):
  File "/usr/local/lib/python3.6/dist-packages/django/template/base.py", line 843, in _resolve_lookup
    current = getattr(current, bit)
AttributeError: 'dict' object has no attribute 'description'

During handling of the above exception, another exception occurred:

Traceback (most recent call last):
  File "/usr/local/lib/python3.6/dist-packages/django/template/base.py", line 849, in _resolve_lookup
    current = current[int(bit)]
ValueError: invalid literal for int() with base 10: 'description'

During handling of the above exception, another exception occurred:

Traceback (most recent call last):
  File "/usr/local/lib/python3.6/dist-packages/django/template/base.py", line 856, in _resolve_lookup
    (bit, current))  # missing attribute
django.template.base.VariableDoesNotExist: Failed lookup for key [description] in {'label': 'Skip SSH key validation for this device', 'type': 'boolean', 'default': False}
[2021-09-05 22:16:46.607 DEBUG                    django.template : 878]
Exception while resolving variable 'min' in template 'ysdevices/device_form.html'.
Traceback (most recent call last):
  File "/usr/local/lib/python3.6/dist-packages/django/template/base.py", line 835, in _resolve_lookup
    current = current[bit]
KeyError: 'min'

During handling of the above exception, another exception occurred:

Traceback (most recent call last):
  File "/usr/local/lib/python3.6/dist-packages/django/template/base.py", line 843, in _resolve_lookup
    current = getattr(current, bit)
AttributeError: 'dict' object has no attribute 'min'

During handling of the above exception, another exception occurred:

Traceback (most recent call last):
  File "/usr/local/lib/python3.6/dist-packages/django/template/base.py", line 849, in _resolve_lookup
    current = current[int(bit)]
ValueError: invalid literal for int() with base 10: 'min'

During handling of the above exception, another exception occurred:

Traceback (most recent call last):
  File "/usr/local/lib/python3.6/dist-packages/django/template/base.py", line 856, in _resolve_lookup
    (bit, current))  # missing attribute
django.template.base.VariableDoesNotExist: Failed lookup for key [min] in {'type': 'string', 'description': 'Address or hostname to access via NETCONF', 'default': ''}
[2021-09-05 22:16:46.607 DEBUG                    django.template : 878]
Exception while resolving variable 'minLength' in template 'ysdevices/device_form.html'.
Traceback (most recent call last):
  File "/usr/local/lib/python3.6/dist-packages/django/template/base.py", line 835, in _resolve_lookup
    current = current[bit]
KeyError: 'minLength'

During handling of the above exception, another exception occurred:

Traceback (most recent call last):
  File "/usr/local/lib/python3.6/dist-packages/django/template/base.py", line 843, in _resolve_lookup
    current = getattr(current, bit)
AttributeError: 'dict' object has no attribute 'minLength'

During handling of the above exception, another exception occurred:

Traceback (most recent call last):
  File "/usr/local/lib/python3.6/dist-packages/django/template/base.py", line 849, in _resolve_lookup
    current = current[int(bit)]
ValueError: invalid literal for int() with base 10: 'minLength'

During handling of the above exception, another exception occurred:

Traceback (most recent call last):
  File "/usr/local/lib/python3.6/dist-packages/django/template/base.py", line 856, in _resolve_lookup
    (bit, current))  # missing attribute
django.template.base.VariableDoesNotExist: Failed lookup for key [minLength] in {'type': 'string', 'description': 'Address or hostname to access via NETCONF', 'default': ''}
[2021-09-05 22:16:46.608 DEBUG                    django.template : 878]
Exception while resolving variable 'max' in template 'ysdevices/device_form.html'.
Traceback (most recent call last):
  File "/usr/local/lib/python3.6/dist-packages/django/template/base.py", line 835, in _resolve_lookup
    current = current[bit]
KeyError: 'max'

During handling of the above exception, another exception occurred:

Traceback (most recent call last):
  File "/usr/local/lib/python3.6/dist-packages/django/template/base.py", line 843, in _resolve_lookup
    current = getattr(current, bit)
AttributeError: 'dict' object has no attribute 'max'

During handling of the above exception, another exception occurred:

Traceback (most recent call last):
  File "/usr/local/lib/python3.6/dist-packages/django/template/base.py", line 849, in _resolve_lookup
    current = current[int(bit)]
ValueError: invalid literal for int() with base 10: 'max'

During handling of the above exception, another exception occurred:

Traceback (most recent call last):
  File "/usr/local/lib/python3.6/dist-packages/django/template/base.py", line 856, in _resolve_lookup
    (bit, current))  # missing attribute
django.template.base.VariableDoesNotExist: Failed lookup for key [max] in {'type': 'string', 'description': 'Address or hostname to access via NETCONF', 'default': ''}
[2021-09-05 22:16:46.608 DEBUG                    django.template : 878]
Exception while resolving variable 'maxLength' in template 'ysdevices/device_form.html'.
Traceback (most recent call last):
  File "/usr/local/lib/python3.6/dist-packages/django/template/base.py", line 835, in _resolve_lookup
    current = current[bit]
KeyError: 'maxLength'

During handling of the above exception, another exception occurred:

Traceback (most recent call last):
  File "/usr/local/lib/python3.6/dist-packages/django/template/base.py", line 843, in _resolve_lookup
    current = getattr(current, bit)
AttributeError: 'dict' object has no attribute 'maxLength'

During handling of the above exception, another exception occurred:

Traceback (most recent call last):
  File "/usr/local/lib/python3.6/dist-packages/django/template/base.py", line 849, in _resolve_lookup
    current = current[int(bit)]
ValueError: invalid literal for int() with base 10: 'maxLength'

During handling of the above exception, another exception occurred:

Traceback (most recent call last):
  File "/usr/local/lib/python3.6/dist-packages/django/template/base.py", line 856, in _resolve_lookup
    (bit, current))  # missing attribute
django.template.base.VariableDoesNotExist: Failed lookup for key [maxLength] in {'type': 'string', 'description': 'Address or hostname to access via NETCONF', 'default': ''}
[2021-09-05 22:16:46.608 DEBUG                    django.template : 878]
Exception while resolving variable 'step' in template 'ysdevices/device_form.html'.
Traceback (most recent call last):
  File "/usr/local/lib/python3.6/dist-packages/django/template/base.py", line 835, in _resolve_lookup
    current = current[bit]
KeyError: 'step'

During handling of the above exception, another exception occurred:

Traceback (most recent call last):
  File "/usr/local/lib/python3.6/dist-packages/django/template/base.py", line 843, in _resolve_lookup
    current = getattr(current, bit)
AttributeError: 'dict' object has no attribute 'step'

During handling of the above exception, another exception occurred:

Traceback (most recent call last):
  File "/usr/local/lib/python3.6/dist-packages/django/template/base.py", line 849, in _resolve_lookup
    current = current[int(bit)]
ValueError: invalid literal for int() with base 10: 'step'

During handling of the above exception, another exception occurred:

Traceback (most recent call last):
  File "/usr/local/lib/python3.6/dist-packages/django/template/base.py", line 856, in _resolve_lookup
    (bit, current))  # missing attribute
django.template.base.VariableDoesNotExist: Failed lookup for key [step] in {'type': 'string', 'description': 'Address or hostname to access via NETCONF', 'default': ''}
[2021-09-05 22:16:46.608 DEBUG                    django.template : 878]
Exception while resolving variable 'required' in template 'ysdevices/device_form.html'.
Traceback (most recent call last):
  File "/usr/local/lib/python3.6/dist-packages/django/template/base.py", line 835, in _resolve_lookup
    current = current[bit]
KeyError: 'required'

During handling of the above exception, another exception occurred:

Traceback (most recent call last):
  File "/usr/local/lib/python3.6/dist-packages/django/template/base.py", line 843, in _resolve_lookup
    current = getattr(current, bit)
AttributeError: 'dict' object has no attribute 'required'

During handling of the above exception, another exception occurred:

Traceback (most recent call last):
  File "/usr/local/lib/python3.6/dist-packages/django/template/base.py", line 849, in _resolve_lookup
    current = current[int(bit)]
ValueError: invalid literal for int() with base 10: 'required'

During handling of the above exception, another exception occurred:

Traceback (most recent call last):
  File "/usr/local/lib/python3.6/dist-packages/django/template/base.py", line 856, in _resolve_lookup
    (bit, current))  # missing attribute
django.template.base.VariableDoesNotExist: Failed lookup for key [required] in {'type': 'string', 'description': 'Address or hostname to access via NETCONF', 'default': ''}
[2021-09-05 22:16:46.609 DEBUG                    django.template : 878]
Exception while resolving variable 'required' in template 'ysdevices/device_form.html'.
Traceback (most recent call last):
  File "/usr/local/lib/python3.6/dist-packages/django/template/base.py", line 835, in _resolve_lookup
    current = current[bit]
KeyError: 'required'

During handling of the above exception, another exception occurred:

Traceback (most recent call last):
  File "/usr/local/lib/python3.6/dist-packages/django/template/base.py", line 843, in _resolve_lookup
    current = getattr(current, bit)
AttributeError: 'dict' object has no attribute 'required'

During handling of the above exception, another exception occurred:

Traceback (most recent call last):
  File "/usr/local/lib/python3.6/dist-packages/django/template/base.py", line 849, in _resolve_lookup
    current = current[int(bit)]
ValueError: invalid literal for int() with base 10: 'required'

During handling of the above exception, another exception occurred:

Traceback (most recent call last):
  File "/usr/local/lib/python3.6/dist-packages/django/template/base.py", line 856, in _resolve_lookup
    (bit, current))  # missing attribute
django.template.base.VariableDoesNotExist: Failed lookup for key [required] in {'type': 'string', 'description': 'Address or hostname to access via NETCONF', 'default': ''}
[2021-09-05 22:16:46.609 DEBUG                    django.template : 878]
Exception while resolving variable 'label' in template 'ysdevices/device_form.html'.
Traceback (most recent call last):
  File "/usr/local/lib/python3.6/dist-packages/django/template/base.py", line 835, in _resolve_lookup
    current = current[bit]
KeyError: 'label'

During handling of the above exception, another exception occurred:

Traceback (most recent call last):
  File "/usr/local/lib/python3.6/dist-packages/django/template/base.py", line 843, in _resolve_lookup
    current = getattr(current, bit)
AttributeError: 'dict' object has no attribute 'label'

During handling of the above exception, another exception occurred:

Traceback (most recent call last):
  File "/usr/local/lib/python3.6/dist-packages/django/template/base.py", line 849, in _resolve_lookup
    current = current[int(bit)]
ValueError: invalid literal for int() with base 10: 'label'

During handling of the above exception, another exception occurred:

Traceback (most recent call last):
  File "/usr/local/lib/python3.6/dist-packages/django/template/base.py", line 856, in _resolve_lookup
    (bit, current))  # missing attribute
django.template.base.VariableDoesNotExist: Failed lookup for key [label] in {'type': 'string', 'description': 'Address or hostname to access via NETCONF', 'default': ''}
[2021-09-05 22:16:46.609 DEBUG                    django.template : 878]
Exception while resolving variable 'required' in template 'ysdevices/device_form.html'.
Traceback (most recent call last):
  File "/usr/local/lib/python3.6/dist-packages/django/template/base.py", line 835, in _resolve_lookup
    current = current[bit]
KeyError: 'required'

During handling of the above exception, another exception occurred:

Traceback (most recent call last):
  File "/usr/local/lib/python3.6/dist-packages/django/template/base.py", line 843, in _resolve_lookup
    current = getattr(current, bit)
AttributeError: 'dict' object has no attribute 'required'

During handling of the above exception, another exception occurred:

Traceback (most recent call last):
  File "/usr/local/lib/python3.6/dist-packages/django/template/base.py", line 849, in _resolve_lookup
    current = current[int(bit)]
ValueError: invalid literal for int() with base 10: 'required'

During handling of the above exception, another exception occurred:

Traceback (most recent call last):
  File "/usr/local/lib/python3.6/dist-packages/django/template/base.py", line 856, in _resolve_lookup
    (bit, current))  # missing attribute
django.template.base.VariableDoesNotExist: Failed lookup for key [required] in {'type': 'string', 'description': 'Address or hostname to access via NETCONF', 'default': ''}
[2021-09-05 22:16:46.609 DEBUG                    django.template : 878]
Exception while resolving variable 'min' in template 'ysdevices/device_form.html'.
Traceback (most recent call last):
  File "/usr/local/lib/python3.6/dist-packages/django/template/base.py", line 835, in _resolve_lookup
    current = current[bit]
KeyError: 'min'

During handling of the above exception, another exception occurred:

Traceback (most recent call last):
  File "/usr/local/lib/python3.6/dist-packages/django/template/base.py", line 843, in _resolve_lookup
    current = getattr(current, bit)
AttributeError: 'dict' object has no attribute 'min'

During handling of the above exception, another exception occurred:

Traceback (most recent call last):
  File "/usr/local/lib/python3.6/dist-packages/django/template/base.py", line 849, in _resolve_lookup
    current = current[int(bit)]
ValueError: invalid literal for int() with base 10: 'min'

During handling of the above exception, another exception occurred:

Traceback (most recent call last):
  File "/usr/local/lib/python3.6/dist-packages/django/template/base.py", line 856, in _resolve_lookup
    (bit, current))  # missing attribute
django.template.base.VariableDoesNotExist: Failed lookup for key [min] in {'type': 'string', 'description': 'Username to access the device via NETCONF', 'minLength': 1, 'maxLength': 50, 'default': ''}
[2021-09-05 22:16:46.610 DEBUG                    django.template : 878]
Exception while resolving variable 'max' in template 'ysdevices/device_form.html'.
Traceback (most recent call last):
  File "/usr/local/lib/python3.6/dist-packages/django/template/base.py", line 835, in _resolve_lookup
    current = current[bit]
KeyError: 'max'

During handling of the above exception, another exception occurred:

Traceback (most recent call last):
  File "/usr/local/lib/python3.6/dist-packages/django/template/base.py", line 843, in _resolve_lookup
    current = getattr(current, bit)
AttributeError: 'dict' object has no attribute 'max'

During handling of the above exception, another exception occurred:

Traceback (most recent call last):
  File "/usr/local/lib/python3.6/dist-packages/django/template/base.py", line 849, in _resolve_lookup
    current = current[int(bit)]
ValueError: invalid literal for int() with base 10: 'max'

During handling of the above exception, another exception occurred:

Traceback (most recent call last):
  File "/usr/local/lib/python3.6/dist-packages/django/template/base.py", line 856, in _resolve_lookup
    (bit, current))  # missing attribute
django.template.base.VariableDoesNotExist: Failed lookup for key [max] in {'type': 'string', 'description': 'Username to access the device via NETCONF', 'minLength': 1, 'maxLength': 50, 'default': ''}
[2021-09-05 22:16:46.610 DEBUG                    django.template : 878]
Exception while resolving variable 'step' in template 'ysdevices/device_form.html'.
Traceback (most recent call last):
  File "/usr/local/lib/python3.6/dist-packages/django/template/base.py", line 835, in _resolve_lookup
    current = current[bit]
KeyError: 'step'

During handling of the above exception, another exception occurred:

Traceback (most recent call last):
  File "/usr/local/lib/python3.6/dist-packages/django/template/base.py", line 843, in _resolve_lookup
    current = getattr(current, bit)
AttributeError: 'dict' object has no attribute 'step'

During handling of the above exception, another exception occurred:

Traceback (most recent call last):
  File "/usr/local/lib/python3.6/dist-packages/django/template/base.py", line 849, in _resolve_lookup
    current = current[int(bit)]
ValueError: invalid literal for int() with base 10: 'step'

During handling of the above exception, another exception occurred:

Traceback (most recent call last):
  File "/usr/local/lib/python3.6/dist-packages/django/template/base.py", line 856, in _resolve_lookup
    (bit, current))  # missing attribute
django.template.base.VariableDoesNotExist: Failed lookup for key [step] in {'type': 'string', 'description': 'Username to access the device via NETCONF', 'minLength': 1, 'maxLength': 50, 'default': ''}
[2021-09-05 22:16:46.610 DEBUG                    django.template : 878]
Exception while resolving variable 'required' in template 'ysdevices/device_form.html'.
Traceback (most recent call last):
  File "/usr/local/lib/python3.6/dist-packages/django/template/base.py", line 835, in _resolve_lookup
    current = current[bit]
KeyError: 'required'

During handling of the above exception, another exception occurred:

Traceback (most recent call last):
  File "/usr/local/lib/python3.6/dist-packages/django/template/base.py", line 843, in _resolve_lookup
    current = getattr(current, bit)
AttributeError: 'dict' object has no attribute 'required'

During handling of the above exception, another exception occurred:

Traceback (most recent call last):
  File "/usr/local/lib/python3.6/dist-packages/django/template/base.py", line 849, in _resolve_lookup
    current = current[int(bit)]
ValueError: invalid literal for int() with base 10: 'required'

During handling of the above exception, another exception occurred:

Traceback (most recent call last):
  File "/usr/local/lib/python3.6/dist-packages/django/template/base.py", line 856, in _resolve_lookup
    (bit, current))  # missing attribute
django.template.base.VariableDoesNotExist: Failed lookup for key [required] in {'type': 'string', 'description': 'Username to access the device via NETCONF', 'minLength': 1, 'maxLength': 50, 'default': ''}
[2021-09-05 22:16:46.611 DEBUG                    django.template : 878]
Exception while resolving variable 'required' in template 'ysdevices/device_form.html'.
Traceback (most recent call last):
  File "/usr/local/lib/python3.6/dist-packages/django/template/base.py", line 835, in _resolve_lookup
    current = current[bit]
KeyError: 'required'

During handling of the above exception, another exception occurred:

Traceback (most recent call last):
  File "/usr/local/lib/python3.6/dist-packages/django/template/base.py", line 843, in _resolve_lookup
    current = getattr(current, bit)
AttributeError: 'dict' object has no attribute 'required'

During handling of the above exception, another exception occurred:

Traceback (most recent call last):
  File "/usr/local/lib/python3.6/dist-packages/django/template/base.py", line 849, in _resolve_lookup
    current = current[int(bit)]
ValueError: invalid literal for int() with base 10: 'required'

During handling of the above exception, another exception occurred:

Traceback (most recent call last):
  File "/usr/local/lib/python3.6/dist-packages/django/template/base.py", line 856, in _resolve_lookup
    (bit, current))  # missing attribute
django.template.base.VariableDoesNotExist: Failed lookup for key [required] in {'type': 'string', 'description': 'Username to access the device via NETCONF', 'minLength': 1, 'maxLength': 50, 'default': ''}
[2021-09-05 22:16:46.611 DEBUG                    django.template : 878]
Exception while resolving variable 'label' in template 'ysdevices/device_form.html'.
Traceback (most recent call last):
  File "/usr/local/lib/python3.6/dist-packages/django/template/base.py", line 835, in _resolve_lookup
    current = current[bit]
KeyError: 'label'

During handling of the above exception, another exception occurred:

Traceback (most recent call last):
  File "/usr/local/lib/python3.6/dist-packages/django/template/base.py", line 843, in _resolve_lookup
    current = getattr(current, bit)
AttributeError: 'dict' object has no attribute 'label'

During handling of the above exception, another exception occurred:

Traceback (most recent call last):
  File "/usr/local/lib/python3.6/dist-packages/django/template/base.py", line 849, in _resolve_lookup
    current = current[int(bit)]
ValueError: invalid literal for int() with base 10: 'label'

During handling of the above exception, another exception occurred:

Traceback (most recent call last):
  File "/usr/local/lib/python3.6/dist-packages/django/template/base.py", line 856, in _resolve_lookup
    (bit, current))  # missing attribute
django.template.base.VariableDoesNotExist: Failed lookup for key [label] in {'type': 'string', 'description': 'Username to access the device via NETCONF', 'minLength': 1, 'maxLength': 50, 'default': ''}
[2021-09-05 22:16:46.611 DEBUG                    django.template : 878]
Exception while resolving variable 'required' in template 'ysdevices/device_form.html'.
Traceback (most recent call last):
  File "/usr/local/lib/python3.6/dist-packages/django/template/base.py", line 835, in _resolve_lookup
    current = current[bit]
KeyError: 'required'

During handling of the above exception, another exception occurred:

Traceback (most recent call last):
  File "/usr/local/lib/python3.6/dist-packages/django/template/base.py", line 843, in _resolve_lookup
    current = getattr(current, bit)
AttributeError: 'dict' object has no attribute 'required'

During handling of the above exception, another exception occurred:

Traceback (most recent call last):
  File "/usr/local/lib/python3.6/dist-packages/django/template/base.py", line 849, in _resolve_lookup
    current = current[int(bit)]
ValueError: invalid literal for int() with base 10: 'required'

During handling of the above exception, another exception occurred:

Traceback (most recent call last):
  File "/usr/local/lib/python3.6/dist-packages/django/template/base.py", line 856, in _resolve_lookup
    (bit, current))  # missing attribute
django.template.base.VariableDoesNotExist: Failed lookup for key [required] in {'type': 'string', 'description': 'Username to access the device via NETCONF', 'minLength': 1, 'maxLength': 50, 'default': ''}
[2021-09-05 22:16:46.611 DEBUG                    django.template : 878]
Exception while resolving variable 'min' in template 'ysdevices/device_form.html'.
Traceback (most recent call last):
  File "/usr/local/lib/python3.6/dist-packages/django/template/base.py", line 835, in _resolve_lookup
    current = current[bit]
KeyError: 'min'

During handling of the above exception, another exception occurred:

Traceback (most recent call last):
  File "/usr/local/lib/python3.6/dist-packages/django/template/base.py", line 843, in _resolve_lookup
    current = getattr(current, bit)
AttributeError: 'dict' object has no attribute 'min'

During handling of the above exception, another exception occurred:

Traceback (most recent call last):
  File "/usr/local/lib/python3.6/dist-packages/django/template/base.py", line 849, in _resolve_lookup
    current = current[int(bit)]
ValueError: invalid literal for int() with base 10: 'min'

During handling of the above exception, another exception occurred:

Traceback (most recent call last):
  File "/usr/local/lib/python3.6/dist-packages/django/template/base.py", line 856, in _resolve_lookup
    (bit, current))  # missing attribute
django.template.base.VariableDoesNotExist: Failed lookup for key [min] in {'type': 'password', 'description': 'Password to access the device via NETCONF', 'minLength': 1, 'maxLength': 50}
[2021-09-05 22:16:46.612 DEBUG                    django.template : 878]
Exception while resolving variable 'max' in template 'ysdevices/device_form.html'.
Traceback (most recent call last):
  File "/usr/local/lib/python3.6/dist-packages/django/template/base.py", line 835, in _resolve_lookup
    current = current[bit]
KeyError: 'max'

During handling of the above exception, another exception occurred:

Traceback (most recent call last):
  File "/usr/local/lib/python3.6/dist-packages/django/template/base.py", line 843, in _resolve_lookup
    current = getattr(current, bit)
AttributeError: 'dict' object has no attribute 'max'

During handling of the above exception, another exception occurred:

Traceback (most recent call last):
  File "/usr/local/lib/python3.6/dist-packages/django/template/base.py", line 849, in _resolve_lookup
    current = current[int(bit)]
ValueError: invalid literal for int() with base 10: 'max'

During handling of the above exception, another exception occurred:

Traceback (most recent call last):
  File "/usr/local/lib/python3.6/dist-packages/django/template/base.py", line 856, in _resolve_lookup
    (bit, current))  # missing attribute
django.template.base.VariableDoesNotExist: Failed lookup for key [max] in {'type': 'password', 'description': 'Password to access the device via NETCONF', 'minLength': 1, 'maxLength': 50}
[2021-09-05 22:16:46.612 DEBUG                    django.template : 878]
Exception while resolving variable 'step' in template 'ysdevices/device_form.html'.
Traceback (most recent call last):
  File "/usr/local/lib/python3.6/dist-packages/django/template/base.py", line 835, in _resolve_lookup
    current = current[bit]
KeyError: 'step'

During handling of the above exception, another exception occurred:

Traceback (most recent call last):
  File "/usr/local/lib/python3.6/dist-packages/django/template/base.py", line 843, in _resolve_lookup
    current = getattr(current, bit)
AttributeError: 'dict' object has no attribute 'step'

During handling of the above exception, another exception occurred:

Traceback (most recent call last):
  File "/usr/local/lib/python3.6/dist-packages/django/template/base.py", line 849, in _resolve_lookup
    current = current[int(bit)]
ValueError: invalid literal for int() with base 10: 'step'

During handling of the above exception, another exception occurred:

Traceback (most recent call last):
  File "/usr/local/lib/python3.6/dist-packages/django/template/base.py", line 856, in _resolve_lookup
    (bit, current))  # missing attribute
django.template.base.VariableDoesNotExist: Failed lookup for key [step] in {'type': 'password', 'description': 'Password to access the device via NETCONF', 'minLength': 1, 'maxLength': 50}
[2021-09-05 22:16:46.614 DEBUG                    django.template : 878]
Exception while resolving variable 'default' in template 'ysdevices/device_form.html'.
Traceback (most recent call last):
  File "/usr/local/lib/python3.6/dist-packages/django/template/base.py", line 835, in _resolve_lookup
    current = current[bit]
KeyError: 'default'

During handling of the above exception, another exception occurred:

Traceback (most recent call last):
  File "/usr/local/lib/python3.6/dist-packages/django/template/base.py", line 843, in _resolve_lookup
    current = getattr(current, bit)
AttributeError: 'dict' object has no attribute 'default'

During handling of the above exception, another exception occurred:

Traceback (most recent call last):
  File "/usr/local/lib/python3.6/dist-packages/django/template/base.py", line 849, in _resolve_lookup
    current = current[int(bit)]
ValueError: invalid literal for int() with base 10: 'default'

During handling of the above exception, another exception occurred:

Traceback (most recent call last):
  File "/usr/local/lib/python3.6/dist-packages/django/template/base.py", line 856, in _resolve_lookup
    (bit, current))  # missing attribute
django.template.base.VariableDoesNotExist: Failed lookup for key [default] in {'type': 'password', 'description': 'Password to access the device via NETCONF', 'minLength': 1, 'maxLength': 50}
[2021-09-05 22:16:46.614 DEBUG                    django.template : 878]
Exception while resolving variable 'default' in template 'ysdevices/device_form.html'.
Traceback (most recent call last):
  File "/usr/local/lib/python3.6/dist-packages/django/template/base.py", line 835, in _resolve_lookup
    current = current[bit]
KeyError: 'default'

During handling of the above exception, another exception occurred:

Traceback (most recent call last):
  File "/usr/local/lib/python3.6/dist-packages/django/template/base.py", line 843, in _resolve_lookup
    current = getattr(current, bit)
AttributeError: 'dict' object has no attribute 'default'

During handling of the above exception, another exception occurred:

Traceback (most recent call last):
  File "/usr/local/lib/python3.6/dist-packages/django/template/base.py", line 849, in _resolve_lookup
    current = current[int(bit)]
ValueError: invalid literal for int() with base 10: 'default'

During handling of the above exception, another exception occurred:

Traceback (most recent call last):
  File "/usr/local/lib/python3.6/dist-packages/django/template/base.py", line 856, in _resolve_lookup
    (bit, current))  # missing attribute
django.template.base.VariableDoesNotExist: Failed lookup for key [default] in {'type': 'password', 'description': 'Password to access the device via NETCONF', 'minLength': 1, 'maxLength': 50}
[2021-09-05 22:16:46.614 DEBUG                    django.template : 878]
Exception while resolving variable 'required' in template 'ysdevices/device_form.html'.
Traceback (most recent call last):
  File "/usr/local/lib/python3.6/dist-packages/django/template/base.py", line 835, in _resolve_lookup
    current = current[bit]
KeyError: 'required'

During handling of the above exception, another exception occurred:

Traceback (most recent call last):
  File "/usr/local/lib/python3.6/dist-packages/django/template/base.py", line 843, in _resolve_lookup
    current = getattr(current, bit)
AttributeError: 'dict' object has no attribute 'required'

During handling of the above exception, another exception occurred:

Traceback (most recent call last):
  File "/usr/local/lib/python3.6/dist-packages/django/template/base.py", line 849, in _resolve_lookup
    current = current[int(bit)]
ValueError: invalid literal for int() with base 10: 'required'

During handling of the above exception, another exception occurred:

Traceback (most recent call last):
  File "/usr/local/lib/python3.6/dist-packages/django/template/base.py", line 856, in _resolve_lookup
    (bit, current))  # missing attribute
django.template.base.VariableDoesNotExist: Failed lookup for key [required] in {'type': 'password', 'description': 'Password to access the device via NETCONF', 'minLength': 1, 'maxLength': 50}
[2021-09-05 22:16:46.615 DEBUG                    django.template : 878]
Exception while resolving variable 'required' in template 'ysdevices/device_form.html'.
Traceback (most recent call last):
  File "/usr/local/lib/python3.6/dist-packages/django/template/base.py", line 835, in _resolve_lookup
    current = current[bit]
KeyError: 'required'

During handling of the above exception, another exception occurred:

Traceback (most recent call last):
  File "/usr/local/lib/python3.6/dist-packages/django/template/base.py", line 843, in _resolve_lookup
    current = getattr(current, bit)
AttributeError: 'dict' object has no attribute 'required'

During handling of the above exception, another exception occurred:

Traceback (most recent call last):
  File "/usr/local/lib/python3.6/dist-packages/django/template/base.py", line 849, in _resolve_lookup
    current = current[int(bit)]
ValueError: invalid literal for int() with base 10: 'required'

During handling of the above exception, another exception occurred:

Traceback (most recent call last):
  File "/usr/local/lib/python3.6/dist-packages/django/template/base.py", line 856, in _resolve_lookup
    (bit, current))  # missing attribute
django.template.base.VariableDoesNotExist: Failed lookup for key [required] in {'type': 'password', 'description': 'Password to access the device via NETCONF', 'minLength': 1, 'maxLength': 50}
[2021-09-05 22:16:46.615 DEBUG                    django.template : 878]
Exception while resolving variable 'label' in template 'ysdevices/device_form.html'.
Traceback (most recent call last):
  File "/usr/local/lib/python3.6/dist-packages/django/template/base.py", line 835, in _resolve_lookup
    current = current[bit]
KeyError: 'label'

During handling of the above exception, another exception occurred:

Traceback (most recent call last):
  File "/usr/local/lib/python3.6/dist-packages/django/template/base.py", line 843, in _resolve_lookup
    current = getattr(current, bit)
AttributeError: 'dict' object has no attribute 'label'

During handling of the above exception, another exception occurred:

Traceback (most recent call last):
  File "/usr/local/lib/python3.6/dist-packages/django/template/base.py", line 849, in _resolve_lookup
    current = current[int(bit)]
ValueError: invalid literal for int() with base 10: 'label'

During handling of the above exception, another exception occurred:

Traceback (most recent call last):
  File "/usr/local/lib/python3.6/dist-packages/django/template/base.py", line 856, in _resolve_lookup
    (bit, current))  # missing attribute
django.template.base.VariableDoesNotExist: Failed lookup for key [label] in {'type': 'password', 'description': 'Password to access the device via NETCONF', 'minLength': 1, 'maxLength': 50}
[2021-09-05 22:16:46.615 DEBUG                    django.template : 878]
Exception while resolving variable 'required' in template 'ysdevices/device_form.html'.
Traceback (most recent call last):
  File "/usr/local/lib/python3.6/dist-packages/django/template/base.py", line 835, in _resolve_lookup
    current = current[bit]
KeyError: 'required'

During handling of the above exception, another exception occurred:

Traceback (most recent call last):
  File "/usr/local/lib/python3.6/dist-packages/django/template/base.py", line 843, in _resolve_lookup
    current = getattr(current, bit)
AttributeError: 'dict' object has no attribute 'required'

During handling of the above exception, another exception occurred:

Traceback (most recent call last):
  File "/usr/local/lib/python3.6/dist-packages/django/template/base.py", line 849, in _resolve_lookup
    current = current[int(bit)]
ValueError: invalid literal for int() with base 10: 'required'

During handling of the above exception, another exception occurred:

Traceback (most recent call last):
  File "/usr/local/lib/python3.6/dist-packages/django/template/base.py", line 856, in _resolve_lookup
    (bit, current))  # missing attribute
django.template.base.VariableDoesNotExist: Failed lookup for key [required] in {'type': 'password', 'description': 'Password to access the device via NETCONF', 'minLength': 1, 'maxLength': 50}
[2021-09-05 22:16:46.615 DEBUG                    django.template : 878]
Exception while resolving variable 'minLength' in template 'ysdevices/device_form.html'.
Traceback (most recent call last):
  File "/usr/local/lib/python3.6/dist-packages/django/template/base.py", line 835, in _resolve_lookup
    current = current[bit]
KeyError: 'minLength'

During handling of the above exception, another exception occurred:

Traceback (most recent call last):
  File "/usr/local/lib/python3.6/dist-packages/django/template/base.py", line 843, in _resolve_lookup
    current = getattr(current, bit)
AttributeError: 'dict' object has no attribute 'minLength'

During handling of the above exception, another exception occurred:

Traceback (most recent call last):
  File "/usr/local/lib/python3.6/dist-packages/django/template/base.py", line 849, in _resolve_lookup
    current = current[int(bit)]
ValueError: invalid literal for int() with base 10: 'minLength'

During handling of the above exception, another exception occurred:

Traceback (most recent call last):
  File "/usr/local/lib/python3.6/dist-packages/django/template/base.py", line 856, in _resolve_lookup
    (bit, current))  # missing attribute
django.template.base.VariableDoesNotExist: Failed lookup for key [minLength] in {'type': 'int', 'description': 'Timeout, in seconds, for NETCONF requests', 'min': 0, 'default': ''}
