[2021-09-05 22:11:49.398 DEBUG                    django.template : 878]
Exception while resolving variable 'default' in template 'ysdevices/device_form.html'.
Traceback (most recent call last):
  File "/usr/local/lib/python3.6/dist-packages/django/template/base.py", line 835, in _resolve_lookup
    current = current[bit]
KeyError: 'default'

During handling of the above exception, another exception occurred:

Traceback (most recent call last):
  File "/usr/local/lib/python3.6/dist-packages/django/template/base.py", line 843, in _resolve_lookup
    current = getattr(current, bit)
AttributeError: 'dict' object has no attribute 'default'

During handling of the above exception, another exception occurred:

Traceback (most recent call last):
  File "/usr/local/lib/python3.6/dist-packages/django/template/base.py", line 849, in _resolve_lookup
    current = current[int(bit)]
ValueError: invalid literal for int() with base 10: 'default'

During handling of the above exception, another exception occurred:

Traceback (most recent call last):
  File "/usr/local/lib/python3.6/dist-packages/django/template/base.py", line 856, in _resolve_lookup
    (bit, current))  # missing attribute
django.template.base.VariableDoesNotExist: Failed lookup for key [default] in {'type': 'password', 'description': 'Password to access the device via RESTCONF', 'minLength': 1, 'maxLength': 50}
[2021-09-05 22:11:49.398 DEBUG                    django.template : 878]
Exception while resolving variable 'required' in template 'ysdevices/device_form.html'.
Traceback (most recent call last):
  File "/usr/local/lib/python3.6/dist-packages/django/template/base.py", line 835, in _resolve_lookup
    current = current[bit]
KeyError: 'required'

During handling of the above exception, another exception occurred:

Traceback (most recent call last):
  File "/usr/local/lib/python3.6/dist-packages/django/template/base.py", line 843, in _resolve_lookup
    current = getattr(current, bit)
AttributeError: 'dict' object has no attribute 'required'

During handling of the above exception, another exception occurred:

Traceback (most recent call last):
  File "/usr/local/lib/python3.6/dist-packages/django/template/base.py", line 849, in _resolve_lookup
    current = current[int(bit)]
ValueError: invalid literal for int() with base 10: 'required'

During handling of the above exception, another exception occurred:

Traceback (most recent call last):
  File "/usr/local/lib/python3.6/dist-packages/django/template/base.py", line 856, in _resolve_lookup
    (bit, current))  # missing attribute
django.template.base.VariableDoesNotExist: Failed lookup for key [required] in {'type': 'password', 'description': 'Password to access the device via RESTCONF', 'minLength': 1, 'maxLength': 50}
[2021-09-05 22:11:49.398 DEBUG                    django.template : 878]
Exception while resolving variable 'required' in template 'ysdevices/device_form.html'.
Traceback (most recent call last):
  File "/usr/local/lib/python3.6/dist-packages/django/template/base.py", line 835, in _resolve_lookup
    current = current[bit]
KeyError: 'required'

During handling of the above exception, another exception occurred:

Traceback (most recent call last):
  File "/usr/local/lib/python3.6/dist-packages/django/template/base.py", line 843, in _resolve_lookup
    current = getattr(current, bit)
AttributeError: 'dict' object has no attribute 'required'

During handling of the above exception, another exception occurred:

Traceback (most recent call last):
  File "/usr/local/lib/python3.6/dist-packages/django/template/base.py", line 849, in _resolve_lookup
    current = current[int(bit)]
ValueError: invalid literal for int() with base 10: 'required'

During handling of the above exception, another exception occurred:

Traceback (most recent call last):
  File "/usr/local/lib/python3.6/dist-packages/django/template/base.py", line 856, in _resolve_lookup
    (bit, current))  # missing attribute
django.template.base.VariableDoesNotExist: Failed lookup for key [required] in {'type': 'password', 'description': 'Password to access the device via RESTCONF', 'minLength': 1, 'maxLength': 50}
[2021-09-05 22:11:49.398 DEBUG                    django.template : 878]
Exception while resolving variable 'label' in template 'ysdevices/device_form.html'.
Traceback (most recent call last):
  File "/usr/local/lib/python3.6/dist-packages/django/template/base.py", line 835, in _resolve_lookup
    current = current[bit]
KeyError: 'label'

During handling of the above exception, another exception occurred:

Traceback (most recent call last):
  File "/usr/local/lib/python3.6/dist-packages/django/template/base.py", line 843, in _resolve_lookup
    current = getattr(current, bit)
AttributeError: 'dict' object has no attribute 'label'

During handling of the above exception, another exception occurred:

Traceback (most recent call last):
  File "/usr/local/lib/python3.6/dist-packages/django/template/base.py", line 849, in _resolve_lookup
    current = current[int(bit)]
ValueError: invalid literal for int() with base 10: 'label'

During handling of the above exception, another exception occurred:

Traceback (most recent call last):
  File "/usr/local/lib/python3.6/dist-packages/django/template/base.py", line 856, in _resolve_lookup
    (bit, current))  # missing attribute
django.template.base.VariableDoesNotExist: Failed lookup for key [label] in {'type': 'password', 'description': 'Password to access the device via RESTCONF', 'minLength': 1, 'maxLength': 50}
[2021-09-05 22:11:49.399 DEBUG                    django.template : 878]
Exception while resolving variable 'required' in template 'ysdevices/device_form.html'.
Traceback (most recent call last):
  File "/usr/local/lib/python3.6/dist-packages/django/template/base.py", line 835, in _resolve_lookup
    current = current[bit]
KeyError: 'required'

During handling of the above exception, another exception occurred:

Traceback (most recent call last):
  File "/usr/local/lib/python3.6/dist-packages/django/template/base.py", line 843, in _resolve_lookup
    current = getattr(current, bit)
AttributeError: 'dict' object has no attribute 'required'

During handling of the above exception, another exception occurred:

Traceback (most recent call last):
  File "/usr/local/lib/python3.6/dist-packages/django/template/base.py", line 849, in _resolve_lookup
    current = current[int(bit)]
ValueError: invalid literal for int() with base 10: 'required'

During handling of the above exception, another exception occurred:

Traceback (most recent call last):
  File "/usr/local/lib/python3.6/dist-packages/django/template/base.py", line 856, in _resolve_lookup
    (bit, current))  # missing attribute
django.template.base.VariableDoesNotExist: Failed lookup for key [required] in {'type': 'password', 'description': 'Password to access the device via RESTCONF', 'minLength': 1, 'maxLength': 50}
[2021-09-05 22:11:49.399 DEBUG                    django.template : 878]
Exception while resolving variable 'description' in template 'ysdevices/device_form.html'.
Traceback (most recent call last):
  File "/usr/local/lib/python3.6/dist-packages/django/template/base.py", line 835, in _resolve_lookup
    current = current[bit]
KeyError: 'description'

During handling of the above exception, another exception occurred:

Traceback (most recent call last):
  File "/usr/local/lib/python3.6/dist-packages/django/template/base.py", line 843, in _resolve_lookup
    current = getattr(current, bit)
AttributeError: 'dict' object has no attribute 'description'

During handling of the above exception, another exception occurred:

Traceback (most recent call last):
  File "/usr/local/lib/python3.6/dist-packages/django/template/base.py", line 849, in _resolve_lookup
    current = current[int(bit)]
ValueError: invalid literal for int() with base 10: 'description'

During handling of the above exception, another exception occurred:

Traceback (most recent call last):
  File "/usr/local/lib/python3.6/dist-packages/django/template/base.py", line 856, in _resolve_lookup
    (bit, current))  # missing attribute
django.template.base.VariableDoesNotExist: Failed lookup for key [description] in {'label': 'Device allows SSH login', 'type': 'boolean', 'default': False}
[2021-09-05 22:11:49.402 DEBUG                    django.template : 878]
Exception while resolving variable 'min' in template 'ysdevices/device_form.html'.
Traceback (most recent call last):
  File "/usr/local/lib/python3.6/dist-packages/django/template/base.py", line 835, in _resolve_lookup
    current = current[bit]
KeyError: 'min'

During handling of the above exception, another exception occurred:

Traceback (most recent call last):
  File "/usr/local/lib/python3.6/dist-packages/django/template/base.py", line 843, in _resolve_lookup
    current = getattr(current, bit)
AttributeError: 'dict' object has no attribute 'min'

During handling of the above exception, another exception occurred:

Traceback (most recent call last):
  File "/usr/local/lib/python3.6/dist-packages/django/template/base.py", line 849, in _resolve_lookup
    current = current[int(bit)]
ValueError: invalid literal for int() with base 10: 'min'

During handling of the above exception, another exception occurred:

Traceback (most recent call last):
  File "/usr/local/lib/python3.6/dist-packages/django/template/base.py", line 856, in _resolve_lookup
    (bit, current))  # missing attribute
django.template.base.VariableDoesNotExist: Failed lookup for key [min] in {'type': 'string', 'description': 'Address or hostname to access via SSH'}
[2021-09-05 22:11:49.403 DEBUG                    django.template : 878]
Exception while resolving variable 'minLength' in template 'ysdevices/device_form.html'.
Traceback (most recent call last):
  File "/usr/local/lib/python3.6/dist-packages/django/template/base.py", line 835, in _resolve_lookup
    current = current[bit]
KeyError: 'minLength'

During handling of the above exception, another exception occurred:

Traceback (most recent call last):
  File "/usr/local/lib/python3.6/dist-packages/django/template/base.py", line 843, in _resolve_lookup
    current = getattr(current, bit)
AttributeError: 'dict' object has no attribute 'minLength'

During handling of the above exception, another exception occurred:

Traceback (most recent call last):
  File "/usr/local/lib/python3.6/dist-packages/django/template/base.py", line 849, in _resolve_lookup
    current = current[int(bit)]
ValueError: invalid literal for int() with base 10: 'minLength'

During handling of the above exception, another exception occurred:

Traceback (most recent call last):
  File "/usr/local/lib/python3.6/dist-packages/django/template/base.py", line 856, in _resolve_lookup
    (bit, current))  # missing attribute
django.template.base.VariableDoesNotExist: Failed lookup for key [minLength] in {'type': 'string', 'description': 'Address or hostname to access via SSH'}
[2021-09-05 22:11:49.403 DEBUG                    django.template : 878]
Exception while resolving variable 'max' in template 'ysdevices/device_form.html'.
Traceback (most recent call last):
  File "/usr/local/lib/python3.6/dist-packages/django/template/base.py", line 835, in _resolve_lookup
    current = current[bit]
KeyError: 'max'

During handling of the above exception, another exception occurred:

Traceback (most recent call last):
  File "/usr/local/lib/python3.6/dist-packages/django/template/base.py", line 843, in _resolve_lookup
    current = getattr(current, bit)
AttributeError: 'dict' object has no attribute 'max'

During handling of the above exception, another exception occurred:

Traceback (most recent call last):
  File "/usr/local/lib/python3.6/dist-packages/django/template/base.py", line 849, in _resolve_lookup
    current = current[int(bit)]
ValueError: invalid literal for int() with base 10: 'max'

During handling of the above exception, another exception occurred:

Traceback (most recent call last):
  File "/usr/local/lib/python3.6/dist-packages/django/template/base.py", line 856, in _resolve_lookup
    (bit, current))  # missing attribute
django.template.base.VariableDoesNotExist: Failed lookup for key [max] in {'type': 'string', 'description': 'Address or hostname to access via SSH'}
[2021-09-05 22:11:49.403 DEBUG                    django.template : 878]
Exception while resolving variable 'maxLength' in template 'ysdevices/device_form.html'.
Traceback (most recent call last):
  File "/usr/local/lib/python3.6/dist-packages/django/template/base.py", line 835, in _resolve_lookup
    current = current[bit]
KeyError: 'maxLength'

During handling of the above exception, another exception occurred:

Traceback (most recent call last):
  File "/usr/local/lib/python3.6/dist-packages/django/template/base.py", line 843, in _resolve_lookup
    current = getattr(current, bit)
AttributeError: 'dict' object has no attribute 'maxLength'

During handling of the above exception, another exception occurred:

Traceback (most recent call last):
  File "/usr/local/lib/python3.6/dist-packages/django/template/base.py", line 849, in _resolve_lookup
    current = current[int(bit)]
ValueError: invalid literal for int() with base 10: 'maxLength'

During handling of the above exception, another exception occurred:

Traceback (most recent call last):
  File "/usr/local/lib/python3.6/dist-packages/django/template/base.py", line 856, in _resolve_lookup
    (bit, current))  # missing attribute
django.template.base.VariableDoesNotExist: Failed lookup for key [maxLength] in {'type': 'string', 'description': 'Address or hostname to access via SSH'}
[2021-09-05 22:11:49.403 DEBUG                    django.template : 878]
Exception while resolving variable 'step' in template 'ysdevices/device_form.html'.
Traceback (most recent call last):
  File "/usr/local/lib/python3.6/dist-packages/django/template/base.py", line 835, in _resolve_lookup
    current = current[bit]
KeyError: 'step'

During handling of the above exception, another exception occurred:

Traceback (most recent call last):
  File "/usr/local/lib/python3.6/dist-packages/django/template/base.py", line 843, in _resolve_lookup
    current = getattr(current, bit)
AttributeError: 'dict' object has no attribute 'step'

During handling of the above exception, another exception occurred:

Traceback (most recent call last):
  File "/usr/local/lib/python3.6/dist-packages/django/template/base.py", line 849, in _resolve_lookup
    current = current[int(bit)]
ValueError: invalid literal for int() with base 10: 'step'

During handling of the above exception, another exception occurred:

Traceback (most recent call last):
  File "/usr/local/lib/python3.6/dist-packages/django/template/base.py", line 856, in _resolve_lookup
    (bit, current))  # missing attribute
django.template.base.VariableDoesNotExist: Failed lookup for key [step] in {'type': 'string', 'description': 'Address or hostname to access via SSH'}
[2021-09-05 22:11:49.404 DEBUG                    django.template : 878]
Exception while resolving variable 'default' in template 'ysdevices/device_form.html'.
Traceback (most recent call last):
  File "/usr/local/lib/python3.6/dist-packages/django/template/base.py", line 835, in _resolve_lookup
    current = current[bit]
KeyError: 'default'

During handling of the above exception, another exception occurred:

Traceback (most recent call last):
  File "/usr/local/lib/python3.6/dist-packages/django/template/base.py", line 843, in _resolve_lookup
    current = getattr(current, bit)
AttributeError: 'dict' object has no attribute 'default'

During handling of the above exception, another exception occurred:

Traceback (most recent call last):
  File "/usr/local/lib/python3.6/dist-packages/django/template/base.py", line 849, in _resolve_lookup
    current = current[int(bit)]
ValueError: invalid literal for int() with base 10: 'default'

During handling of the above exception, another exception occurred:

Traceback (most recent call last):
  File "/usr/local/lib/python3.6/dist-packages/django/template/base.py", line 856, in _resolve_lookup
    (bit, current))  # missing attribute
django.template.base.VariableDoesNotExist: Failed lookup for key [default] in {'type': 'string', 'description': 'Address or hostname to access via SSH'}
[2021-09-05 22:11:49.404 DEBUG                    django.template : 878]
Exception while resolving variable 'default' in template 'ysdevices/device_form.html'.
Traceback (most recent call last):
  File "/usr/local/lib/python3.6/dist-packages/django/template/base.py", line 835, in _resolve_lookup
    current = current[bit]
KeyError: 'default'

During handling of the above exception, another exception occurred:

Traceback (most recent call last):
  File "/usr/local/lib/python3.6/dist-packages/django/template/base.py", line 843, in _resolve_lookup
    current = getattr(current, bit)
AttributeError: 'dict' object has no attribute 'default'

During handling of the above exception, another exception occurred:

Traceback (most recent call last):
  File "/usr/local/lib/python3.6/dist-packages/django/template/base.py", line 849, in _resolve_lookup
    current = current[int(bit)]
ValueError: invalid literal for int() with base 10: 'default'

During handling of the above exception, another exception occurred:

Traceback (most recent call last):
  File "/usr/local/lib/python3.6/dist-packages/django/template/base.py", line 856, in _resolve_lookup
    (bit, current))  # missing attribute
django.template.base.VariableDoesNotExist: Failed lookup for key [default] in {'type': 'string', 'description': 'Address or hostname to access via SSH'}
[2021-09-05 22:11:49.404 DEBUG                    django.template : 878]
Exception while resolving variable 'required' in template 'ysdevices/device_form.html'.
Traceback (most recent call last):
  File "/usr/local/lib/python3.6/dist-packages/django/template/base.py", line 835, in _resolve_lookup
    current = current[bit]
KeyError: 'required'

During handling of the above exception, another exception occurred:

Traceback (most recent call last):
  File "/usr/local/lib/python3.6/dist-packages/django/template/base.py", line 843, in _resolve_lookup
    current = getattr(current, bit)
AttributeError: 'dict' object has no attribute 'required'

During handling of the above exception, another exception occurred:

Traceback (most recent call last):
  File "/usr/local/lib/python3.6/dist-packages/django/template/base.py", line 849, in _resolve_lookup
    current = current[int(bit)]
ValueError: invalid literal for int() with base 10: 'required'

During handling of the above exception, another exception occurred:

Traceback (most recent call last):
  File "/usr/local/lib/python3.6/dist-packages/django/template/base.py", line 856, in _resolve_lookup
    (bit, current))  # missing attribute
django.template.base.VariableDoesNotExist: Failed lookup for key [required] in {'type': 'string', 'description': 'Address or hostname to access via SSH'}
[2021-09-05 22:11:49.404 DEBUG                    django.template : 878]
Exception while resolving variable 'required' in template 'ysdevices/device_form.html'.
Traceback (most recent call last):
  File "/usr/local/lib/python3.6/dist-packages/django/template/base.py", line 835, in _resolve_lookup
    current = current[bit]
KeyError: 'required'

During handling of the above exception, another exception occurred:

Traceback (most recent call last):
  File "/usr/local/lib/python3.6/dist-packages/django/template/base.py", line 843, in _resolve_lookup
    current = getattr(current, bit)
AttributeError: 'dict' object has no attribute 'required'

During handling of the above exception, another exception occurred:

Traceback (most recent call last):
  File "/usr/local/lib/python3.6/dist-packages/django/template/base.py", line 849, in _resolve_lookup
    current = current[int(bit)]
ValueError: invalid literal for int() with base 10: 'required'

During handling of the above exception, another exception occurred:

Traceback (most recent call last):
  File "/usr/local/lib/python3.6/dist-packages/django/template/base.py", line 856, in _resolve_lookup
    (bit, current))  # missing attribute
django.template.base.VariableDoesNotExist: Failed lookup for key [required] in {'type': 'string', 'description': 'Address or hostname to access via SSH'}
[2021-09-05 22:11:49.404 DEBUG                    django.template : 878]
Exception while resolving variable 'label' in template 'ysdevices/device_form.html'.
Traceback (most recent call last):
  File "/usr/local/lib/python3.6/dist-packages/django/template/base.py", line 835, in _resolve_lookup
    current = current[bit]
KeyError: 'label'

During handling of the above exception, another exception occurred:

Traceback (most recent call last):
  File "/usr/local/lib/python3.6/dist-packages/django/template/base.py", line 843, in _resolve_lookup
    current = getattr(current, bit)
AttributeError: 'dict' object has no attribute 'label'

During handling of the above exception, another exception occurred:

Traceback (most recent call last):
  File "/usr/local/lib/python3.6/dist-packages/django/template/base.py", line 849, in _resolve_lookup
    current = current[int(bit)]
ValueError: invalid literal for int() with base 10: 'label'

During handling of the above exception, another exception occurred:

Traceback (most recent call last):
  File "/usr/local/lib/python3.6/dist-packages/django/template/base.py", line 856, in _resolve_lookup
    (bit, current))  # missing attribute
django.template.base.VariableDoesNotExist: Failed lookup for key [label] in {'type': 'string', 'description': 'Address or hostname to access via SSH'}
[2021-09-05 22:11:49.405 DEBUG                    django.template : 878]
Exception while resolving variable 'required' in template 'ysdevices/device_form.html'.
Traceback (most recent call last):
  File "/usr/local/lib/python3.6/dist-packages/django/template/base.py", line 835, in _resolve_lookup
    current = current[bit]
KeyError: 'required'

During handling of the above exception, another exception occurred:

Traceback (most recent call last):
  File "/usr/local/lib/python3.6/dist-packages/django/template/base.py", line 843, in _resolve_lookup
    current = getattr(current, bit)
AttributeError: 'dict' object has no attribute 'required'

During handling of the above exception, another exception occurred:

Traceback (most recent call last):
  File "/usr/local/lib/python3.6/dist-packages/django/template/base.py", line 849, in _resolve_lookup
    current = current[int(bit)]
ValueError: invalid literal for int() with base 10: 'required'

During handling of the above exception, another exception occurred:

Traceback (most recent call last):
  File "/usr/local/lib/python3.6/dist-packages/django/template/base.py", line 856, in _resolve_lookup
    (bit, current))  # missing attribute
django.template.base.VariableDoesNotExist: Failed lookup for key [required] in {'type': 'string', 'description': 'Address or hostname to access via SSH'}
[2021-09-05 22:11:49.405 DEBUG                    django.template : 878]
Exception while resolving variable 'minLength' in template 'ysdevices/device_form.html'.
Traceback (most recent call last):
  File "/usr/local/lib/python3.6/dist-packages/django/template/base.py", line 835, in _resolve_lookup
    current = current[bit]
KeyError: 'minLength'

During handling of the above exception, another exception occurred:

Traceback (most recent call last):
  File "/usr/local/lib/python3.6/dist-packages/django/template/base.py", line 843, in _resolve_lookup
    current = getattr(current, bit)
AttributeError: 'dict' object has no attribute 'minLength'

During handling of the above exception, another exception occurred:

Traceback (most recent call last):
  File "/usr/local/lib/python3.6/dist-packages/django/template/base.py", line 849, in _resolve_lookup
    current = current[int(bit)]
ValueError: invalid literal for int() with base 10: 'minLength'

During handling of the above exception, another exception occurred:

Traceback (most recent call last):
  File "/usr/local/lib/python3.6/dist-packages/django/template/base.py", line 856, in _resolve_lookup
    (bit, current))  # missing attribute
django.template.base.VariableDoesNotExist: Failed lookup for key [minLength] in {'label': 'SSH Port', 'type': 'int', 'description': 'Port number for SSH connection to device console', 'min': 1, 'max': 65535, 'default': 22, 'required': True}
[2021-09-05 22:11:49.405 DEBUG                    django.template : 878]
Exception while resolving variable 'maxLength' in template 'ysdevices/device_form.html'.
Traceback (most recent call last):
  File "/usr/local/lib/python3.6/dist-packages/django/template/base.py", line 835, in _resolve_lookup
    current = current[bit]
KeyError: 'maxLength'

During handling of the above exception, another exception occurred:

Traceback (most recent call last):
  File "/usr/local/lib/python3.6/dist-packages/django/template/base.py", line 843, in _resolve_lookup
    current = getattr(current, bit)
AttributeError: 'dict' object has no attribute 'maxLength'

During handling of the above exception, another exception occurred:

Traceback (most recent call last):
  File "/usr/local/lib/python3.6/dist-packages/django/template/base.py", line 849, in _resolve_lookup
    current = current[int(bit)]
ValueError: invalid literal for int() with base 10: 'maxLength'

During handling of the above exception, another exception occurred:

Traceback (most recent call last):
  File "/usr/local/lib/python3.6/dist-packages/django/template/base.py", line 856, in _resolve_lookup
    (bit, current))  # missing attribute
django.template.base.VariableDoesNotExist: Failed lookup for key [maxLength] in {'label': 'SSH Port', 'type': 'int', 'description': 'Port number for SSH connection to device console', 'min': 1, 'max': 65535, 'default': 22, 'required': True}
[2021-09-05 22:11:49.406 DEBUG                    django.template : 878]
Exception while resolving variable 'step' in template 'ysdevices/device_form.html'.
Traceback (most recent call last):
  File "/usr/local/lib/python3.6/dist-packages/django/template/base.py", line 835, in _resolve_lookup
    current = current[bit]
KeyError: 'step'

During handling of the above exception, another exception occurred:

Traceback (most recent call last):
  File "/usr/local/lib/python3.6/dist-packages/django/template/base.py", line 843, in _resolve_lookup
    current = getattr(current, bit)
AttributeError: 'dict' object has no attribute 'step'

During handling of the above exception, another exception occurred:

Traceback (most recent call last):
  File "/usr/local/lib/python3.6/dist-packages/django/template/base.py", line 849, in _resolve_lookup
    current = current[int(bit)]
ValueError: invalid literal for int() with base 10: 'step'

During handling of the above exception, another exception occurred:

Traceback (most recent call last):
  File "/usr/local/lib/python3.6/dist-packages/django/template/base.py", line 856, in _resolve_lookup
    (bit, current))  # missing attribute
django.template.base.VariableDoesNotExist: Failed lookup for key [step] in {'label': 'SSH Port', 'type': 'int', 'description': 'Port number for SSH connection to device console', 'min': 1, 'max': 65535, 'default': 22, 'required': True}
[2021-09-05 22:11:49.406 DEBUG                    django.template : 878]
Exception while resolving variable 'minLength' in template 'ysdevices/device_form.html'.
Traceback (most recent call last):
  File "/usr/local/lib/python3.6/dist-packages/django/template/base.py", line 835, in _resolve_lookup
    current = current[bit]
KeyError: 'minLength'

During handling of the above exception, another exception occurred:

Traceback (most recent call last):
  File "/usr/local/lib/python3.6/dist-packages/django/template/base.py", line 843, in _resolve_lookup
    current = getattr(current, bit)
AttributeError: 'dict' object has no attribute 'minLength'

During handling of the above exception, another exception occurred:

Traceback (most recent call last):
  File "/usr/local/lib/python3.6/dist-packages/django/template/base.py", line 849, in _resolve_lookup
    current = current[int(bit)]
ValueError: invalid literal for int() with base 10: 'minLength'

During handling of the above exception, another exception occurred:

Traceback (most recent call last):
  File "/usr/local/lib/python3.6/dist-packages/django/template/base.py", line 856, in _resolve_lookup
    (bit, current))  # missing attribute
django.template.base.VariableDoesNotExist: Failed lookup for key [minLength] in {'label': 'Delay Factor', 'type': 'float', 'description': 'Multiplier for acceptable delays from the device. Set to lower value for faster performance. Set to higher value if timeout errors are seen.', 'min': 0, 'default': 1.0, 'step': 0.1}
[2021-09-05 22:11:49.406 DEBUG                    django.template : 878]
Exception while resolving variable 'max' in template 'ysdevices/device_form.html'.
Traceback (most recent call last):
  File "/usr/local/lib/python3.6/dist-packages/django/template/base.py", line 835, in _resolve_lookup
    current = current[bit]
KeyError: 'max'

During handling of the above exception, another exception occurred:

Traceback (most recent call last):
  File "/usr/local/lib/python3.6/dist-packages/django/template/base.py", line 843, in _resolve_lookup
    current = getattr(current, bit)
AttributeError: 'dict' object has no attribute 'max'

During handling of the above exception, another exception occurred:

Traceback (most recent call last):
  File "/usr/local/lib/python3.6/dist-packages/django/template/base.py", line 849, in _resolve_lookup
    current = current[int(bit)]
ValueError: invalid literal for int() with base 10: 'max'

During handling of the above exception, another exception occurred:

Traceback (most recent call last):
  File "/usr/local/lib/python3.6/dist-packages/django/template/base.py", line 856, in _resolve_lookup
    (bit, current))  # missing attribute
django.template.base.VariableDoesNotExist: Failed lookup for key [max] in {'label': 'Delay Factor', 'type': 'float', 'description': 'Multiplier for acceptable delays from the device. Set to lower value for faster performance. Set to higher value if timeout errors are seen.', 'min': 0, 'default': 1.0, 'step': 0.1}
[2021-09-05 22:11:49.407 DEBUG                    django.template : 878]
Exception while resolving variable 'maxLength' in template 'ysdevices/device_form.html'.
Traceback (most recent call last):
  File "/usr/local/lib/python3.6/dist-packages/django/template/base.py", line 835, in _resolve_lookup
    current = current[bit]
KeyError: 'maxLength'

During handling of the above exception, another exception occurred:

Traceback (most recent call last):
  File "/usr/local/lib/python3.6/dist-packages/django/template/base.py", line 843, in _resolve_lookup
    current = getattr(current, bit)
AttributeError: 'dict' object has no attribute 'maxLength'

During handling of the above exception, another exception occurred:

Traceback (most recent call last):
  File "/usr/local/lib/python3.6/dist-packages/django/template/base.py", line 849, in _resolve_lookup
    current = current[int(bit)]
ValueError: invalid literal for int() with base 10: 'maxLength'

During handling of the above exception, another exception occurred:

Traceback (most recent call last):
  File "/usr/local/lib/python3.6/dist-packages/django/template/base.py", line 856, in _resolve_lookup
    (bit, current))  # missing attribute
django.template.base.VariableDoesNotExist: Failed lookup for key [maxLength] in {'label': 'Delay Factor', 'type': 'float', 'description': 'Multiplier for acceptable delays from the device. Set to lower value for faster performance. Set to higher value if timeout errors are seen.', 'min': 0, 'default': 1.0, 'step': 0.1}
[2021-09-05 22:11:49.407 DEBUG                    django.template : 878]
Exception while resolving variable 'required' in template 'ysdevices/device_form.html'.
Traceback (most recent call last):
  File "/usr/local/lib/python3.6/dist-packages/django/template/base.py", line 835, in _resolve_lookup
    current = current[bit]
KeyError: 'required'

During handling of the above exception, another exception occurred:

Traceback (most recent call last):
  File "/usr/local/lib/python3.6/dist-packages/django/template/base.py", line 843, in _resolve_lookup
    current = getattr(current, bit)
AttributeError: 'dict' object has no attribute 'required'

During handling of the above exception, another exception occurred:

Traceback (most recent call last):
  File "/usr/local/lib/python3.6/dist-packages/django/template/base.py", line 849, in _resolve_lookup
    current = current[int(bit)]
ValueError: invalid literal for int() with base 10: 'required'

During handling of the above exception, another exception occurred:

Traceback (most recent call last):
  File "/usr/local/lib/python3.6/dist-packages/django/template/base.py", line 856, in _resolve_lookup
    (bit, current))  # missing attribute
django.template.base.VariableDoesNotExist: Failed lookup for key [required] in {'label': 'Delay Factor', 'type': 'float', 'description': 'Multiplier for acceptable delays from the device. Set to lower value for faster performance. Set to higher value if timeout errors are seen.', 'min': 0, 'default': 1.0, 'step': 0.1}
[2021-09-05 22:11:49.407 DEBUG                    django.template : 878]
Exception while resolving variable 'required' in template 'ysdevices/device_form.html'.
Traceback (most recent call last):
  File "/usr/local/lib/python3.6/dist-packages/django/template/base.py", line 835, in _resolve_lookup
    current = current[bit]
KeyError: 'required'

During handling of the above exception, another exception occurred:

Traceback (most recent call last):
  File "/usr/local/lib/python3.6/dist-packages/django/template/base.py", line 843, in _resolve_lookup
    current = getattr(current, bit)
AttributeError: 'dict' object has no attribute 'required'

During handling of the above exception, another exception occurred:

Traceback (most recent call last):
  File "/usr/local/lib/python3.6/dist-packages/django/template/base.py", line 849, in _resolve_lookup
    current = current[int(bit)]
ValueError: invalid literal for int() with base 10: 'required'

During handling of the above exception, another exception occurred:

Traceback (most recent call last):
  File "/usr/local/lib/python3.6/dist-packages/django/template/base.py", line 856, in _resolve_lookup
    (bit, current))  # missing attribute
django.template.base.VariableDoesNotExist: Failed lookup for key [required] in {'label': 'Delay Factor', 'type': 'float', 'description': 'Multiplier for acceptable delays from the device. Set to lower value for faster performance. Set to higher value if timeout errors are seen.', 'min': 0, 'default': 1.0, 'step': 0.1}
[2021-09-05 22:11:49.408 DEBUG                    django.template : 878]
Exception while resolving variable 'min' in template 'ysdevices/device_form.html'.
Traceback (most recent call last):
  File "/usr/local/lib/python3.6/dist-packages/django/template/base.py", line 835, in _resolve_lookup
    current = current[bit]
KeyError: 'min'

During handling of the above exception, another exception occurred:

Traceback (most recent call last):
  File "/usr/local/lib/python3.6/dist-packages/django/template/base.py", line 843, in _resolve_lookup
    current = getattr(current, bit)
AttributeError: 'dict' object has no attribute 'min'

During handling of the above exception, another exception occurred:

Traceback (most recent call last):
  File "/usr/local/lib/python3.6/dist-packages/django/template/base.py", line 849, in _resolve_lookup
    current = current[int(bit)]
ValueError: invalid literal for int() with base 10: 'min'

During handling of the above exception, another exception occurred:

Traceback (most recent call last):
  File "/usr/local/lib/python3.6/dist-packages/django/template/base.py", line 856, in _resolve_lookup
    (bit, current))  # missing attribute
django.template.base.VariableDoesNotExist: Failed lookup for key [min] in {'type': 'string', 'description': 'Username to access the device via SSH', 'minLength': 1}
[2021-09-05 22:11:49.408 DEBUG                    django.template : 878]
Exception while resolving variable 'max' in template 'ysdevices/device_form.html'.
Traceback (most recent call last):
  File "/usr/local/lib/python3.6/dist-packages/django/template/base.py", line 835, in _resolve_lookup
    current = current[bit]
KeyError: 'max'

During handling of the above exception, another exception occurred:

Traceback (most recent call last):
  File "/usr/local/lib/python3.6/dist-packages/django/template/base.py", line 843, in _resolve_lookup
    current = getattr(current, bit)
AttributeError: 'dict' object has no attribute 'max'

During handling of the above exception, another exception occurred:

Traceback (most recent call last):
  File "/usr/local/lib/python3.6/dist-packages/django/template/base.py", line 849, in _resolve_lookup
    current = current[int(bit)]
ValueError: invalid literal for int() with base 10: 'max'

During handling of the above exception, another exception occurred:

Traceback (most recent call last):
  File "/usr/local/lib/python3.6/dist-packages/django/template/base.py", line 856, in _resolve_lookup
    (bit, current))  # missing attribute
django.template.base.VariableDoesNotExist: Failed lookup for key [max] in {'type': 'string', 'description': 'Username to access the device via SSH', 'minLength': 1}
[2021-09-05 22:11:49.408 DEBUG                    django.template : 878]
Exception while resolving variable 'maxLength' in template 'ysdevices/device_form.html'.
Traceback (most recent call last):
  File "/usr/local/lib/python3.6/dist-packages/django/template/base.py", line 835, in _resolve_lookup
    current = current[bit]
KeyError: 'maxLength'

During handling of the above exception, another exception occurred:

Traceback (most recent call last):
  File "/usr/local/lib/python3.6/dist-packages/django/template/base.py", line 843, in _resolve_lookup
    current = getattr(current, bit)
AttributeError: 'dict' object has no attribute 'maxLength'

During handling of the above exception, another exception occurred:

Traceback (most recent call last):
  File "/usr/local/lib/python3.6/dist-packages/django/template/base.py", line 849, in _resolve_lookup
    current = current[int(bit)]
ValueError: invalid literal for int() with base 10: 'maxLength'

During handling of the above exception, another exception occurred:

Traceback (most recent call last):
  File "/usr/local/lib/python3.6/dist-packages/django/template/base.py", line 856, in _resolve_lookup
    (bit, current))  # missing attribute
django.template.base.VariableDoesNotExist: Failed lookup for key [maxLength] in {'type': 'string', 'description': 'Username to access the device via SSH', 'minLength': 1}
[2021-09-05 22:11:49.408 DEBUG                    django.template : 878]
Exception while resolving variable 'step' in template 'ysdevices/device_form.html'.
Traceback (most recent call last):
  File "/usr/local/lib/python3.6/dist-packages/django/template/base.py", line 835, in _resolve_lookup
    current = current[bit]
KeyError: 'step'

During handling of the above exception, another exception occurred:

Traceback (most recent call last):
  File "/usr/local/lib/python3.6/dist-packages/django/template/base.py", line 843, in _resolve_lookup
    current = getattr(current, bit)
AttributeError: 'dict' object has no attribute 'step'

During handling of the above exception, another exception occurred:

Traceback (most recent call last):
  File "/usr/local/lib/python3.6/dist-packages/django/template/base.py", line 849, in _resolve_lookup
    current = current[int(bit)]
ValueError: invalid literal for int() with base 10: 'step'

During handling of the above exception, another exception occurred:

Traceback (most recent call last):
  File "/usr/local/lib/python3.6/dist-packages/django/template/base.py", line 856, in _resolve_lookup
    (bit, current))  # missing attribute
django.template.base.VariableDoesNotExist: Failed lookup for key [step] in {'type': 'string', 'description': 'Username to access the device via SSH', 'minLength': 1}
[2021-09-05 22:11:49.408 DEBUG                    django.template : 878]
Exception while resolving variable 'default' in template 'ysdevices/device_form.html'.
Traceback (most recent call last):
  File "/usr/local/lib/python3.6/dist-packages/django/template/base.py", line 835, in _resolve_lookup
    current = current[bit]
KeyError: 'default'

During handling of the above exception, another exception occurred:

Traceback (most recent call last):
  File "/usr/local/lib/python3.6/dist-packages/django/template/base.py", line 843, in _resolve_lookup
    current = getattr(current, bit)
AttributeError: 'dict' object has no attribute 'default'

During handling of the above exception, another exception occurred:

Traceback (most recent call last):
  File "/usr/local/lib/python3.6/dist-packages/django/template/base.py", line 849, in _resolve_lookup
    current = current[int(bit)]
ValueError: invalid literal for int() with base 10: 'default'

During handling of the above exception, another exception occurred:

Traceback (most recent call last):
  File "/usr/local/lib/python3.6/dist-packages/django/template/base.py", line 856, in _resolve_lookup
    (bit, current))  # missing attribute
django.template.base.VariableDoesNotExist: Failed lookup for key [default] in {'type': 'string', 'description': 'Username to access the device via SSH', 'minLength': 1}
[2021-09-05 22:11:49.409 DEBUG                    django.template : 878]
Exception while resolving variable 'default' in template 'ysdevices/device_form.html'.
Traceback (most recent call last):
  File "/usr/local/lib/python3.6/dist-packages/django/template/base.py", line 835, in _resolve_lookup
    current = current[bit]
KeyError: 'default'

During handling of the above exception, another exception occurred:

Traceback (most recent call last):
  File "/usr/local/lib/python3.6/dist-packages/django/template/base.py", line 843, in _resolve_lookup
    current = getattr(current, bit)
AttributeError: 'dict' object has no attribute 'default'

During handling of the above exception, another exception occurred:

Traceback (most recent call last):
  File "/usr/local/lib/python3.6/dist-packages/django/template/base.py", line 849, in _resolve_lookup
    current = current[int(bit)]
ValueError: invalid literal for int() with base 10: 'default'

During handling of the above exception, another exception occurred:

Traceback (most recent call last):
  File "/usr/local/lib/python3.6/dist-packages/django/template/base.py", line 856, in _resolve_lookup
    (bit, current))  # missing attribute
django.template.base.VariableDoesNotExist: Failed lookup for key [default] in {'type': 'string', 'description': 'Username to access the device via SSH', 'minLength': 1}
[2021-09-05 22:11:49.409 DEBUG                    django.template : 878]
Exception while resolving variable 'required' in template 'ysdevices/device_form.html'.
Traceback (most recent call last):
  File "/usr/local/lib/python3.6/dist-packages/django/template/base.py", line 835, in _resolve_lookup
    current = current[bit]
KeyError: 'required'

During handling of the above exception, another exception occurred:

Traceback (most recent call last):
  File "/usr/local/lib/python3.6/dist-packages/django/template/base.py", line 843, in _resolve_lookup
    current = getattr(current, bit)
AttributeError: 'dict' object has no attribute 'required'

During handling of the above exception, another exception occurred:

Traceback (most recent call last):
  File "/usr/local/lib/python3.6/dist-packages/django/template/base.py", line 849, in _resolve_lookup
    current = current[int(bit)]
ValueError: invalid literal for int() with base 10: 'required'

During handling of the above exception, another exception occurred:

Traceback (most recent call last):
  File "/usr/local/lib/python3.6/dist-packages/django/template/base.py", line 856, in _resolve_lookup
    (bit, current))  # missing attribute
django.template.base.VariableDoesNotExist: Failed lookup for key [required] in {'type': 'string', 'description': 'Username to access the device via SSH', 'minLength': 1}
[2021-09-05 22:11:49.409 DEBUG                    django.template : 878]
Exception while resolving variable 'required' in template 'ysdevices/device_form.html'.
Traceback (most recent call last):
  File "/usr/local/lib/python3.6/dist-packages/django/template/base.py", line 835, in _resolve_lookup
    current = current[bit]
KeyError: 'required'

During handling of the above exception, another exception occurred:

Traceback (most recent call last):
  File "/usr/local/lib/python3.6/dist-packages/django/template/base.py", line 843, in _resolve_lookup
    current = getattr(current, bit)
AttributeError: 'dict' object has no attribute 'required'

During handling of the above exception, another exception occurred:

Traceback (most recent call last):
  File "/usr/local/lib/python3.6/dist-packages/django/template/base.py", line 849, in _resolve_lookup
    current = current[int(bit)]
ValueError: invalid literal for int() with base 10: 'required'

During handling of the above exception, another exception occurred:

Traceback (most recent call last):
  File "/usr/local/lib/python3.6/dist-packages/django/template/base.py", line 856, in _resolve_lookup
    (bit, current))  # missing attribute
django.template.base.VariableDoesNotExist: Failed lookup for key [required] in {'type': 'string', 'description': 'Username to access the device via SSH', 'minLength': 1}
[2021-09-05 22:11:49.409 DEBUG                    django.template : 878]
Exception while resolving variable 'label' in template 'ysdevices/device_form.html'.
Traceback (most recent call last):
  File "/usr/local/lib/python3.6/dist-packages/django/template/base.py", line 835, in _resolve_lookup
    current = current[bit]
KeyError: 'label'

During handling of the above exception, another exception occurred:

Traceback (most recent call last):
  File "/usr/local/lib/python3.6/dist-packages/django/template/base.py", line 843, in _resolve_lookup
    current = getattr(current, bit)
AttributeError: 'dict' object has no attribute 'label'

During handling of the above exception, another exception occurred:

Traceback (most recent call last):
  File "/usr/local/lib/python3.6/dist-packages/django/template/base.py", line 849, in _resolve_lookup
    current = current[int(bit)]
ValueError: invalid literal for int() with base 10: 'label'

During handling of the above exception, another exception occurred:

Traceback (most recent call last):
  File "/usr/local/lib/python3.6/dist-packages/django/template/base.py", line 856, in _resolve_lookup
    (bit, current))  # missing attribute
django.template.base.VariableDoesNotExist: Failed lookup for key [label] in {'type': 'string', 'description': 'Username to access the device via SSH', 'minLength': 1}
[2021-09-05 22:11:49.410 DEBUG                    django.template : 878]
Exception while resolving variable 'required' in template 'ysdevices/device_form.html'.
Traceback (most recent call last):
  File "/usr/local/lib/python3.6/dist-packages/django/template/base.py", line 835, in _resolve_lookup
    current = current[bit]
KeyError: 'required'

During handling of the above exception, another exception occurred:

Traceback (most recent call last):
  File "/usr/local/lib/python3.6/dist-packages/django/template/base.py", line 843, in _resolve_lookup
    current = getattr(current, bit)
AttributeError: 'dict' object has no attribute 'required'

During handling of the above exception, another exception occurred:

Traceback (most recent call last):
  File "/usr/local/lib/python3.6/dist-packages/django/template/base.py", line 849, in _resolve_lookup
    current = current[int(bit)]
ValueError: invalid literal for int() with base 10: 'required'

During handling of the above exception, another exception occurred:

Traceback (most recent call last):
  File "/usr/local/lib/python3.6/dist-packages/django/template/base.py", line 856, in _resolve_lookup
    (bit, current))  # missing attribute
django.template.base.VariableDoesNotExist: Failed lookup for key [required] in {'type': 'string', 'description': 'Username to access the device via SSH', 'minLength': 1}
[2021-09-05 22:11:49.410 DEBUG                    django.template : 878]
Exception while resolving variable 'min' in template 'ysdevices/device_form.html'.
Traceback (most recent call last):
  File "/usr/local/lib/python3.6/dist-packages/django/template/base.py", line 835, in _resolve_lookup
    current = current[bit]
KeyError: 'min'

During handling of the above exception, another exception occurred:

Traceback (most recent call last):
  File "/usr/local/lib/python3.6/dist-packages/django/template/base.py", line 843, in _resolve_lookup
    current = getattr(current, bit)
AttributeError: 'dict' object has no attribute 'min'

During handling of the above exception, another exception occurred:

Traceback (most recent call last):
  File "/usr/local/lib/python3.6/dist-packages/django/template/base.py", line 849, in _resolve_lookup
    current = current[int(bit)]
ValueError: invalid literal for int() with base 10: 'min'

During handling of the above exception, another exception occurred:

Traceback (most recent call last):
  File "/usr/local/lib/python3.6/dist-packages/django/template/base.py", line 856, in _resolve_lookup
    (bit, current))  # missing attribute
django.template.base.VariableDoesNotExist: Failed lookup for key [min] in {'type': 'password', 'description': 'Password to access the device via SSH', 'minLength': 1}
[2021-09-05 22:11:49.410 DEBUG                    django.template : 878]
Exception while resolving variable 'max' in template 'ysdevices/device_form.html'.
Traceback (most recent call last):
  File "/usr/local/lib/python3.6/dist-packages/django/template/base.py", line 835, in _resolve_lookup
    current = current[bit]
KeyError: 'max'

During handling of the above exception, another exception occurred:

Traceback (most recent call last):
  File "/usr/local/lib/python3.6/dist-packages/django/template/base.py", line 843, in _resolve_lookup
    current = getattr(current, bit)
AttributeError: 'dict' object has no attribute 'max'

During handling of the above exception, another exception occurred:

Traceback (most recent call last):
  File "/usr/local/lib/python3.6/dist-packages/django/template/base.py", line 849, in _resolve_lookup
    current = current[int(bit)]
ValueError: invalid literal for int() with base 10: 'max'

During handling of the above exception, another exception occurred:

Traceback (most recent call last):
  File "/usr/local/lib/python3.6/dist-packages/django/template/base.py", line 856, in _resolve_lookup
    (bit, current))  # missing attribute
django.template.base.VariableDoesNotExist: Failed lookup for key [max] in {'type': 'password', 'description': 'Password to access the device via SSH', 'minLength': 1}
[2021-09-05 22:11:49.410 DEBUG                    django.template : 878]
Exception while resolving variable 'maxLength' in template 'ysdevices/device_form.html'.
Traceback (most recent call last):
  File "/usr/local/lib/python3.6/dist-packages/django/template/base.py", line 835, in _resolve_lookup
    current = current[bit]
KeyError: 'maxLength'

During handling of the above exception, another exception occurred:

Traceback (most recent call last):
  File "/usr/local/lib/python3.6/dist-packages/django/template/base.py", line 843, in _resolve_lookup
    current = getattr(current, bit)
AttributeError: 'dict' object has no attribute 'maxLength'

During handling of the above exception, another exception occurred:

Traceback (most recent call last):
  File "/usr/local/lib/python3.6/dist-packages/django/template/base.py", line 849, in _resolve_lookup
    current = current[int(bit)]
ValueError: invalid literal for int() with base 10: 'maxLength'

During handling of the above exception, another exception occurred:

Traceback (most recent call last):
  File "/usr/local/lib/python3.6/dist-packages/django/template/base.py", line 856, in _resolve_lookup
    (bit, current))  # missing attribute
django.template.base.VariableDoesNotExist: Failed lookup for key [maxLength] in {'type': 'password', 'description': 'Password to access the device via SSH', 'minLength': 1}
[2021-09-05 22:11:49.411 DEBUG                    django.template : 878]
Exception while resolving variable 'step' in template 'ysdevices/device_form.html'.
Traceback (most recent call last):
  File "/usr/local/lib/python3.6/dist-packages/django/template/base.py", line 835, in _resolve_lookup
    current = current[bit]
KeyError: 'step'

During handling of the above exception, another exception occurred:

Traceback (most recent call last):
  File "/usr/local/lib/python3.6/dist-packages/django/template/base.py", line 843, in _resolve_lookup
    current = getattr(current, bit)
AttributeError: 'dict' object has no attribute 'step'

During handling of the above exception, another exception occurred:

Traceback (most recent call last):
  File "/usr/local/lib/python3.6/dist-packages/django/template/base.py", line 849, in _resolve_lookup
    current = current[int(bit)]
ValueError: invalid literal for int() with base 10: 'step'

During handling of the above exception, another exception occurred:

Traceback (most recent call last):
  File "/usr/local/lib/python3.6/dist-packages/django/template/base.py", line 856, in _resolve_lookup
    (bit, current))  # missing attribute
django.template.base.VariableDoesNotExist: Failed lookup for key [step] in {'type': 'password', 'description': 'Password to access the device via SSH', 'minLength': 1}
[2021-09-05 22:11:49.411 DEBUG                    django.template : 878]
Exception while resolving variable 'default' in template 'ysdevices/device_form.html'.
Traceback (most recent call last):
  File "/usr/local/lib/python3.6/dist-packages/django/template/base.py", line 835, in _resolve_lookup
    current = current[bit]
KeyError: 'default'

During handling of the above exception, another exception occurred:

Traceback (most recent call last):
  File "/usr/local/lib/python3.6/dist-packages/django/template/base.py", line 843, in _resolve_lookup
    current = getattr(current, bit)
AttributeError: 'dict' object has no attribute 'default'

During handling of the above exception, another exception occurred:

Traceback (most recent call last):
  File "/usr/local/lib/python3.6/dist-packages/django/template/base.py", line 849, in _resolve_lookup
    current = current[int(bit)]
ValueError: invalid literal for int() with base 10: 'default'

During handling of the above exception, another exception occurred:

Traceback (most recent call last):
  File "/usr/local/lib/python3.6/dist-packages/django/template/base.py", line 856, in _resolve_lookup
    (bit, current))  # missing attribute
django.template.base.VariableDoesNotExist: Failed lookup for key [default] in {'type': 'password', 'description': 'Password to access the device via SSH', 'minLength': 1}
[2021-09-05 22:11:49.411 DEBUG                    django.template : 878]
Exception while resolving variable 'default' in template 'ysdevices/device_form.html'.
Traceback (most recent call last):
  File "/usr/local/lib/python3.6/dist-packages/django/template/base.py", line 835, in _resolve_lookup
    current = current[bit]
KeyError: 'default'

During handling of the above exception, another exception occurred:

Traceback (most recent call last):
  File "/usr/local/lib/python3.6/dist-packages/django/template/base.py", line 843, in _resolve_lookup
    current = getattr(current, bit)
AttributeError: 'dict' object has no attribute 'default'

During handling of the above exception, another exception occurred:

Traceback (most recent call last):
  File "/usr/local/lib/python3.6/dist-packages/django/template/base.py", line 849, in _resolve_lookup
    current = current[int(bit)]
ValueError: invalid literal for int() with base 10: 'default'

During handling of the above exception, another exception occurred:

Traceback (most recent call last):
  File "/usr/local/lib/python3.6/dist-packages/django/template/base.py", line 856, in _resolve_lookup
    (bit, current))  # missing attribute
django.template.base.VariableDoesNotExist: Failed lookup for key [default] in {'type': 'password', 'description': 'Password to access the device via SSH', 'minLength': 1}
[2021-09-05 22:11:49.411 DEBUG                    django.template : 878]
Exception while resolving variable 'required' in template 'ysdevices/device_form.html'.
Traceback (most recent call last):
  File "/usr/local/lib/python3.6/dist-packages/django/template/base.py", line 835, in _resolve_lookup
    current = current[bit]
KeyError: 'required'

During handling of the above exception, another exception occurred:

Traceback (most recent call last):
  File "/usr/local/lib/python3.6/dist-packages/django/template/base.py", line 843, in _resolve_lookup
    current = getattr(current, bit)
AttributeError: 'dict' object has no attribute 'required'

During handling of the above exception, another exception occurred:

Traceback (most recent call last):
  File "/usr/local/lib/python3.6/dist-packages/django/template/base.py", line 849, in _resolve_lookup
    current = current[int(bit)]
ValueError: invalid literal for int() with base 10: 'required'

During handling of the above exception, another exception occurred:

Traceback (most recent call last):
  File "/usr/local/lib/python3.6/dist-packages/django/template/base.py", line 856, in _resolve_lookup
    (bit, current))  # missing attribute
django.template.base.VariableDoesNotExist: Failed lookup for key [required] in {'type': 'password', 'description': 'Password to access the device via SSH', 'minLength': 1}
[2021-09-05 22:11:49.412 DEBUG                    django.template : 878]
Exception while resolving variable 'required' in template 'ysdevices/device_form.html'.
Traceback (most recent call last):
  File "/usr/local/lib/python3.6/dist-packages/django/template/base.py", line 835, in _resolve_lookup
    current = current[bit]
KeyError: 'required'

During handling of the above exception, another exception occurred:

Traceback (most recent call last):
  File "/usr/local/lib/python3.6/dist-packages/django/template/base.py", line 843, in _resolve_lookup
    current = getattr(current, bit)
AttributeError: 'dict' object has no attribute 'required'

During handling of the above exception, another exception occurred:

Traceback (most recent call last):
  File "/usr/local/lib/python3.6/dist-packages/django/template/base.py", line 849, in _resolve_lookup
    current = current[int(bit)]
ValueError: invalid literal for int() with base 10: 'required'

During handling of the above exception, another exception occurred:

Traceback (most recent call last):
  File "/usr/local/lib/python3.6/dist-packages/django/template/base.py", line 856, in _resolve_lookup
    (bit, current))  # missing attribute
django.template.base.VariableDoesNotExist: Failed lookup for key [required] in {'type': 'password', 'description': 'Password to access the device via SSH', 'minLength': 1}
[2021-09-05 22:11:49.412 DEBUG                    django.template : 878]
Exception while resolving variable 'label' in template 'ysdevices/device_form.html'.
Traceback (most recent call last):
  File "/usr/local/lib/python3.6/dist-packages/django/template/base.py", line 835, in _resolve_lookup
    current = current[bit]
KeyError: 'label'

During handling of the above exception, another exception occurred:

Traceback (most recent call last):
  File "/usr/local/lib/python3.6/dist-packages/django/template/base.py", line 843, in _resolve_lookup
    current = getattr(current, bit)
AttributeError: 'dict' object has no attribute 'label'

During handling of the above exception, another exception occurred:

Traceback (most recent call last):
  File "/usr/local/lib/python3.6/dist-packages/django/template/base.py", line 849, in _resolve_lookup
    current = current[int(bit)]
ValueError: invalid literal for int() with base 10: 'label'

During handling of the above exception, another exception occurred:

Traceback (most recent call last):
  File "/usr/local/lib/python3.6/dist-packages/django/template/base.py", line 856, in _resolve_lookup
    (bit, current))  # missing attribute
django.template.base.VariableDoesNotExist: Failed lookup for key [label] in {'type': 'password', 'description': 'Password to access the device via SSH', 'minLength': 1}
[2021-09-05 22:11:49.412 DEBUG                    django.template : 878]
Exception while resolving variable 'required' in template 'ysdevices/device_form.html'.
Traceback (most recent call last):
  File "/usr/local/lib/python3.6/dist-packages/django/template/base.py", line 835, in _resolve_lookup
    current = current[bit]
KeyError: 'required'

During handling of the above exception, another exception occurred:

Traceback (most recent call last):
  File "/usr/local/lib/python3.6/dist-packages/django/template/base.py", line 843, in _resolve_lookup
    current = getattr(current, bit)
AttributeError: 'dict' object has no attribute 'required'

During handling of the above exception, another exception occurred:

Traceback (most recent call last):
  File "/usr/local/lib/python3.6/dist-packages/django/template/base.py", line 849, in _resolve_lookup
    current = current[int(bit)]
ValueError: invalid literal for int() with base 10: 'required'

During handling of the above exception, another exception occurred:

Traceback (most recent call last):
  File "/usr/local/lib/python3.6/dist-packages/django/template/base.py", line 856, in _resolve_lookup
    (bit, current))  # missing attribute
django.template.base.VariableDoesNotExist: Failed lookup for key [required] in {'type': 'password', 'description': 'Password to access the device via SSH', 'minLength': 1}
[2021-09-05 22:11:49.412 DEBUG                    django.template : 878]
Exception while resolving variable 'minLength' in template 'ysdevices/device_form.html'.
Traceback (most recent call last):
  File "/usr/local/lib/python3.6/dist-packages/django/template/base.py", line 835, in _resolve_lookup
    current = current[bit]
KeyError: 'minLength'

During handling of the above exception, another exception occurred:

Traceback (most recent call last):
  File "/usr/local/lib/python3.6/dist-packages/django/template/base.py", line 843, in _resolve_lookup
    current = getattr(current, bit)
AttributeError: 'dict' object has no attribute 'minLength'

During handling of the above exception, another exception occurred:

Traceback (most recent call last):
  File "/usr/local/lib/python3.6/dist-packages/django/template/base.py", line 849, in _resolve_lookup
    current = current[int(bit)]
ValueError: invalid literal for int() with base 10: 'minLength'

During handling of the above exception, another exception occurred:

Traceback (most recent call last):
  File "/usr/local/lib/python3.6/dist-packages/django/template/base.py", line 856, in _resolve_lookup
    (bit, current))  # missing attribute
django.template.base.VariableDoesNotExist: Failed lookup for key [minLength] in {'type': 'int', 'description': 'Timeout, in seconds, for SSH requests', 'min': 0}
[2021-09-05 22:11:49.413 DEBUG                    django.template : 878]
Exception while resolving variable 'max' in template 'ysdevices/device_form.html'.
Traceback (most recent call last):
  File "/usr/local/lib/python3.6/dist-packages/django/template/base.py", line 835, in _resolve_lookup
    current = current[bit]
KeyError: 'max'

During handling of the above exception, another exception occurred:

Traceback (most recent call last):
  File "/usr/local/lib/python3.6/dist-packages/django/template/base.py", line 843, in _resolve_lookup
    current = getattr(current, bit)
AttributeError: 'dict' object has no attribute 'max'

During handling of the above exception, another exception occurred:

Traceback (most recent call last):
  File "/usr/local/lib/python3.6/dist-packages/django/template/base.py", line 849, in _resolve_lookup
    current = current[int(bit)]
ValueError: invalid literal for int() with base 10: 'max'

During handling of the above exception, another exception occurred:

Traceback (most recent call last):
  File "/usr/local/lib/python3.6/dist-packages/django/template/base.py", line 856, in _resolve_lookup
    (bit, current))  # missing attribute
django.template.base.VariableDoesNotExist: Failed lookup for key [max] in {'type': 'int', 'description': 'Timeout, in seconds, for SSH requests', 'min': 0}
[2021-09-05 22:11:49.413 DEBUG                    django.template : 878]
Exception while resolving variable 'maxLength' in template 'ysdevices/device_form.html'.
Traceback (most recent call last):
  File "/usr/local/lib/python3.6/dist-packages/django/template/base.py", line 835, in _resolve_lookup
    current = current[bit]
KeyError: 'maxLength'

During handling of the above exception, another exception occurred:

Traceback (most recent call last):
  File "/usr/local/lib/python3.6/dist-packages/django/template/base.py", line 843, in _resolve_lookup
    current = getattr(current, bit)
AttributeError: 'dict' object has no attribute 'maxLength'

During handling of the above exception, another exception occurred:

Traceback (most recent call last):
  File "/usr/local/lib/python3.6/dist-packages/django/template/base.py", line 849, in _resolve_lookup
    current = current[int(bit)]
ValueError: invalid literal for int() with base 10: 'maxLength'

During handling of the above exception, another exception occurred:

Traceback (most recent call last):
  File "/usr/local/lib/python3.6/dist-packages/django/template/base.py", line 856, in _resolve_lookup
    (bit, current))  # missing attribute
django.template.base.VariableDoesNotExist: Failed lookup for key [maxLength] in {'type': 'int', 'description': 'Timeout, in seconds, for SSH requests', 'min': 0}
[2021-09-05 22:11:49.413 DEBUG                    django.template : 878]
Exception while resolving variable 'step' in template 'ysdevices/device_form.html'.
Traceback (most recent call last):
  File "/usr/local/lib/python3.6/dist-packages/django/template/base.py", line 835, in _resolve_lookup
    current = current[bit]
KeyError: 'step'

During handling of the above exception, another exception occurred:

Traceback (most recent call last):
  File "/usr/local/lib/python3.6/dist-packages/django/template/base.py", line 843, in _resolve_lookup
    current = getattr(current, bit)
AttributeError: 'dict' object has no attribute 'step'

During handling of the above exception, another exception occurred:

Traceback (most recent call last):
  File "/usr/local/lib/python3.6/dist-packages/django/template/base.py", line 849, in _resolve_lookup
    current = current[int(bit)]
ValueError: invalid literal for int() with base 10: 'step'

During handling of the above exception, another exception occurred:

Traceback (most recent call last):
  File "/usr/local/lib/python3.6/dist-packages/django/template/base.py", line 856, in _resolve_lookup
    (bit, current))  # missing attribute
django.template.base.VariableDoesNotExist: Failed lookup for key [step] in {'type': 'int', 'description': 'Timeout, in seconds, for SSH requests', 'min': 0}
[2021-09-05 22:11:49.413 DEBUG                    django.template : 878]
Exception while resolving variable 'default' in template 'ysdevices/device_form.html'.
Traceback (most recent call last):
  File "/usr/local/lib/python3.6/dist-packages/django/template/base.py", line 835, in _resolve_lookup
    current = current[bit]
KeyError: 'default'

During handling of the above exception, another exception occurred:

Traceback (most recent call last):
  File "/usr/local/lib/python3.6/dist-packages/django/template/base.py", line 843, in _resolve_lookup
    current = getattr(current, bit)
AttributeError: 'dict' object has no attribute 'default'

During handling of the above exception, another exception occurred:

Traceback (most recent call last):
  File "/usr/local/lib/python3.6/dist-packages/django/template/base.py", line 849, in _resolve_lookup
    current = current[int(bit)]
ValueError: invalid literal for int() with base 10: 'default'

During handling of the above exception, another exception occurred:

Traceback (most recent call last):
  File "/usr/local/lib/python3.6/dist-packages/django/template/base.py", line 856, in _resolve_lookup
    (bit, current))  # missing attribute
django.template.base.VariableDoesNotExist: Failed lookup for key [default] in {'type': 'int', 'description': 'Timeout, in seconds, for SSH requests', 'min': 0}
[2021-09-05 22:11:49.414 DEBUG                    django.template : 878]
Exception while resolving variable 'default' in template 'ysdevices/device_form.html'.
Traceback (most recent call last):
  File "/usr/local/lib/python3.6/dist-packages/django/template/base.py", line 835, in _resolve_lookup
    current = current[bit]
KeyError: 'default'

During handling of the above exception, another exception occurred:

Traceback (most recent call last):
  File "/usr/local/lib/python3.6/dist-packages/django/template/base.py", line 843, in _resolve_lookup
    current = getattr(current, bit)
AttributeError: 'dict' object has no attribute 'default'

During handling of the above exception, another exception occurred:

Traceback (most recent call last):
  File "/usr/local/lib/python3.6/dist-packages/django/template/base.py", line 849, in _resolve_lookup
    current = current[int(bit)]
ValueError: invalid literal for int() with base 10: 'default'

During handling of the above exception, another exception occurred:

Traceback (most recent call last):
  File "/usr/local/lib/python3.6/dist-packages/django/template/base.py", line 856, in _resolve_lookup
    (bit, current))  # missing attribute
django.template.base.VariableDoesNotExist: Failed lookup for key [default] in {'type': 'int', 'description': 'Timeout, in seconds, for SSH requests', 'min': 0}
[2021-09-05 22:11:49.414 DEBUG                    django.template : 878]
Exception while resolving variable 'required' in template 'ysdevices/device_form.html'.
Traceback (most recent call last):
  File "/usr/local/lib/python3.6/dist-packages/django/template/base.py", line 835, in _resolve_lookup
    current = current[bit]
KeyError: 'required'

During handling of the above exception, another exception occurred:

Traceback (most recent call last):
  File "/usr/local/lib/python3.6/dist-packages/django/template/base.py", line 843, in _resolve_lookup
    current = getattr(current, bit)
AttributeError: 'dict' object has no attribute 'required'

During handling of the above exception, another exception occurred:

Traceback (most recent call last):
  File "/usr/local/lib/python3.6/dist-packages/django/template/base.py", line 849, in _resolve_lookup
    current = current[int(bit)]
ValueError: invalid literal for int() with base 10: 'required'

During handling of the above exception, another exception occurred:

Traceback (most recent call last):
  File "/usr/local/lib/python3.6/dist-packages/django/template/base.py", line 856, in _resolve_lookup
    (bit, current))  # missing attribute
django.template.base.VariableDoesNotExist: Failed lookup for key [required] in {'type': 'int', 'description': 'Timeout, in seconds, for SSH requests', 'min': 0}
[2021-09-05 22:11:49.414 DEBUG                    django.template : 878]
Exception while resolving variable 'required' in template 'ysdevices/device_form.html'.
Traceback (most recent call last):
  File "/usr/local/lib/python3.6/dist-packages/django/template/base.py", line 835, in _resolve_lookup
    current = current[bit]
KeyError: 'required'

During handling of the above exception, another exception occurred:

Traceback (most recent call last):
  File "/usr/local/lib/python3.6/dist-packages/django/template/base.py", line 843, in _resolve_lookup
    current = getattr(current, bit)
AttributeError: 'dict' object has no attribute 'required'

During handling of the above exception, another exception occurred:

Traceback (most recent call last):
  File "/usr/local/lib/python3.6/dist-packages/django/template/base.py", line 849, in _resolve_lookup
    current = current[int(bit)]
ValueError: invalid literal for int() with base 10: 'required'

During handling of the above exception, another exception occurred:

Traceback (most recent call last):
  File "/usr/local/lib/python3.6/dist-packages/django/template/base.py", line 856, in _resolve_lookup
    (bit, current))  # missing attribute
django.template.base.VariableDoesNotExist: Failed lookup for key [required] in {'type': 'int', 'description': 'Timeout, in seconds, for SSH requests', 'min': 0}
[2021-09-05 22:11:49.414 DEBUG                    django.template : 878]
Exception while resolving variable 'label' in template 'ysdevices/device_form.html'.
Traceback (most recent call last):
  File "/usr/local/lib/python3.6/dist-packages/django/template/base.py", line 835, in _resolve_lookup
    current = current[bit]
KeyError: 'label'

During handling of the above exception, another exception occurred:

Traceback (most recent call last):
  File "/usr/local/lib/python3.6/dist-packages/django/template/base.py", line 843, in _resolve_lookup
    current = getattr(current, bit)
AttributeError: 'dict' object has no attribute 'label'

During handling of the above exception, another exception occurred:

Traceback (most recent call last):
  File "/usr/local/lib/python3.6/dist-packages/django/template/base.py", line 849, in _resolve_lookup
    current = current[int(bit)]
ValueError: invalid literal for int() with base 10: 'label'

During handling of the above exception, another exception occurred:

Traceback (most recent call last):
  File "/usr/local/lib/python3.6/dist-packages/django/template/base.py", line 856, in _resolve_lookup
    (bit, current))  # missing attribute
django.template.base.VariableDoesNotExist: Failed lookup for key [label] in {'type': 'int', 'description': 'Timeout, in seconds, for SSH requests', 'min': 0}
[2021-09-05 22:11:49.415 DEBUG                    django.template : 878]
Exception while resolving variable 'required' in template 'ysdevices/device_form.html'.
Traceback (most recent call last):
  File "/usr/local/lib/python3.6/dist-packages/django/template/base.py", line 835, in _resolve_lookup
    current = current[bit]
KeyError: 'required'

During handling of the above exception, another exception occurred:

Traceback (most recent call last):
  File "/usr/local/lib/python3.6/dist-packages/django/template/base.py", line 843, in _resolve_lookup
    current = getattr(current, bit)
AttributeError: 'dict' object has no attribute 'required'

During handling of the above exception, another exception occurred:

Traceback (most recent call last):
  File "/usr/local/lib/python3.6/dist-packages/django/template/base.py", line 849, in _resolve_lookup
    current = current[int(bit)]
ValueError: invalid literal for int() with base 10: 'required'

During handling of the above exception, another exception occurred:

Traceback (most recent call last):
  File "/usr/local/lib/python3.6/dist-packages/django/template/base.py", line 856, in _resolve_lookup
    (bit, current))  # missing attribute
django.template.base.VariableDoesNotExist: Failed lookup for key [required] in {'type': 'int', 'description': 'Timeout, in seconds, for SSH requests', 'min': 0}
[2021-09-05 22:11:49.415 DEBUG                    django.template : 878]
Exception while resolving variable 'description' in template 'ysdevices/device_form.html'.
Traceback (most recent call last):
  File "/usr/local/lib/python3.6/dist-packages/django/template/base.py", line 835, in _resolve_lookup
    current = current[bit]
KeyError: 'description'

During handling of the above exception, another exception occurred:

Traceback (most recent call last):
  File "/usr/local/lib/python3.6/dist-packages/django/template/base.py", line 843, in _resolve_lookup
    current = getattr(current, bit)
AttributeError: 'dict' object has no attribute 'description'

During handling of the above exception, another exception occurred:

Traceback (most recent call last):
  File "/usr/local/lib/python3.6/dist-packages/django/template/base.py", line 849, in _resolve_lookup
    current = current[int(bit)]
ValueError: invalid literal for int() with base 10: 'description'

During handling of the above exception, another exception occurred:

Traceback (most recent call last):
  File "/usr/local/lib/python3.6/dist-packages/django/template/base.py", line 856, in _resolve_lookup
    (bit, current))  # missing attribute
django.template.base.VariableDoesNotExist: Failed lookup for key [description] in {'label': 'Use SSL Certificate', 'type': 'boolean', 'default': False}
[2021-09-05 22:16:33.331 DEBUG         yangsuite.ysdevices.plugin : 396]
Calling "ping -c 1 10.0.0.1"
[2021-09-05 22:16:33.336 DEBUG         yangsuite.ysdevices.plugin : 402]
b'PING 10.0.0.1 (10.0.0.1) 56(84) bytes of data.\n64 bytes from 10.0.0.1: icmp_seq=1 ttl=254 time=1.35 ms\n\n--- 10.0.0.1 ping statistics ---\n1 packets transmitted, 1 received, 0% packet loss, time 0ms\nrtt min/avg/max/mdev = 1.358/1.358/1.358/0.000 ms\n'
[2021-09-05 22:16:33.336 DEBUG     yangsuite.ysdevices.devprofile : 531]
Result: {'base': {'label': 'ping', 'status': True}, 'status': True}
[2021-09-05 22:16:33.337 INFO           yangsuite.ysdevices.views : 398]
Connectivity check for CiscoIOSXR: {'base': {'label': 'ping', 'status': True}, 'status': True, 'os_ver': ''}
[2021-09-05 22:18:28.488 INFO    yangsuite.ysfilemanager.filemanager.repository : 181]
Created YANG repository YANG repository 'CISCOXR' owned by 'admin' (0 modules)
[2021-09-05 22:21:45.564 DEBUG   yangsuite.ysfilemanager.filemanager.utility :  76]
Split userset "admin+ciscoxr" to user "admin", setname/reponame "ciscoxr"
[2021-09-05 22:21:45.565 DEBUG   yangsuite.ysfilemanager.filemanager.utility :  76]
Split userset "admin+ciscoxr" to user "admin", setname/reponame "ciscoxr"
[2021-09-05 22:21:45.647 INFO    yangsuite.ysfilemanager.filemanager.yangset : 280]
Loaded YANG set 'CISCOXR' owned by 'admin' (346 modules) from /ys-data/users/admin/yangsets/ciscoxr
[2021-09-05 22:21:46.851 DEBUG   yangsuite.ysfilemanager.filemanager.base : 496]
Module 'Cisco-IOS-XR-ha-eem-policy-oper': depends on module 'Cisco-IOS-XR-ha-eem-policy-oper-sub1' that was not scanned
[2021-09-05 22:21:46.852 DEBUG   yangsuite.ysfilemanager.filemanager.base : 496]
Module 'Cisco-IOS-XR-lpts-pre-ifib-oper': depends on module 'Cisco-IOS-XR-lpts-pre-ifib-oper-sub1' that was not scanned
[2021-09-05 22:21:46.852 DEBUG   yangsuite.ysfilemanager.filemanager.base : 496]
Module 'cisco-xr-netconf-monitoring-deviations': depends on module 'ietf-netconf-monitoring' that was not scanned
[2021-09-05 22:21:46.852 DEBUG   yangsuite.ysfilemanager.filemanager.base : 496]
Module 'openconfig-if-aggregate': depends on module 'iana-if-type' that was not scanned
[2021-09-05 22:21:46.852 DEBUG   yangsuite.ysfilemanager.filemanager.base : 496]
Module 'openconfig-interfaces': depends on module 'ietf-interfaces' that was not scanned
[2021-09-05 22:21:46.852 DEBUG   yangsuite.ysfilemanager.filemanager.base : 496]
Module 'openconfig-mpls': depends on module 'openconfig-mpls-igp' that was not scanned
[2021-09-05 22:21:46.853 DEBUG   yangsuite.ysfilemanager.filemanager.base : 496]
Module 'openconfig-mpls': depends on module 'openconfig-mpls-static' that was not scanned
[2021-09-05 22:21:46.853 DEBUG   yangsuite.ysfilemanager.filemanager.base : 496]
Module 'openconfig-mpls': depends on module 'openconfig-mpls-te' that was not scanned
[2021-09-05 22:22:13.694 DEBUG   yangsuite.ysfilemanager.filemanager.utility :  76]
Split userset "admin+ciscoxr" to user "admin", setname/reponame "ciscoxr"
[2021-09-05 22:22:13.697 DEBUG   yangsuite.ysfilemanager.filemanager.utility :  76]
Split userset "admin+ciscoxr" to user "admin", setname/reponame "ciscoxr"
[2021-09-05 22:22:13.745 INFO    yangsuite.ysfilemanager.filemanager.yangset : 280]
Loaded YANG set 'CISCOXR' owned by 'admin' (346 modules) from /ys-data/users/admin/yangsets/ciscoxr
[2021-09-05 22:24:01.198 DEBUG   yangsuite.ysfilemanager.filemanager.utility :  76]
Split userset "admin+ciscoxr" to user "admin", setname/reponame "ciscoxr"
[2021-09-05 22:24:01.198 DEBUG   yangsuite.ysfilemanager.filemanager.utility :  76]
Split userset "admin+ciscoxr" to user "admin", setname/reponame "ciscoxr"
[2021-09-05 22:24:01.243 INFO    yangsuite.ysfilemanager.filemanager.yangset : 280]
Loaded YANG set 'CISCOXR' owned by 'admin' (346 modules) from /ys-data/users/admin/yangsets/ciscoxr
