[2021-09-05 22:11:49.371 DEBUG                    django.template : 878]
Exception while resolving variable 'maxLength' in template 'ysdevices/device_form.html'.
Traceback (most recent call last):
  File "/usr/local/lib/python3.6/dist-packages/django/template/base.py", line 835, in _resolve_lookup
    current = current[bit]
KeyError: 'maxLength'

During handling of the above exception, another exception occurred:

Traceback (most recent call last):
  File "/usr/local/lib/python3.6/dist-packages/django/template/base.py", line 843, in _resolve_lookup
    current = getattr(current, bit)
AttributeError: 'dict' object has no attribute 'maxLength'

During handling of the above exception, another exception occurred:

Traceback (most recent call last):
  File "/usr/local/lib/python3.6/dist-packages/django/template/base.py", line 849, in _resolve_lookup
    current = current[int(bit)]
ValueError: invalid literal for int() with base 10: 'maxLength'

During handling of the above exception, another exception occurred:

Traceback (most recent call last):
  File "/usr/local/lib/python3.6/dist-packages/django/template/base.py", line 856, in _resolve_lookup
    (bit, current))  # missing attribute
django.template.base.VariableDoesNotExist: Failed lookup for key [maxLength] in {'label': 'TLS host override', 'type': 'string', 'description': 'Set to CN of certificate (hostname requires DNS).', 'minLength': 1}
[2021-09-05 22:11:49.371 DEBUG                    django.template : 878]
Exception while resolving variable 'step' in template 'ysdevices/device_form.html'.
Traceback (most recent call last):
  File "/usr/local/lib/python3.6/dist-packages/django/template/base.py", line 835, in _resolve_lookup
    current = current[bit]
KeyError: 'step'

During handling of the above exception, another exception occurred:

Traceback (most recent call last):
  File "/usr/local/lib/python3.6/dist-packages/django/template/base.py", line 843, in _resolve_lookup
    current = getattr(current, bit)
AttributeError: 'dict' object has no attribute 'step'

During handling of the above exception, another exception occurred:

Traceback (most recent call last):
  File "/usr/local/lib/python3.6/dist-packages/django/template/base.py", line 849, in _resolve_lookup
    current = current[int(bit)]
ValueError: invalid literal for int() with base 10: 'step'

During handling of the above exception, another exception occurred:

Traceback (most recent call last):
  File "/usr/local/lib/python3.6/dist-packages/django/template/base.py", line 856, in _resolve_lookup
    (bit, current))  # missing attribute
django.template.base.VariableDoesNotExist: Failed lookup for key [step] in {'label': 'TLS host override', 'type': 'string', 'description': 'Set to CN of certificate (hostname requires DNS).', 'minLength': 1}
[2021-09-05 22:11:49.372 DEBUG                    django.template : 878]
Exception while resolving variable 'default' in template 'ysdevices/device_form.html'.
Traceback (most recent call last):
  File "/usr/local/lib/python3.6/dist-packages/django/template/base.py", line 835, in _resolve_lookup
    current = current[bit]
KeyError: 'default'

During handling of the above exception, another exception occurred:

Traceback (most recent call last):
  File "/usr/local/lib/python3.6/dist-packages/django/template/base.py", line 843, in _resolve_lookup
    current = getattr(current, bit)
AttributeError: 'dict' object has no attribute 'default'

During handling of the above exception, another exception occurred:

Traceback (most recent call last):
  File "/usr/local/lib/python3.6/dist-packages/django/template/base.py", line 849, in _resolve_lookup
    current = current[int(bit)]
ValueError: invalid literal for int() with base 10: 'default'

During handling of the above exception, another exception occurred:

Traceback (most recent call last):
  File "/usr/local/lib/python3.6/dist-packages/django/template/base.py", line 856, in _resolve_lookup
    (bit, current))  # missing attribute
django.template.base.VariableDoesNotExist: Failed lookup for key [default] in {'label': 'TLS host override', 'type': 'string', 'description': 'Set to CN of certificate (hostname requires DNS).', 'minLength': 1}
[2021-09-05 22:11:49.372 DEBUG                    django.template : 878]
Exception while resolving variable 'default' in template 'ysdevices/device_form.html'.
Traceback (most recent call last):
  File "/usr/local/lib/python3.6/dist-packages/django/template/base.py", line 835, in _resolve_lookup
    current = current[bit]
KeyError: 'default'

During handling of the above exception, another exception occurred:

Traceback (most recent call last):
  File "/usr/local/lib/python3.6/dist-packages/django/template/base.py", line 843, in _resolve_lookup
    current = getattr(current, bit)
AttributeError: 'dict' object has no attribute 'default'

During handling of the above exception, another exception occurred:

Traceback (most recent call last):
  File "/usr/local/lib/python3.6/dist-packages/django/template/base.py", line 849, in _resolve_lookup
    current = current[int(bit)]
ValueError: invalid literal for int() with base 10: 'default'

During handling of the above exception, another exception occurred:

Traceback (most recent call last):
  File "/usr/local/lib/python3.6/dist-packages/django/template/base.py", line 856, in _resolve_lookup
    (bit, current))  # missing attribute
django.template.base.VariableDoesNotExist: Failed lookup for key [default] in {'label': 'TLS host override', 'type': 'string', 'description': 'Set to CN of certificate (hostname requires DNS).', 'minLength': 1}
[2021-09-05 22:11:49.372 DEBUG                    django.template : 878]
Exception while resolving variable 'required' in template 'ysdevices/device_form.html'.
Traceback (most recent call last):
  File "/usr/local/lib/python3.6/dist-packages/django/template/base.py", line 835, in _resolve_lookup
    current = current[bit]
KeyError: 'required'

During handling of the above exception, another exception occurred:

Traceback (most recent call last):
  File "/usr/local/lib/python3.6/dist-packages/django/template/base.py", line 843, in _resolve_lookup
    current = getattr(current, bit)
AttributeError: 'dict' object has no attribute 'required'

During handling of the above exception, another exception occurred:

Traceback (most recent call last):
  File "/usr/local/lib/python3.6/dist-packages/django/template/base.py", line 849, in _resolve_lookup
    current = current[int(bit)]
ValueError: invalid literal for int() with base 10: 'required'

During handling of the above exception, another exception occurred:

Traceback (most recent call last):
  File "/usr/local/lib/python3.6/dist-packages/django/template/base.py", line 856, in _resolve_lookup
    (bit, current))  # missing attribute
django.template.base.VariableDoesNotExist: Failed lookup for key [required] in {'label': 'TLS host override', 'type': 'string', 'description': 'Set to CN of certificate (hostname requires DNS).', 'minLength': 1}
[2021-09-05 22:11:49.372 DEBUG                    django.template : 878]
Exception while resolving variable 'required' in template 'ysdevices/device_form.html'.
Traceback (most recent call last):
  File "/usr/local/lib/python3.6/dist-packages/django/template/base.py", line 835, in _resolve_lookup
    current = current[bit]
KeyError: 'required'

During handling of the above exception, another exception occurred:

Traceback (most recent call last):
  File "/usr/local/lib/python3.6/dist-packages/django/template/base.py", line 843, in _resolve_lookup
    current = getattr(current, bit)
AttributeError: 'dict' object has no attribute 'required'

During handling of the above exception, another exception occurred:

Traceback (most recent call last):
  File "/usr/local/lib/python3.6/dist-packages/django/template/base.py", line 849, in _resolve_lookup
    current = current[int(bit)]
ValueError: invalid literal for int() with base 10: 'required'

During handling of the above exception, another exception occurred:

Traceback (most recent call last):
  File "/usr/local/lib/python3.6/dist-packages/django/template/base.py", line 856, in _resolve_lookup
    (bit, current))  # missing attribute
django.template.base.VariableDoesNotExist: Failed lookup for key [required] in {'label': 'TLS host override', 'type': 'string', 'description': 'Set to CN of certificate (hostname requires DNS).', 'minLength': 1}
[2021-09-05 22:11:49.373 DEBUG                    django.template : 878]
Exception while resolving variable 'required' in template 'ysdevices/device_form.html'.
Traceback (most recent call last):
  File "/usr/local/lib/python3.6/dist-packages/django/template/base.py", line 835, in _resolve_lookup
    current = current[bit]
KeyError: 'required'

During handling of the above exception, another exception occurred:

Traceback (most recent call last):
  File "/usr/local/lib/python3.6/dist-packages/django/template/base.py", line 843, in _resolve_lookup
    current = getattr(current, bit)
AttributeError: 'dict' object has no attribute 'required'

During handling of the above exception, another exception occurred:

Traceback (most recent call last):
  File "/usr/local/lib/python3.6/dist-packages/django/template/base.py", line 849, in _resolve_lookup
    current = current[int(bit)]
ValueError: invalid literal for int() with base 10: 'required'

During handling of the above exception, another exception occurred:

Traceback (most recent call last):
  File "/usr/local/lib/python3.6/dist-packages/django/template/base.py", line 856, in _resolve_lookup
    (bit, current))  # missing attribute
django.template.base.VariableDoesNotExist: Failed lookup for key [required] in {'label': 'TLS host override', 'type': 'string', 'description': 'Set to CN of certificate (hostname requires DNS).', 'minLength': 1}
[2021-09-05 22:11:49.373 DEBUG                    django.template : 878]
Exception while resolving variable 'description' in template 'ysdevices/device_form.html'.
Traceback (most recent call last):
  File "/usr/local/lib/python3.6/dist-packages/django/template/base.py", line 835, in _resolve_lookup
    current = current[bit]
KeyError: 'description'

During handling of the above exception, another exception occurred:

Traceback (most recent call last):
  File "/usr/local/lib/python3.6/dist-packages/django/template/base.py", line 843, in _resolve_lookup
    current = getattr(current, bit)
AttributeError: 'dict' object has no attribute 'description'

During handling of the above exception, another exception occurred:

Traceback (most recent call last):
  File "/usr/local/lib/python3.6/dist-packages/django/template/base.py", line 849, in _resolve_lookup
    current = current[int(bit)]
ValueError: invalid literal for int() with base 10: 'description'

During handling of the above exception, another exception occurred:

Traceback (most recent call last):
  File "/usr/local/lib/python3.6/dist-packages/django/template/base.py", line 856, in _resolve_lookup
    (bit, current))  # missing attribute
django.template.base.VariableDoesNotExist: Failed lookup for key [description] in {'label': 'Device supports NETCONF', 'type': 'boolean', 'default': False}
[2021-09-05 22:11:49.374 DEBUG                    django.template : 878]
Exception while resolving variable 'minLength' in template 'ysdevices/device_form.html'.
Traceback (most recent call last):
  File "/usr/local/lib/python3.6/dist-packages/django/template/base.py", line 835, in _resolve_lookup
    current = current[bit]
KeyError: 'minLength'

During handling of the above exception, another exception occurred:

Traceback (most recent call last):
  File "/usr/local/lib/python3.6/dist-packages/django/template/base.py", line 843, in _resolve_lookup
    current = getattr(current, bit)
AttributeError: 'dict' object has no attribute 'minLength'

During handling of the above exception, another exception occurred:

Traceback (most recent call last):
  File "/usr/local/lib/python3.6/dist-packages/django/template/base.py", line 849, in _resolve_lookup
    current = current[int(bit)]
ValueError: invalid literal for int() with base 10: 'minLength'

During handling of the above exception, another exception occurred:

Traceback (most recent call last):
  File "/usr/local/lib/python3.6/dist-packages/django/template/base.py", line 856, in _resolve_lookup
    (bit, current))  # missing attribute
django.template.base.VariableDoesNotExist: Failed lookup for key [minLength] in {'label': 'NETCONF port', 'type': 'int', 'description': 'Port number NETCONF listens on', 'min': 1, 'max': 65535, 'default': 830, 'required': True}
[2021-09-05 22:11:49.374 DEBUG                    django.template : 878]
Exception while resolving variable 'maxLength' in template 'ysdevices/device_form.html'.
Traceback (most recent call last):
  File "/usr/local/lib/python3.6/dist-packages/django/template/base.py", line 835, in _resolve_lookup
    current = current[bit]
KeyError: 'maxLength'

During handling of the above exception, another exception occurred:

Traceback (most recent call last):
  File "/usr/local/lib/python3.6/dist-packages/django/template/base.py", line 843, in _resolve_lookup
    current = getattr(current, bit)
AttributeError: 'dict' object has no attribute 'maxLength'

During handling of the above exception, another exception occurred:

Traceback (most recent call last):
  File "/usr/local/lib/python3.6/dist-packages/django/template/base.py", line 849, in _resolve_lookup
    current = current[int(bit)]
ValueError: invalid literal for int() with base 10: 'maxLength'

During handling of the above exception, another exception occurred:

Traceback (most recent call last):
  File "/usr/local/lib/python3.6/dist-packages/django/template/base.py", line 856, in _resolve_lookup
    (bit, current))  # missing attribute
django.template.base.VariableDoesNotExist: Failed lookup for key [maxLength] in {'label': 'NETCONF port', 'type': 'int', 'description': 'Port number NETCONF listens on', 'min': 1, 'max': 65535, 'default': 830, 'required': True}
[2021-09-05 22:11:49.375 DEBUG                    django.template : 878]
Exception while resolving variable 'step' in template 'ysdevices/device_form.html'.
Traceback (most recent call last):
  File "/usr/local/lib/python3.6/dist-packages/django/template/base.py", line 835, in _resolve_lookup
    current = current[bit]
KeyError: 'step'

During handling of the above exception, another exception occurred:

Traceback (most recent call last):
  File "/usr/local/lib/python3.6/dist-packages/django/template/base.py", line 843, in _resolve_lookup
    current = getattr(current, bit)
AttributeError: 'dict' object has no attribute 'step'

During handling of the above exception, another exception occurred:

Traceback (most recent call last):
  File "/usr/local/lib/python3.6/dist-packages/django/template/base.py", line 849, in _resolve_lookup
    current = current[int(bit)]
ValueError: invalid literal for int() with base 10: 'step'

During handling of the above exception, another exception occurred:

Traceback (most recent call last):
  File "/usr/local/lib/python3.6/dist-packages/django/template/base.py", line 856, in _resolve_lookup
    (bit, current))  # missing attribute
django.template.base.VariableDoesNotExist: Failed lookup for key [step] in {'label': 'NETCONF port', 'type': 'int', 'description': 'Port number NETCONF listens on', 'min': 1, 'max': 65535, 'default': 830, 'required': True}
[2021-09-05 22:11:49.375 DEBUG                    django.template : 878]
Exception while resolving variable 'description' in template 'ysdevices/device_form.html'.
Traceback (most recent call last):
  File "/usr/local/lib/python3.6/dist-packages/django/template/base.py", line 835, in _resolve_lookup
    current = current[bit]
KeyError: 'description'

During handling of the above exception, another exception occurred:

Traceback (most recent call last):
  File "/usr/local/lib/python3.6/dist-packages/django/template/base.py", line 843, in _resolve_lookup
    current = getattr(current, bit)
AttributeError: 'dict' object has no attribute 'description'

During handling of the above exception, another exception occurred:

Traceback (most recent call last):
  File "/usr/local/lib/python3.6/dist-packages/django/template/base.py", line 849, in _resolve_lookup
    current = current[int(bit)]
ValueError: invalid literal for int() with base 10: 'description'

During handling of the above exception, another exception occurred:

Traceback (most recent call last):
  File "/usr/local/lib/python3.6/dist-packages/django/template/base.py", line 856, in _resolve_lookup
    (bit, current))  # missing attribute
django.template.base.VariableDoesNotExist: Failed lookup for key [description] in {'label': 'Skip SSH key validation for this device', 'type': 'boolean', 'default': False}
[2021-09-05 22:11:49.375 DEBUG                    django.template : 878]
Exception while resolving variable 'min' in template 'ysdevices/device_form.html'.
Traceback (most recent call last):
  File "/usr/local/lib/python3.6/dist-packages/django/template/base.py", line 835, in _resolve_lookup
    current = current[bit]
KeyError: 'min'

During handling of the above exception, another exception occurred:

Traceback (most recent call last):
  File "/usr/local/lib/python3.6/dist-packages/django/template/base.py", line 843, in _resolve_lookup
    current = getattr(current, bit)
AttributeError: 'dict' object has no attribute 'min'

During handling of the above exception, another exception occurred:

Traceback (most recent call last):
  File "/usr/local/lib/python3.6/dist-packages/django/template/base.py", line 849, in _resolve_lookup
    current = current[int(bit)]
ValueError: invalid literal for int() with base 10: 'min'

During handling of the above exception, another exception occurred:

Traceback (most recent call last):
  File "/usr/local/lib/python3.6/dist-packages/django/template/base.py", line 856, in _resolve_lookup
    (bit, current))  # missing attribute
django.template.base.VariableDoesNotExist: Failed lookup for key [min] in {'type': 'string', 'description': 'Address or hostname to access via NETCONF'}
[2021-09-05 22:11:49.376 DEBUG                    django.template : 878]
Exception while resolving variable 'minLength' in template 'ysdevices/device_form.html'.
Traceback (most recent call last):
  File "/usr/local/lib/python3.6/dist-packages/django/template/base.py", line 835, in _resolve_lookup
    current = current[bit]
KeyError: 'minLength'

During handling of the above exception, another exception occurred:

Traceback (most recent call last):
  File "/usr/local/lib/python3.6/dist-packages/django/template/base.py", line 843, in _resolve_lookup
    current = getattr(current, bit)
AttributeError: 'dict' object has no attribute 'minLength'

During handling of the above exception, another exception occurred:

Traceback (most recent call last):
  File "/usr/local/lib/python3.6/dist-packages/django/template/base.py", line 849, in _resolve_lookup
    current = current[int(bit)]
ValueError: invalid literal for int() with base 10: 'minLength'

During handling of the above exception, another exception occurred:

Traceback (most recent call last):
  File "/usr/local/lib/python3.6/dist-packages/django/template/base.py", line 856, in _resolve_lookup
    (bit, current))  # missing attribute
django.template.base.VariableDoesNotExist: Failed lookup for key [minLength] in {'type': 'string', 'description': 'Address or hostname to access via NETCONF'}
[2021-09-05 22:11:49.376 DEBUG                    django.template : 878]
Exception while resolving variable 'max' in template 'ysdevices/device_form.html'.
Traceback (most recent call last):
  File "/usr/local/lib/python3.6/dist-packages/django/template/base.py", line 835, in _resolve_lookup
    current = current[bit]
KeyError: 'max'

During handling of the above exception, another exception occurred:

Traceback (most recent call last):
  File "/usr/local/lib/python3.6/dist-packages/django/template/base.py", line 843, in _resolve_lookup
    current = getattr(current, bit)
AttributeError: 'dict' object has no attribute 'max'

During handling of the above exception, another exception occurred:

Traceback (most recent call last):
  File "/usr/local/lib/python3.6/dist-packages/django/template/base.py", line 849, in _resolve_lookup
    current = current[int(bit)]
ValueError: invalid literal for int() with base 10: 'max'

During handling of the above exception, another exception occurred:

Traceback (most recent call last):
  File "/usr/local/lib/python3.6/dist-packages/django/template/base.py", line 856, in _resolve_lookup
    (bit, current))  # missing attribute
django.template.base.VariableDoesNotExist: Failed lookup for key [max] in {'type': 'string', 'description': 'Address or hostname to access via NETCONF'}
[2021-09-05 22:11:49.376 DEBUG                    django.template : 878]
Exception while resolving variable 'maxLength' in template 'ysdevices/device_form.html'.
Traceback (most recent call last):
  File "/usr/local/lib/python3.6/dist-packages/django/template/base.py", line 835, in _resolve_lookup
    current = current[bit]
KeyError: 'maxLength'

During handling of the above exception, another exception occurred:

Traceback (most recent call last):
  File "/usr/local/lib/python3.6/dist-packages/django/template/base.py", line 843, in _resolve_lookup
    current = getattr(current, bit)
AttributeError: 'dict' object has no attribute 'maxLength'

During handling of the above exception, another exception occurred:

Traceback (most recent call last):
  File "/usr/local/lib/python3.6/dist-packages/django/template/base.py", line 849, in _resolve_lookup
    current = current[int(bit)]
ValueError: invalid literal for int() with base 10: 'maxLength'

During handling of the above exception, another exception occurred:

Traceback (most recent call last):
  File "/usr/local/lib/python3.6/dist-packages/django/template/base.py", line 856, in _resolve_lookup
    (bit, current))  # missing attribute
django.template.base.VariableDoesNotExist: Failed lookup for key [maxLength] in {'type': 'string', 'description': 'Address or hostname to access via NETCONF'}
[2021-09-05 22:11:49.376 DEBUG                    django.template : 878]
Exception while resolving variable 'step' in template 'ysdevices/device_form.html'.
Traceback (most recent call last):
  File "/usr/local/lib/python3.6/dist-packages/django/template/base.py", line 835, in _resolve_lookup
    current = current[bit]
KeyError: 'step'

During handling of the above exception, another exception occurred:

Traceback (most recent call last):
  File "/usr/local/lib/python3.6/dist-packages/django/template/base.py", line 843, in _resolve_lookup
    current = getattr(current, bit)
AttributeError: 'dict' object has no attribute 'step'

During handling of the above exception, another exception occurred:

Traceback (most recent call last):
  File "/usr/local/lib/python3.6/dist-packages/django/template/base.py", line 849, in _resolve_lookup
    current = current[int(bit)]
ValueError: invalid literal for int() with base 10: 'step'

During handling of the above exception, another exception occurred:

Traceback (most recent call last):
  File "/usr/local/lib/python3.6/dist-packages/django/template/base.py", line 856, in _resolve_lookup
    (bit, current))  # missing attribute
django.template.base.VariableDoesNotExist: Failed lookup for key [step] in {'type': 'string', 'description': 'Address or hostname to access via NETCONF'}
[2021-09-05 22:11:49.377 DEBUG                    django.template : 878]
Exception while resolving variable 'default' in template 'ysdevices/device_form.html'.
Traceback (most recent call last):
  File "/usr/local/lib/python3.6/dist-packages/django/template/base.py", line 835, in _resolve_lookup
    current = current[bit]
KeyError: 'default'

During handling of the above exception, another exception occurred:

Traceback (most recent call last):
  File "/usr/local/lib/python3.6/dist-packages/django/template/base.py", line 843, in _resolve_lookup
    current = getattr(current, bit)
AttributeError: 'dict' object has no attribute 'default'

During handling of the above exception, another exception occurred:

Traceback (most recent call last):
  File "/usr/local/lib/python3.6/dist-packages/django/template/base.py", line 849, in _resolve_lookup
    current = current[int(bit)]
ValueError: invalid literal for int() with base 10: 'default'

During handling of the above exception, another exception occurred:

Traceback (most recent call last):
  File "/usr/local/lib/python3.6/dist-packages/django/template/base.py", line 856, in _resolve_lookup
    (bit, current))  # missing attribute
django.template.base.VariableDoesNotExist: Failed lookup for key [default] in {'type': 'string', 'description': 'Address or hostname to access via NETCONF'}
[2021-09-05 22:11:49.377 DEBUG                    django.template : 878]
Exception while resolving variable 'default' in template 'ysdevices/device_form.html'.
Traceback (most recent call last):
  File "/usr/local/lib/python3.6/dist-packages/django/template/base.py", line 835, in _resolve_lookup
    current = current[bit]
KeyError: 'default'

During handling of the above exception, another exception occurred:

Traceback (most recent call last):
  File "/usr/local/lib/python3.6/dist-packages/django/template/base.py", line 843, in _resolve_lookup
    current = getattr(current, bit)
AttributeError: 'dict' object has no attribute 'default'

During handling of the above exception, another exception occurred:

Traceback (most recent call last):
  File "/usr/local/lib/python3.6/dist-packages/django/template/base.py", line 849, in _resolve_lookup
    current = current[int(bit)]
ValueError: invalid literal for int() with base 10: 'default'

During handling of the above exception, another exception occurred:

Traceback (most recent call last):
  File "/usr/local/lib/python3.6/dist-packages/django/template/base.py", line 856, in _resolve_lookup
    (bit, current))  # missing attribute
django.template.base.VariableDoesNotExist: Failed lookup for key [default] in {'type': 'string', 'description': 'Address or hostname to access via NETCONF'}
[2021-09-05 22:11:49.377 DEBUG                    django.template : 878]
Exception while resolving variable 'required' in template 'ysdevices/device_form.html'.
Traceback (most recent call last):
  File "/usr/local/lib/python3.6/dist-packages/django/template/base.py", line 835, in _resolve_lookup
    current = current[bit]
KeyError: 'required'

During handling of the above exception, another exception occurred:

Traceback (most recent call last):
  File "/usr/local/lib/python3.6/dist-packages/django/template/base.py", line 843, in _resolve_lookup
    current = getattr(current, bit)
AttributeError: 'dict' object has no attribute 'required'

During handling of the above exception, another exception occurred:

Traceback (most recent call last):
  File "/usr/local/lib/python3.6/dist-packages/django/template/base.py", line 849, in _resolve_lookup
    current = current[int(bit)]
ValueError: invalid literal for int() with base 10: 'required'

During handling of the above exception, another exception occurred:

Traceback (most recent call last):
  File "/usr/local/lib/python3.6/dist-packages/django/template/base.py", line 856, in _resolve_lookup
    (bit, current))  # missing attribute
django.template.base.VariableDoesNotExist: Failed lookup for key [required] in {'type': 'string', 'description': 'Address or hostname to access via NETCONF'}
[2021-09-05 22:11:49.377 DEBUG                    django.template : 878]
Exception while resolving variable 'required' in template 'ysdevices/device_form.html'.
Traceback (most recent call last):
  File "/usr/local/lib/python3.6/dist-packages/django/template/base.py", line 835, in _resolve_lookup
    current = current[bit]
KeyError: 'required'

During handling of the above exception, another exception occurred:

Traceback (most recent call last):
  File "/usr/local/lib/python3.6/dist-packages/django/template/base.py", line 843, in _resolve_lookup
    current = getattr(current, bit)
AttributeError: 'dict' object has no attribute 'required'

During handling of the above exception, another exception occurred:

Traceback (most recent call last):
  File "/usr/local/lib/python3.6/dist-packages/django/template/base.py", line 849, in _resolve_lookup
    current = current[int(bit)]
ValueError: invalid literal for int() with base 10: 'required'

During handling of the above exception, another exception occurred:

Traceback (most recent call last):
  File "/usr/local/lib/python3.6/dist-packages/django/template/base.py", line 856, in _resolve_lookup
    (bit, current))  # missing attribute
django.template.base.VariableDoesNotExist: Failed lookup for key [required] in {'type': 'string', 'description': 'Address or hostname to access via NETCONF'}
[2021-09-05 22:11:49.378 DEBUG                    django.template : 878]
Exception while resolving variable 'label' in template 'ysdevices/device_form.html'.
Traceback (most recent call last):
  File "/usr/local/lib/python3.6/dist-packages/django/template/base.py", line 835, in _resolve_lookup
    current = current[bit]
KeyError: 'label'

During handling of the above exception, another exception occurred:

Traceback (most recent call last):
  File "/usr/local/lib/python3.6/dist-packages/django/template/base.py", line 843, in _resolve_lookup
    current = getattr(current, bit)
AttributeError: 'dict' object has no attribute 'label'

During handling of the above exception, another exception occurred:

Traceback (most recent call last):
  File "/usr/local/lib/python3.6/dist-packages/django/template/base.py", line 849, in _resolve_lookup
    current = current[int(bit)]
ValueError: invalid literal for int() with base 10: 'label'

During handling of the above exception, another exception occurred:

Traceback (most recent call last):
  File "/usr/local/lib/python3.6/dist-packages/django/template/base.py", line 856, in _resolve_lookup
    (bit, current))  # missing attribute
django.template.base.VariableDoesNotExist: Failed lookup for key [label] in {'type': 'string', 'description': 'Address or hostname to access via NETCONF'}
[2021-09-05 22:11:49.378 DEBUG                    django.template : 878]
Exception while resolving variable 'required' in template 'ysdevices/device_form.html'.
Traceback (most recent call last):
  File "/usr/local/lib/python3.6/dist-packages/django/template/base.py", line 835, in _resolve_lookup
    current = current[bit]
KeyError: 'required'

During handling of the above exception, another exception occurred:

Traceback (most recent call last):
  File "/usr/local/lib/python3.6/dist-packages/django/template/base.py", line 843, in _resolve_lookup
    current = getattr(current, bit)
AttributeError: 'dict' object has no attribute 'required'

During handling of the above exception, another exception occurred:

Traceback (most recent call last):
  File "/usr/local/lib/python3.6/dist-packages/django/template/base.py", line 849, in _resolve_lookup
    current = current[int(bit)]
ValueError: invalid literal for int() with base 10: 'required'

During handling of the above exception, another exception occurred:

Traceback (most recent call last):
  File "/usr/local/lib/python3.6/dist-packages/django/template/base.py", line 856, in _resolve_lookup
    (bit, current))  # missing attribute
django.template.base.VariableDoesNotExist: Failed lookup for key [required] in {'type': 'string', 'description': 'Address or hostname to access via NETCONF'}
[2021-09-05 22:11:49.378 DEBUG                    django.template : 878]
Exception while resolving variable 'min' in template 'ysdevices/device_form.html'.
Traceback (most recent call last):
  File "/usr/local/lib/python3.6/dist-packages/django/template/base.py", line 835, in _resolve_lookup
    current = current[bit]
KeyError: 'min'

During handling of the above exception, another exception occurred:

Traceback (most recent call last):
  File "/usr/local/lib/python3.6/dist-packages/django/template/base.py", line 843, in _resolve_lookup
    current = getattr(current, bit)
AttributeError: 'dict' object has no attribute 'min'

During handling of the above exception, another exception occurred:

Traceback (most recent call last):
  File "/usr/local/lib/python3.6/dist-packages/django/template/base.py", line 849, in _resolve_lookup
    current = current[int(bit)]
ValueError: invalid literal for int() with base 10: 'min'

During handling of the above exception, another exception occurred:

Traceback (most recent call last):
  File "/usr/local/lib/python3.6/dist-packages/django/template/base.py", line 856, in _resolve_lookup
    (bit, current))  # missing attribute
django.template.base.VariableDoesNotExist: Failed lookup for key [min] in {'type': 'string', 'description': 'Username to access the device via NETCONF', 'minLength': 1, 'maxLength': 50}
[2021-09-05 22:11:49.379 DEBUG                    django.template : 878]
Exception while resolving variable 'max' in template 'ysdevices/device_form.html'.
Traceback (most recent call last):
  File "/usr/local/lib/python3.6/dist-packages/django/template/base.py", line 835, in _resolve_lookup
    current = current[bit]
KeyError: 'max'

During handling of the above exception, another exception occurred:

Traceback (most recent call last):
  File "/usr/local/lib/python3.6/dist-packages/django/template/base.py", line 843, in _resolve_lookup
    current = getattr(current, bit)
AttributeError: 'dict' object has no attribute 'max'

During handling of the above exception, another exception occurred:

Traceback (most recent call last):
  File "/usr/local/lib/python3.6/dist-packages/django/template/base.py", line 849, in _resolve_lookup
    current = current[int(bit)]
ValueError: invalid literal for int() with base 10: 'max'

During handling of the above exception, another exception occurred:

Traceback (most recent call last):
  File "/usr/local/lib/python3.6/dist-packages/django/template/base.py", line 856, in _resolve_lookup
    (bit, current))  # missing attribute
django.template.base.VariableDoesNotExist: Failed lookup for key [max] in {'type': 'string', 'description': 'Username to access the device via NETCONF', 'minLength': 1, 'maxLength': 50}
[2021-09-05 22:11:49.379 DEBUG                    django.template : 878]
Exception while resolving variable 'step' in template 'ysdevices/device_form.html'.
Traceback (most recent call last):
  File "/usr/local/lib/python3.6/dist-packages/django/template/base.py", line 835, in _resolve_lookup
    current = current[bit]
KeyError: 'step'

During handling of the above exception, another exception occurred:

Traceback (most recent call last):
  File "/usr/local/lib/python3.6/dist-packages/django/template/base.py", line 843, in _resolve_lookup
    current = getattr(current, bit)
AttributeError: 'dict' object has no attribute 'step'

During handling of the above exception, another exception occurred:

Traceback (most recent call last):
  File "/usr/local/lib/python3.6/dist-packages/django/template/base.py", line 849, in _resolve_lookup
    current = current[int(bit)]
ValueError: invalid literal for int() with base 10: 'step'

During handling of the above exception, another exception occurred:

Traceback (most recent call last):
  File "/usr/local/lib/python3.6/dist-packages/django/template/base.py", line 856, in _resolve_lookup
    (bit, current))  # missing attribute
django.template.base.VariableDoesNotExist: Failed lookup for key [step] in {'type': 'string', 'description': 'Username to access the device via NETCONF', 'minLength': 1, 'maxLength': 50}
[2021-09-05 22:11:49.379 DEBUG                    django.template : 878]
Exception while resolving variable 'default' in template 'ysdevices/device_form.html'.
Traceback (most recent call last):
  File "/usr/local/lib/python3.6/dist-packages/django/template/base.py", line 835, in _resolve_lookup
    current = current[bit]
KeyError: 'default'

During handling of the above exception, another exception occurred:

Traceback (most recent call last):
  File "/usr/local/lib/python3.6/dist-packages/django/template/base.py", line 843, in _resolve_lookup
    current = getattr(current, bit)
AttributeError: 'dict' object has no attribute 'default'

During handling of the above exception, another exception occurred:

Traceback (most recent call last):
  File "/usr/local/lib/python3.6/dist-packages/django/template/base.py", line 849, in _resolve_lookup
    current = current[int(bit)]
ValueError: invalid literal for int() with base 10: 'default'

During handling of the above exception, another exception occurred:

Traceback (most recent call last):
  File "/usr/local/lib/python3.6/dist-packages/django/template/base.py", line 856, in _resolve_lookup
    (bit, current))  # missing attribute
django.template.base.VariableDoesNotExist: Failed lookup for key [default] in {'type': 'string', 'description': 'Username to access the device via NETCONF', 'minLength': 1, 'maxLength': 50}
[2021-09-05 22:11:49.379 DEBUG                    django.template : 878]
Exception while resolving variable 'default' in template 'ysdevices/device_form.html'.
Traceback (most recent call last):
  File "/usr/local/lib/python3.6/dist-packages/django/template/base.py", line 835, in _resolve_lookup
    current = current[bit]
KeyError: 'default'

During handling of the above exception, another exception occurred:

Traceback (most recent call last):
  File "/usr/local/lib/python3.6/dist-packages/django/template/base.py", line 843, in _resolve_lookup
    current = getattr(current, bit)
AttributeError: 'dict' object has no attribute 'default'

During handling of the above exception, another exception occurred:

Traceback (most recent call last):
  File "/usr/local/lib/python3.6/dist-packages/django/template/base.py", line 849, in _resolve_lookup
    current = current[int(bit)]
ValueError: invalid literal for int() with base 10: 'default'

During handling of the above exception, another exception occurred:

Traceback (most recent call last):
  File "/usr/local/lib/python3.6/dist-packages/django/template/base.py", line 856, in _resolve_lookup
    (bit, current))  # missing attribute
django.template.base.VariableDoesNotExist: Failed lookup for key [default] in {'type': 'string', 'description': 'Username to access the device via NETCONF', 'minLength': 1, 'maxLength': 50}
[2021-09-05 22:11:49.380 DEBUG                    django.template : 878]
Exception while resolving variable 'required' in template 'ysdevices/device_form.html'.
Traceback (most recent call last):
  File "/usr/local/lib/python3.6/dist-packages/django/template/base.py", line 835, in _resolve_lookup
    current = current[bit]
KeyError: 'required'

During handling of the above exception, another exception occurred:

Traceback (most recent call last):
  File "/usr/local/lib/python3.6/dist-packages/django/template/base.py", line 843, in _resolve_lookup
    current = getattr(current, bit)
AttributeError: 'dict' object has no attribute 'required'

During handling of the above exception, another exception occurred:

Traceback (most recent call last):
  File "/usr/local/lib/python3.6/dist-packages/django/template/base.py", line 849, in _resolve_lookup
    current = current[int(bit)]
ValueError: invalid literal for int() with base 10: 'required'

During handling of the above exception, another exception occurred:

Traceback (most recent call last):
  File "/usr/local/lib/python3.6/dist-packages/django/template/base.py", line 856, in _resolve_lookup
    (bit, current))  # missing attribute
django.template.base.VariableDoesNotExist: Failed lookup for key [required] in {'type': 'string', 'description': 'Username to access the device via NETCONF', 'minLength': 1, 'maxLength': 50}
[2021-09-05 22:11:49.380 DEBUG                    django.template : 878]
Exception while resolving variable 'required' in template 'ysdevices/device_form.html'.
Traceback (most recent call last):
  File "/usr/local/lib/python3.6/dist-packages/django/template/base.py", line 835, in _resolve_lookup
    current = current[bit]
KeyError: 'required'

During handling of the above exception, another exception occurred:

Traceback (most recent call last):
  File "/usr/local/lib/python3.6/dist-packages/django/template/base.py", line 843, in _resolve_lookup
    current = getattr(current, bit)
AttributeError: 'dict' object has no attribute 'required'

During handling of the above exception, another exception occurred:

Traceback (most recent call last):
  File "/usr/local/lib/python3.6/dist-packages/django/template/base.py", line 849, in _resolve_lookup
    current = current[int(bit)]
ValueError: invalid literal for int() with base 10: 'required'

During handling of the above exception, another exception occurred:

Traceback (most recent call last):
  File "/usr/local/lib/python3.6/dist-packages/django/template/base.py", line 856, in _resolve_lookup
    (bit, current))  # missing attribute
django.template.base.VariableDoesNotExist: Failed lookup for key [required] in {'type': 'string', 'description': 'Username to access the device via NETCONF', 'minLength': 1, 'maxLength': 50}
[2021-09-05 22:11:49.380 DEBUG                    django.template : 878]
Exception while resolving variable 'label' in template 'ysdevices/device_form.html'.
Traceback (most recent call last):
  File "/usr/local/lib/python3.6/dist-packages/django/template/base.py", line 835, in _resolve_lookup
    current = current[bit]
KeyError: 'label'

During handling of the above exception, another exception occurred:

Traceback (most recent call last):
  File "/usr/local/lib/python3.6/dist-packages/django/template/base.py", line 843, in _resolve_lookup
    current = getattr(current, bit)
AttributeError: 'dict' object has no attribute 'label'

During handling of the above exception, another exception occurred:

Traceback (most recent call last):
  File "/usr/local/lib/python3.6/dist-packages/django/template/base.py", line 849, in _resolve_lookup
    current = current[int(bit)]
ValueError: invalid literal for int() with base 10: 'label'

During handling of the above exception, another exception occurred:

Traceback (most recent call last):
  File "/usr/local/lib/python3.6/dist-packages/django/template/base.py", line 856, in _resolve_lookup
    (bit, current))  # missing attribute
django.template.base.VariableDoesNotExist: Failed lookup for key [label] in {'type': 'string', 'description': 'Username to access the device via NETCONF', 'minLength': 1, 'maxLength': 50}
[2021-09-05 22:11:49.380 DEBUG                    django.template : 878]
Exception while resolving variable 'required' in template 'ysdevices/device_form.html'.
Traceback (most recent call last):
  File "/usr/local/lib/python3.6/dist-packages/django/template/base.py", line 835, in _resolve_lookup
    current = current[bit]
KeyError: 'required'

During handling of the above exception, another exception occurred:

Traceback (most recent call last):
  File "/usr/local/lib/python3.6/dist-packages/django/template/base.py", line 843, in _resolve_lookup
    current = getattr(current, bit)
AttributeError: 'dict' object has no attribute 'required'

During handling of the above exception, another exception occurred:

Traceback (most recent call last):
  File "/usr/local/lib/python3.6/dist-packages/django/template/base.py", line 849, in _resolve_lookup
    current = current[int(bit)]
ValueError: invalid literal for int() with base 10: 'required'

During handling of the above exception, another exception occurred:

Traceback (most recent call last):
  File "/usr/local/lib/python3.6/dist-packages/django/template/base.py", line 856, in _resolve_lookup
    (bit, current))  # missing attribute
django.template.base.VariableDoesNotExist: Failed lookup for key [required] in {'type': 'string', 'description': 'Username to access the device via NETCONF', 'minLength': 1, 'maxLength': 50}
[2021-09-05 22:11:49.381 DEBUG                    django.template : 878]
Exception while resolving variable 'min' in template 'ysdevices/device_form.html'.
Traceback (most recent call last):
  File "/usr/local/lib/python3.6/dist-packages/django/template/base.py", line 835, in _resolve_lookup
    current = current[bit]
KeyError: 'min'

During handling of the above exception, another exception occurred:

Traceback (most recent call last):
  File "/usr/local/lib/python3.6/dist-packages/django/template/base.py", line 843, in _resolve_lookup
    current = getattr(current, bit)
AttributeError: 'dict' object has no attribute 'min'

During handling of the above exception, another exception occurred:

Traceback (most recent call last):
  File "/usr/local/lib/python3.6/dist-packages/django/template/base.py", line 849, in _resolve_lookup
    current = current[int(bit)]
ValueError: invalid literal for int() with base 10: 'min'

During handling of the above exception, another exception occurred:

Traceback (most recent call last):
  File "/usr/local/lib/python3.6/dist-packages/django/template/base.py", line 856, in _resolve_lookup
    (bit, current))  # missing attribute
django.template.base.VariableDoesNotExist: Failed lookup for key [min] in {'type': 'password', 'description': 'Password to access the device via NETCONF', 'minLength': 1, 'maxLength': 50}
[2021-09-05 22:11:49.381 DEBUG                    django.template : 878]
Exception while resolving variable 'max' in template 'ysdevices/device_form.html'.
Traceback (most recent call last):
  File "/usr/local/lib/python3.6/dist-packages/django/template/base.py", line 835, in _resolve_lookup
    current = current[bit]
KeyError: 'max'

During handling of the above exception, another exception occurred:

Traceback (most recent call last):
  File "/usr/local/lib/python3.6/dist-packages/django/template/base.py", line 843, in _resolve_lookup
    current = getattr(current, bit)
AttributeError: 'dict' object has no attribute 'max'

During handling of the above exception, another exception occurred:

Traceback (most recent call last):
  File "/usr/local/lib/python3.6/dist-packages/django/template/base.py", line 849, in _resolve_lookup
    current = current[int(bit)]
ValueError: invalid literal for int() with base 10: 'max'

During handling of the above exception, another exception occurred:

Traceback (most recent call last):
  File "/usr/local/lib/python3.6/dist-packages/django/template/base.py", line 856, in _resolve_lookup
    (bit, current))  # missing attribute
django.template.base.VariableDoesNotExist: Failed lookup for key [max] in {'type': 'password', 'description': 'Password to access the device via NETCONF', 'minLength': 1, 'maxLength': 50}
[2021-09-05 22:11:49.382 DEBUG                    django.template : 878]
Exception while resolving variable 'step' in template 'ysdevices/device_form.html'.
Traceback (most recent call last):
  File "/usr/local/lib/python3.6/dist-packages/django/template/base.py", line 835, in _resolve_lookup
    current = current[bit]
KeyError: 'step'

During handling of the above exception, another exception occurred:

Traceback (most recent call last):
  File "/usr/local/lib/python3.6/dist-packages/django/template/base.py", line 843, in _resolve_lookup
    current = getattr(current, bit)
AttributeError: 'dict' object has no attribute 'step'

During handling of the above exception, another exception occurred:

Traceback (most recent call last):
  File "/usr/local/lib/python3.6/dist-packages/django/template/base.py", line 849, in _resolve_lookup
    current = current[int(bit)]
ValueError: invalid literal for int() with base 10: 'step'

During handling of the above exception, another exception occurred:

Traceback (most recent call last):
  File "/usr/local/lib/python3.6/dist-packages/django/template/base.py", line 856, in _resolve_lookup
    (bit, current))  # missing attribute
django.template.base.VariableDoesNotExist: Failed lookup for key [step] in {'type': 'password', 'description': 'Password to access the device via NETCONF', 'minLength': 1, 'maxLength': 50}
[2021-09-05 22:11:49.382 DEBUG                    django.template : 878]
Exception while resolving variable 'default' in template 'ysdevices/device_form.html'.
Traceback (most recent call last):
  File "/usr/local/lib/python3.6/dist-packages/django/template/base.py", line 835, in _resolve_lookup
    current = current[bit]
KeyError: 'default'

During handling of the above exception, another exception occurred:

Traceback (most recent call last):
  File "/usr/local/lib/python3.6/dist-packages/django/template/base.py", line 843, in _resolve_lookup
    current = getattr(current, bit)
AttributeError: 'dict' object has no attribute 'default'

During handling of the above exception, another exception occurred:

Traceback (most recent call last):
  File "/usr/local/lib/python3.6/dist-packages/django/template/base.py", line 849, in _resolve_lookup
    current = current[int(bit)]
ValueError: invalid literal for int() with base 10: 'default'

During handling of the above exception, another exception occurred:

Traceback (most recent call last):
  File "/usr/local/lib/python3.6/dist-packages/django/template/base.py", line 856, in _resolve_lookup
    (bit, current))  # missing attribute
django.template.base.VariableDoesNotExist: Failed lookup for key [default] in {'type': 'password', 'description': 'Password to access the device via NETCONF', 'minLength': 1, 'maxLength': 50}
[2021-09-05 22:11:49.382 DEBUG                    django.template : 878]
Exception while resolving variable 'default' in template 'ysdevices/device_form.html'.
Traceback (most recent call last):
  File "/usr/local/lib/python3.6/dist-packages/django/template/base.py", line 835, in _resolve_lookup
    current = current[bit]
KeyError: 'default'

During handling of the above exception, another exception occurred:

Traceback (most recent call last):
  File "/usr/local/lib/python3.6/dist-packages/django/template/base.py", line 843, in _resolve_lookup
    current = getattr(current, bit)
AttributeError: 'dict' object has no attribute 'default'

During handling of the above exception, another exception occurred:

Traceback (most recent call last):
  File "/usr/local/lib/python3.6/dist-packages/django/template/base.py", line 849, in _resolve_lookup
    current = current[int(bit)]
ValueError: invalid literal for int() with base 10: 'default'

During handling of the above exception, another exception occurred:

Traceback (most recent call last):
  File "/usr/local/lib/python3.6/dist-packages/django/template/base.py", line 856, in _resolve_lookup
    (bit, current))  # missing attribute
django.template.base.VariableDoesNotExist: Failed lookup for key [default] in {'type': 'password', 'description': 'Password to access the device via NETCONF', 'minLength': 1, 'maxLength': 50}
[2021-09-05 22:11:49.382 DEBUG                    django.template : 878]
Exception while resolving variable 'required' in template 'ysdevices/device_form.html'.
Traceback (most recent call last):
  File "/usr/local/lib/python3.6/dist-packages/django/template/base.py", line 835, in _resolve_lookup
    current = current[bit]
KeyError: 'required'

During handling of the above exception, another exception occurred:

Traceback (most recent call last):
  File "/usr/local/lib/python3.6/dist-packages/django/template/base.py", line 843, in _resolve_lookup
    current = getattr(current, bit)
AttributeError: 'dict' object has no attribute 'required'

During handling of the above exception, another exception occurred:

Traceback (most recent call last):
  File "/usr/local/lib/python3.6/dist-packages/django/template/base.py", line 849, in _resolve_lookup
    current = current[int(bit)]
ValueError: invalid literal for int() with base 10: 'required'

During handling of the above exception, another exception occurred:

Traceback (most recent call last):
  File "/usr/local/lib/python3.6/dist-packages/django/template/base.py", line 856, in _resolve_lookup
    (bit, current))  # missing attribute
django.template.base.VariableDoesNotExist: Failed lookup for key [required] in {'type': 'password', 'description': 'Password to access the device via NETCONF', 'minLength': 1, 'maxLength': 50}
[2021-09-05 22:11:49.383 DEBUG                    django.template : 878]
Exception while resolving variable 'required' in template 'ysdevices/device_form.html'.
Traceback (most recent call last):
  File "/usr/local/lib/python3.6/dist-packages/django/template/base.py", line 835, in _resolve_lookup
    current = current[bit]
KeyError: 'required'

During handling of the above exception, another exception occurred:

Traceback (most recent call last):
  File "/usr/local/lib/python3.6/dist-packages/django/template/base.py", line 843, in _resolve_lookup
    current = getattr(current, bit)
AttributeError: 'dict' object has no attribute 'required'

During handling of the above exception, another exception occurred:

Traceback (most recent call last):
  File "/usr/local/lib/python3.6/dist-packages/django/template/base.py", line 849, in _resolve_lookup
    current = current[int(bit)]
ValueError: invalid literal for int() with base 10: 'required'

During handling of the above exception, another exception occurred:

Traceback (most recent call last):
  File "/usr/local/lib/python3.6/dist-packages/django/template/base.py", line 856, in _resolve_lookup
    (bit, current))  # missing attribute
django.template.base.VariableDoesNotExist: Failed lookup for key [required] in {'type': 'password', 'description': 'Password to access the device via NETCONF', 'minLength': 1, 'maxLength': 50}
[2021-09-05 22:11:49.383 DEBUG                    django.template : 878]
Exception while resolving variable 'label' in template 'ysdevices/device_form.html'.
Traceback (most recent call last):
  File "/usr/local/lib/python3.6/dist-packages/django/template/base.py", line 835, in _resolve_lookup
    current = current[bit]
KeyError: 'label'

During handling of the above exception, another exception occurred:

Traceback (most recent call last):
  File "/usr/local/lib/python3.6/dist-packages/django/template/base.py", line 843, in _resolve_lookup
    current = getattr(current, bit)
AttributeError: 'dict' object has no attribute 'label'

During handling of the above exception, another exception occurred:

Traceback (most recent call last):
  File "/usr/local/lib/python3.6/dist-packages/django/template/base.py", line 849, in _resolve_lookup
    current = current[int(bit)]
ValueError: invalid literal for int() with base 10: 'label'

During handling of the above exception, another exception occurred:

Traceback (most recent call last):
  File "/usr/local/lib/python3.6/dist-packages/django/template/base.py", line 856, in _resolve_lookup
    (bit, current))  # missing attribute
django.template.base.VariableDoesNotExist: Failed lookup for key [label] in {'type': 'password', 'description': 'Password to access the device via NETCONF', 'minLength': 1, 'maxLength': 50}
[2021-09-05 22:11:49.383 DEBUG                    django.template : 878]
Exception while resolving variable 'required' in template 'ysdevices/device_form.html'.
Traceback (most recent call last):
  File "/usr/local/lib/python3.6/dist-packages/django/template/base.py", line 835, in _resolve_lookup
    current = current[bit]
KeyError: 'required'

During handling of the above exception, another exception occurred:

Traceback (most recent call last):
  File "/usr/local/lib/python3.6/dist-packages/django/template/base.py", line 843, in _resolve_lookup
    current = getattr(current, bit)
AttributeError: 'dict' object has no attribute 'required'

During handling of the above exception, another exception occurred:

Traceback (most recent call last):
  File "/usr/local/lib/python3.6/dist-packages/django/template/base.py", line 849, in _resolve_lookup
    current = current[int(bit)]
ValueError: invalid literal for int() with base 10: 'required'

During handling of the above exception, another exception occurred:

Traceback (most recent call last):
  File "/usr/local/lib/python3.6/dist-packages/django/template/base.py", line 856, in _resolve_lookup
    (bit, current))  # missing attribute
django.template.base.VariableDoesNotExist: Failed lookup for key [required] in {'type': 'password', 'description': 'Password to access the device via NETCONF', 'minLength': 1, 'maxLength': 50}
[2021-09-05 22:11:49.384 DEBUG                    django.template : 878]
Exception while resolving variable 'minLength' in template 'ysdevices/device_form.html'.
Traceback (most recent call last):
  File "/usr/local/lib/python3.6/dist-packages/django/template/base.py", line 835, in _resolve_lookup
    current = current[bit]
KeyError: 'minLength'

During handling of the above exception, another exception occurred:

Traceback (most recent call last):
  File "/usr/local/lib/python3.6/dist-packages/django/template/base.py", line 843, in _resolve_lookup
    current = getattr(current, bit)
AttributeError: 'dict' object has no attribute 'minLength'

During handling of the above exception, another exception occurred:

Traceback (most recent call last):
  File "/usr/local/lib/python3.6/dist-packages/django/template/base.py", line 849, in _resolve_lookup
    current = current[int(bit)]
ValueError: invalid literal for int() with base 10: 'minLength'

During handling of the above exception, another exception occurred:

Traceback (most recent call last):
  File "/usr/local/lib/python3.6/dist-packages/django/template/base.py", line 856, in _resolve_lookup
    (bit, current))  # missing attribute
django.template.base.VariableDoesNotExist: Failed lookup for key [minLength] in {'type': 'int', 'description': 'Timeout, in seconds, for NETCONF requests', 'min': 0}
[2021-09-05 22:11:49.384 DEBUG                    django.template : 878]
Exception while resolving variable 'max' in template 'ysdevices/device_form.html'.
Traceback (most recent call last):
  File "/usr/local/lib/python3.6/dist-packages/django/template/base.py", line 835, in _resolve_lookup
    current = current[bit]
KeyError: 'max'

During handling of the above exception, another exception occurred:

Traceback (most recent call last):
  File "/usr/local/lib/python3.6/dist-packages/django/template/base.py", line 843, in _resolve_lookup
    current = getattr(current, bit)
AttributeError: 'dict' object has no attribute 'max'

During handling of the above exception, another exception occurred:

Traceback (most recent call last):
  File "/usr/local/lib/python3.6/dist-packages/django/template/base.py", line 849, in _resolve_lookup
    current = current[int(bit)]
ValueError: invalid literal for int() with base 10: 'max'

During handling of the above exception, another exception occurred:

Traceback (most recent call last):
  File "/usr/local/lib/python3.6/dist-packages/django/template/base.py", line 856, in _resolve_lookup
    (bit, current))  # missing attribute
django.template.base.VariableDoesNotExist: Failed lookup for key [max] in {'type': 'int', 'description': 'Timeout, in seconds, for NETCONF requests', 'min': 0}
[2021-09-05 22:11:49.384 DEBUG                    django.template : 878]
Exception while resolving variable 'maxLength' in template 'ysdevices/device_form.html'.
Traceback (most recent call last):
  File "/usr/local/lib/python3.6/dist-packages/django/template/base.py", line 835, in _resolve_lookup
    current = current[bit]
KeyError: 'maxLength'

During handling of the above exception, another exception occurred:

Traceback (most recent call last):
  File "/usr/local/lib/python3.6/dist-packages/django/template/base.py", line 843, in _resolve_lookup
    current = getattr(current, bit)
AttributeError: 'dict' object has no attribute 'maxLength'

During handling of the above exception, another exception occurred:

Traceback (most recent call last):
  File "/usr/local/lib/python3.6/dist-packages/django/template/base.py", line 849, in _resolve_lookup
    current = current[int(bit)]
ValueError: invalid literal for int() with base 10: 'maxLength'

During handling of the above exception, another exception occurred:

Traceback (most recent call last):
  File "/usr/local/lib/python3.6/dist-packages/django/template/base.py", line 856, in _resolve_lookup
    (bit, current))  # missing attribute
django.template.base.VariableDoesNotExist: Failed lookup for key [maxLength] in {'type': 'int', 'description': 'Timeout, in seconds, for NETCONF requests', 'min': 0}
[2021-09-05 22:11:49.384 DEBUG                    django.template : 878]
Exception while resolving variable 'step' in template 'ysdevices/device_form.html'.
Traceback (most recent call last):
  File "/usr/local/lib/python3.6/dist-packages/django/template/base.py", line 835, in _resolve_lookup
    current = current[bit]
KeyError: 'step'

During handling of the above exception, another exception occurred:

Traceback (most recent call last):
  File "/usr/local/lib/python3.6/dist-packages/django/template/base.py", line 843, in _resolve_lookup
    current = getattr(current, bit)
AttributeError: 'dict' object has no attribute 'step'

During handling of the above exception, another exception occurred:

Traceback (most recent call last):
  File "/usr/local/lib/python3.6/dist-packages/django/template/base.py", line 849, in _resolve_lookup
    current = current[int(bit)]
ValueError: invalid literal for int() with base 10: 'step'

During handling of the above exception, another exception occurred:

Traceback (most recent call last):
  File "/usr/local/lib/python3.6/dist-packages/django/template/base.py", line 856, in _resolve_lookup
    (bit, current))  # missing attribute
django.template.base.VariableDoesNotExist: Failed lookup for key [step] in {'type': 'int', 'description': 'Timeout, in seconds, for NETCONF requests', 'min': 0}
[2021-09-05 22:11:49.385 DEBUG                    django.template : 878]
Exception while resolving variable 'default' in template 'ysdevices/device_form.html'.
Traceback (most recent call last):
  File "/usr/local/lib/python3.6/dist-packages/django/template/base.py", line 835, in _resolve_lookup
    current = current[bit]
KeyError: 'default'

During handling of the above exception, another exception occurred:

Traceback (most recent call last):
  File "/usr/local/lib/python3.6/dist-packages/django/template/base.py", line 843, in _resolve_lookup
    current = getattr(current, bit)
AttributeError: 'dict' object has no attribute 'default'

During handling of the above exception, another exception occurred:

Traceback (most recent call last):
  File "/usr/local/lib/python3.6/dist-packages/django/template/base.py", line 849, in _resolve_lookup
    current = current[int(bit)]
ValueError: invalid literal for int() with base 10: 'default'

During handling of the above exception, another exception occurred:

Traceback (most recent call last):
  File "/usr/local/lib/python3.6/dist-packages/django/template/base.py", line 856, in _resolve_lookup
    (bit, current))  # missing attribute
django.template.base.VariableDoesNotExist: Failed lookup for key [default] in {'type': 'int', 'description': 'Timeout, in seconds, for NETCONF requests', 'min': 0}
[2021-09-05 22:11:49.385 DEBUG                    django.template : 878]
Exception while resolving variable 'default' in template 'ysdevices/device_form.html'.
Traceback (most recent call last):
  File "/usr/local/lib/python3.6/dist-packages/django/template/base.py", line 835, in _resolve_lookup
    current = current[bit]
KeyError: 'default'

During handling of the above exception, another exception occurred:

Traceback (most recent call last):
  File "/usr/local/lib/python3.6/dist-packages/django/template/base.py", line 843, in _resolve_lookup
    current = getattr(current, bit)
AttributeError: 'dict' object has no attribute 'default'

During handling of the above exception, another exception occurred:

Traceback (most recent call last):
  File "/usr/local/lib/python3.6/dist-packages/django/template/base.py", line 849, in _resolve_lookup
    current = current[int(bit)]
ValueError: invalid literal for int() with base 10: 'default'

During handling of the above exception, another exception occurred:

Traceback (most recent call last):
  File "/usr/local/lib/python3.6/dist-packages/django/template/base.py", line 856, in _resolve_lookup
    (bit, current))  # missing attribute
django.template.base.VariableDoesNotExist: Failed lookup for key [default] in {'type': 'int', 'description': 'Timeout, in seconds, for NETCONF requests', 'min': 0}
[2021-09-05 22:11:49.385 DEBUG                    django.template : 878]
Exception while resolving variable 'required' in template 'ysdevices/device_form.html'.
Traceback (most recent call last):
  File "/usr/local/lib/python3.6/dist-packages/django/template/base.py", line 835, in _resolve_lookup
    current = current[bit]
KeyError: 'required'

During handling of the above exception, another exception occurred:

Traceback (most recent call last):
  File "/usr/local/lib/python3.6/dist-packages/django/template/base.py", line 843, in _resolve_lookup
    current = getattr(current, bit)
AttributeError: 'dict' object has no attribute 'required'

During handling of the above exception, another exception occurred:

Traceback (most recent call last):
  File "/usr/local/lib/python3.6/dist-packages/django/template/base.py", line 849, in _resolve_lookup
    current = current[int(bit)]
ValueError: invalid literal for int() with base 10: 'required'

During handling of the above exception, another exception occurred:

Traceback (most recent call last):
  File "/usr/local/lib/python3.6/dist-packages/django/template/base.py", line 856, in _resolve_lookup
    (bit, current))  # missing attribute
django.template.base.VariableDoesNotExist: Failed lookup for key [required] in {'type': 'int', 'description': 'Timeout, in seconds, for NETCONF requests', 'min': 0}
[2021-09-05 22:11:49.385 DEBUG                    django.template : 878]
Exception while resolving variable 'required' in template 'ysdevices/device_form.html'.
Traceback (most recent call last):
  File "/usr/local/lib/python3.6/dist-packages/django/template/base.py", line 835, in _resolve_lookup
    current = current[bit]
KeyError: 'required'

During handling of the above exception, another exception occurred:

Traceback (most recent call last):
  File "/usr/local/lib/python3.6/dist-packages/django/template/base.py", line 843, in _resolve_lookup
    current = getattr(current, bit)
AttributeError: 'dict' object has no attribute 'required'

During handling of the above exception, another exception occurred:

Traceback (most recent call last):
  File "/usr/local/lib/python3.6/dist-packages/django/template/base.py", line 849, in _resolve_lookup
    current = current[int(bit)]
ValueError: invalid literal for int() with base 10: 'required'

During handling of the above exception, another exception occurred:

Traceback (most recent call last):
  File "/usr/local/lib/python3.6/dist-packages/django/template/base.py", line 856, in _resolve_lookup
    (bit, current))  # missing attribute
django.template.base.VariableDoesNotExist: Failed lookup for key [required] in {'type': 'int', 'description': 'Timeout, in seconds, for NETCONF requests', 'min': 0}
[2021-09-05 22:11:49.386 DEBUG                    django.template : 878]
Exception while resolving variable 'label' in template 'ysdevices/device_form.html'.
Traceback (most recent call last):
  File "/usr/local/lib/python3.6/dist-packages/django/template/base.py", line 835, in _resolve_lookup
    current = current[bit]
KeyError: 'label'

During handling of the above exception, another exception occurred:

Traceback (most recent call last):
  File "/usr/local/lib/python3.6/dist-packages/django/template/base.py", line 843, in _resolve_lookup
    current = getattr(current, bit)
AttributeError: 'dict' object has no attribute 'label'

During handling of the above exception, another exception occurred:

Traceback (most recent call last):
  File "/usr/local/lib/python3.6/dist-packages/django/template/base.py", line 849, in _resolve_lookup
    current = current[int(bit)]
ValueError: invalid literal for int() with base 10: 'label'

During handling of the above exception, another exception occurred:

Traceback (most recent call last):
  File "/usr/local/lib/python3.6/dist-packages/django/template/base.py", line 856, in _resolve_lookup
    (bit, current))  # missing attribute
django.template.base.VariableDoesNotExist: Failed lookup for key [label] in {'type': 'int', 'description': 'Timeout, in seconds, for NETCONF requests', 'min': 0}
[2021-09-05 22:11:49.386 DEBUG                    django.template : 878]
Exception while resolving variable 'required' in template 'ysdevices/device_form.html'.
Traceback (most recent call last):
  File "/usr/local/lib/python3.6/dist-packages/django/template/base.py", line 835, in _resolve_lookup
    current = current[bit]
KeyError: 'required'

During handling of the above exception, another exception occurred:

Traceback (most recent call last):
  File "/usr/local/lib/python3.6/dist-packages/django/template/base.py", line 843, in _resolve_lookup
    current = getattr(current, bit)
AttributeError: 'dict' object has no attribute 'required'

During handling of the above exception, another exception occurred:

Traceback (most recent call last):
  File "/usr/local/lib/python3.6/dist-packages/django/template/base.py", line 849, in _resolve_lookup
    current = current[int(bit)]
ValueError: invalid literal for int() with base 10: 'required'

During handling of the above exception, another exception occurred:

Traceback (most recent call last):
  File "/usr/local/lib/python3.6/dist-packages/django/template/base.py", line 856, in _resolve_lookup
    (bit, current))  # missing attribute
django.template.base.VariableDoesNotExist: Failed lookup for key [required] in {'type': 'int', 'description': 'Timeout, in seconds, for NETCONF requests', 'min': 0}
[2021-09-05 22:11:49.386 DEBUG                    django.template : 878]
Exception while resolving variable 'description' in template 'ysdevices/device_form.html'.
Traceback (most recent call last):
  File "/usr/local/lib/python3.6/dist-packages/django/template/base.py", line 835, in _resolve_lookup
    current = current[bit]
KeyError: 'description'

During handling of the above exception, another exception occurred:

Traceback (most recent call last):
  File "/usr/local/lib/python3.6/dist-packages/django/template/base.py", line 843, in _resolve_lookup
    current = getattr(current, bit)
AttributeError: 'dict' object has no attribute 'description'

During handling of the above exception, another exception occurred:

Traceback (most recent call last):
  File "/usr/local/lib/python3.6/dist-packages/django/template/base.py", line 849, in _resolve_lookup
    current = current[int(bit)]
ValueError: invalid literal for int() with base 10: 'description'

During handling of the above exception, another exception occurred:

Traceback (most recent call last):
  File "/usr/local/lib/python3.6/dist-packages/django/template/base.py", line 856, in _resolve_lookup
    (bit, current))  # missing attribute
django.template.base.VariableDoesNotExist: Failed lookup for key [description] in {'label': 'Device supports RESTCONF', 'type': 'boolean', 'default': False}
[2021-09-05 22:11:49.387 DEBUG                    django.template : 878]
Exception while resolving variable 'min' in template 'ysdevices/device_form.html'.
Traceback (most recent call last):
  File "/usr/local/lib/python3.6/dist-packages/django/template/base.py", line 835, in _resolve_lookup
    current = current[bit]
KeyError: 'min'

During handling of the above exception, another exception occurred:

Traceback (most recent call last):
  File "/usr/local/lib/python3.6/dist-packages/django/template/base.py", line 843, in _resolve_lookup
    current = getattr(current, bit)
AttributeError: 'dict' object has no attribute 'min'

During handling of the above exception, another exception occurred:

Traceback (most recent call last):
  File "/usr/local/lib/python3.6/dist-packages/django/template/base.py", line 849, in _resolve_lookup
    current = current[int(bit)]
ValueError: invalid literal for int() with base 10: 'min'

During handling of the above exception, another exception occurred:

Traceback (most recent call last):
  File "/usr/local/lib/python3.6/dist-packages/django/template/base.py", line 856, in _resolve_lookup
    (bit, current))  # missing attribute
django.template.base.VariableDoesNotExist: Failed lookup for key [min] in {'label': 'HTTP or HTTP(secure) encoding', 'type': 'string', 'default': 'https'}
[2021-09-05 22:11:49.387 DEBUG                    django.template : 878]
Exception while resolving variable 'minLength' in template 'ysdevices/device_form.html'.
Traceback (most recent call last):
  File "/usr/local/lib/python3.6/dist-packages/django/template/base.py", line 835, in _resolve_lookup
    current = current[bit]
KeyError: 'minLength'

During handling of the above exception, another exception occurred:

Traceback (most recent call last):
  File "/usr/local/lib/python3.6/dist-packages/django/template/base.py", line 843, in _resolve_lookup
    current = getattr(current, bit)
AttributeError: 'dict' object has no attribute 'minLength'

During handling of the above exception, another exception occurred:

Traceback (most recent call last):
  File "/usr/local/lib/python3.6/dist-packages/django/template/base.py", line 849, in _resolve_lookup
    current = current[int(bit)]
ValueError: invalid literal for int() with base 10: 'minLength'

During handling of the above exception, another exception occurred:

Traceback (most recent call last):
  File "/usr/local/lib/python3.6/dist-packages/django/template/base.py", line 856, in _resolve_lookup
    (bit, current))  # missing attribute
django.template.base.VariableDoesNotExist: Failed lookup for key [minLength] in {'label': 'HTTP or HTTP(secure) encoding', 'type': 'string', 'default': 'https'}
[2021-09-05 22:11:49.387 DEBUG                    django.template : 878]
Exception while resolving variable 'max' in template 'ysdevices/device_form.html'.
Traceback (most recent call last):
  File "/usr/local/lib/python3.6/dist-packages/django/template/base.py", line 835, in _resolve_lookup
    current = current[bit]
KeyError: 'max'

During handling of the above exception, another exception occurred:

Traceback (most recent call last):
  File "/usr/local/lib/python3.6/dist-packages/django/template/base.py", line 843, in _resolve_lookup
    current = getattr(current, bit)
AttributeError: 'dict' object has no attribute 'max'

During handling of the above exception, another exception occurred:

Traceback (most recent call last):
  File "/usr/local/lib/python3.6/dist-packages/django/template/base.py", line 849, in _resolve_lookup
    current = current[int(bit)]
ValueError: invalid literal for int() with base 10: 'max'

During handling of the above exception, another exception occurred:

Traceback (most recent call last):
  File "/usr/local/lib/python3.6/dist-packages/django/template/base.py", line 856, in _resolve_lookup
    (bit, current))  # missing attribute
django.template.base.VariableDoesNotExist: Failed lookup for key [max] in {'label': 'HTTP or HTTP(secure) encoding', 'type': 'string', 'default': 'https'}
[2021-09-05 22:11:49.387 DEBUG                    django.template : 878]
Exception while resolving variable 'maxLength' in template 'ysdevices/device_form.html'.
Traceback (most recent call last):
  File "/usr/local/lib/python3.6/dist-packages/django/template/base.py", line 835, in _resolve_lookup
    current = current[bit]
KeyError: 'maxLength'

During handling of the above exception, another exception occurred:

Traceback (most recent call last):
  File "/usr/local/lib/python3.6/dist-packages/django/template/base.py", line 843, in _resolve_lookup
    current = getattr(current, bit)
AttributeError: 'dict' object has no attribute 'maxLength'

During handling of the above exception, another exception occurred:

Traceback (most recent call last):
  File "/usr/local/lib/python3.6/dist-packages/django/template/base.py", line 849, in _resolve_lookup
    current = current[int(bit)]
ValueError: invalid literal for int() with base 10: 'maxLength'

During handling of the above exception, another exception occurred:

Traceback (most recent call last):
  File "/usr/local/lib/python3.6/dist-packages/django/template/base.py", line 856, in _resolve_lookup
    (bit, current))  # missing attribute
django.template.base.VariableDoesNotExist: Failed lookup for key [maxLength] in {'label': 'HTTP or HTTP(secure) encoding', 'type': 'string', 'default': 'https'}
[2021-09-05 22:11:49.388 DEBUG                    django.template : 878]
Exception while resolving variable 'step' in template 'ysdevices/device_form.html'.
Traceback (most recent call last):
  File "/usr/local/lib/python3.6/dist-packages/django/template/base.py", line 835, in _resolve_lookup
    current = current[bit]
KeyError: 'step'

During handling of the above exception, another exception occurred:

Traceback (most recent call last):
  File "/usr/local/lib/python3.6/dist-packages/django/template/base.py", line 843, in _resolve_lookup
    current = getattr(current, bit)
AttributeError: 'dict' object has no attribute 'step'

During handling of the above exception, another exception occurred:

Traceback (most recent call last):
  File "/usr/local/lib/python3.6/dist-packages/django/template/base.py", line 849, in _resolve_lookup
    current = current[int(bit)]
ValueError: invalid literal for int() with base 10: 'step'

During handling of the above exception, another exception occurred:

Traceback (most recent call last):
  File "/usr/local/lib/python3.6/dist-packages/django/template/base.py", line 856, in _resolve_lookup
    (bit, current))  # missing attribute
django.template.base.VariableDoesNotExist: Failed lookup for key [step] in {'label': 'HTTP or HTTP(secure) encoding', 'type': 'string', 'default': 'https'}
[2021-09-05 22:11:49.388 DEBUG                    django.template : 878]
Exception while resolving variable 'description' in template 'ysdevices/device_form.html'.
Traceback (most recent call last):
  File "/usr/local/lib/python3.6/dist-packages/django/template/base.py", line 835, in _resolve_lookup
    current = current[bit]
KeyError: 'description'

During handling of the above exception, another exception occurred:

Traceback (most recent call last):
  File "/usr/local/lib/python3.6/dist-packages/django/template/base.py", line 843, in _resolve_lookup
    current = getattr(current, bit)
AttributeError: 'dict' object has no attribute 'description'

During handling of the above exception, another exception occurred:

Traceback (most recent call last):
  File "/usr/local/lib/python3.6/dist-packages/django/template/base.py", line 849, in _resolve_lookup
    current = current[int(bit)]
ValueError: invalid literal for int() with base 10: 'description'

During handling of the above exception, another exception occurred:

Traceback (most recent call last):
  File "/usr/local/lib/python3.6/dist-packages/django/template/base.py", line 856, in _resolve_lookup
    (bit, current))  # missing attribute
django.template.base.VariableDoesNotExist: Failed lookup for key [description] in {'label': 'HTTP or HTTP(secure) encoding', 'type': 'string', 'default': 'https'}
[2021-09-05 22:11:49.388 DEBUG                    django.template : 878]
Exception while resolving variable 'required' in template 'ysdevices/device_form.html'.
Traceback (most recent call last):
  File "/usr/local/lib/python3.6/dist-packages/django/template/base.py", line 835, in _resolve_lookup
    current = current[bit]
KeyError: 'required'

During handling of the above exception, another exception occurred:

Traceback (most recent call last):
  File "/usr/local/lib/python3.6/dist-packages/django/template/base.py", line 843, in _resolve_lookup
    current = getattr(current, bit)
AttributeError: 'dict' object has no attribute 'required'

During handling of the above exception, another exception occurred:

Traceback (most recent call last):
  File "/usr/local/lib/python3.6/dist-packages/django/template/base.py", line 849, in _resolve_lookup
    current = current[int(bit)]
ValueError: invalid literal for int() with base 10: 'required'

During handling of the above exception, another exception occurred:

Traceback (most recent call last):
  File "/usr/local/lib/python3.6/dist-packages/django/template/base.py", line 856, in _resolve_lookup
    (bit, current))  # missing attribute
django.template.base.VariableDoesNotExist: Failed lookup for key [required] in {'label': 'HTTP or HTTP(secure) encoding', 'type': 'string', 'default': 'https'}
[2021-09-05 22:11:49.388 DEBUG                    django.template : 878]
Exception while resolving variable 'required' in template 'ysdevices/device_form.html'.
Traceback (most recent call last):
  File "/usr/local/lib/python3.6/dist-packages/django/template/base.py", line 835, in _resolve_lookup
    current = current[bit]
KeyError: 'required'

During handling of the above exception, another exception occurred:

Traceback (most recent call last):
  File "/usr/local/lib/python3.6/dist-packages/django/template/base.py", line 843, in _resolve_lookup
    current = getattr(current, bit)
AttributeError: 'dict' object has no attribute 'required'

During handling of the above exception, another exception occurred:

Traceback (most recent call last):
  File "/usr/local/lib/python3.6/dist-packages/django/template/base.py", line 849, in _resolve_lookup
    current = current[int(bit)]
ValueError: invalid literal for int() with base 10: 'required'

During handling of the above exception, another exception occurred:

Traceback (most recent call last):
  File "/usr/local/lib/python3.6/dist-packages/django/template/base.py", line 856, in _resolve_lookup
    (bit, current))  # missing attribute
django.template.base.VariableDoesNotExist: Failed lookup for key [required] in {'label': 'HTTP or HTTP(secure) encoding', 'type': 'string', 'default': 'https'}
[2021-09-05 22:11:49.389 DEBUG                    django.template : 878]
Exception while resolving variable 'min' in template 'ysdevices/device_form.html'.
Traceback (most recent call last):
  File "/usr/local/lib/python3.6/dist-packages/django/template/base.py", line 835, in _resolve_lookup
    current = current[bit]
KeyError: 'min'

During handling of the above exception, another exception occurred:

Traceback (most recent call last):
  File "/usr/local/lib/python3.6/dist-packages/django/template/base.py", line 843, in _resolve_lookup
    current = getattr(current, bit)
AttributeError: 'dict' object has no attribute 'min'

During handling of the above exception, another exception occurred:

Traceback (most recent call last):
  File "/usr/local/lib/python3.6/dist-packages/django/template/base.py", line 849, in _resolve_lookup
    current = current[int(bit)]
ValueError: invalid literal for int() with base 10: 'min'

During handling of the above exception, another exception occurred:

Traceback (most recent call last):
  File "/usr/local/lib/python3.6/dist-packages/django/template/base.py", line 856, in _resolve_lookup
    (bit, current))  # missing attribute
django.template.base.VariableDoesNotExist: Failed lookup for key [min] in {'label': 'RESTCONF base URL', 'type': 'string', 'default': '/restconf'}
[2021-09-05 22:11:49.389 DEBUG                    django.template : 878]
Exception while resolving variable 'minLength' in template 'ysdevices/device_form.html'.
Traceback (most recent call last):
  File "/usr/local/lib/python3.6/dist-packages/django/template/base.py", line 835, in _resolve_lookup
    current = current[bit]
KeyError: 'minLength'

During handling of the above exception, another exception occurred:

Traceback (most recent call last):
  File "/usr/local/lib/python3.6/dist-packages/django/template/base.py", line 843, in _resolve_lookup
    current = getattr(current, bit)
AttributeError: 'dict' object has no attribute 'minLength'

During handling of the above exception, another exception occurred:

Traceback (most recent call last):
  File "/usr/local/lib/python3.6/dist-packages/django/template/base.py", line 849, in _resolve_lookup
    current = current[int(bit)]
ValueError: invalid literal for int() with base 10: 'minLength'

During handling of the above exception, another exception occurred:

Traceback (most recent call last):
  File "/usr/local/lib/python3.6/dist-packages/django/template/base.py", line 856, in _resolve_lookup
    (bit, current))  # missing attribute
django.template.base.VariableDoesNotExist: Failed lookup for key [minLength] in {'label': 'RESTCONF base URL', 'type': 'string', 'default': '/restconf'}
[2021-09-05 22:11:49.389 DEBUG                    django.template : 878]
Exception while resolving variable 'max' in template 'ysdevices/device_form.html'.
Traceback (most recent call last):
  File "/usr/local/lib/python3.6/dist-packages/django/template/base.py", line 835, in _resolve_lookup
    current = current[bit]
KeyError: 'max'

During handling of the above exception, another exception occurred:

Traceback (most recent call last):
  File "/usr/local/lib/python3.6/dist-packages/django/template/base.py", line 843, in _resolve_lookup
    current = getattr(current, bit)
AttributeError: 'dict' object has no attribute 'max'

During handling of the above exception, another exception occurred:

Traceback (most recent call last):
  File "/usr/local/lib/python3.6/dist-packages/django/template/base.py", line 849, in _resolve_lookup
    current = current[int(bit)]
ValueError: invalid literal for int() with base 10: 'max'

During handling of the above exception, another exception occurred:

Traceback (most recent call last):
  File "/usr/local/lib/python3.6/dist-packages/django/template/base.py", line 856, in _resolve_lookup
    (bit, current))  # missing attribute
django.template.base.VariableDoesNotExist: Failed lookup for key [max] in {'label': 'RESTCONF base URL', 'type': 'string', 'default': '/restconf'}
[2021-09-05 22:11:49.389 DEBUG                    django.template : 878]
Exception while resolving variable 'maxLength' in template 'ysdevices/device_form.html'.
Traceback (most recent call last):
  File "/usr/local/lib/python3.6/dist-packages/django/template/base.py", line 835, in _resolve_lookup
    current = current[bit]
KeyError: 'maxLength'

During handling of the above exception, another exception occurred:

Traceback (most recent call last):
  File "/usr/local/lib/python3.6/dist-packages/django/template/base.py", line 843, in _resolve_lookup
    current = getattr(current, bit)
AttributeError: 'dict' object has no attribute 'maxLength'

During handling of the above exception, another exception occurred:

Traceback (most recent call last):
  File "/usr/local/lib/python3.6/dist-packages/django/template/base.py", line 849, in _resolve_lookup
    current = current[int(bit)]
ValueError: invalid literal for int() with base 10: 'maxLength'

During handling of the above exception, another exception occurred:

Traceback (most recent call last):
  File "/usr/local/lib/python3.6/dist-packages/django/template/base.py", line 856, in _resolve_lookup
    (bit, current))  # missing attribute
django.template.base.VariableDoesNotExist: Failed lookup for key [maxLength] in {'label': 'RESTCONF base URL', 'type': 'string', 'default': '/restconf'}
[2021-09-05 22:11:49.390 DEBUG                    django.template : 878]
Exception while resolving variable 'step' in template 'ysdevices/device_form.html'.
Traceback (most recent call last):
  File "/usr/local/lib/python3.6/dist-packages/django/template/base.py", line 835, in _resolve_lookup
    current = current[bit]
KeyError: 'step'

During handling of the above exception, another exception occurred:

Traceback (most recent call last):
  File "/usr/local/lib/python3.6/dist-packages/django/template/base.py", line 843, in _resolve_lookup
    current = getattr(current, bit)
AttributeError: 'dict' object has no attribute 'step'

During handling of the above exception, another exception occurred:

Traceback (most recent call last):
  File "/usr/local/lib/python3.6/dist-packages/django/template/base.py", line 849, in _resolve_lookup
    current = current[int(bit)]
ValueError: invalid literal for int() with base 10: 'step'

During handling of the above exception, another exception occurred:

Traceback (most recent call last):
  File "/usr/local/lib/python3.6/dist-packages/django/template/base.py", line 856, in _resolve_lookup
    (bit, current))  # missing attribute
django.template.base.VariableDoesNotExist: Failed lookup for key [step] in {'label': 'RESTCONF base URL', 'type': 'string', 'default': '/restconf'}
[2021-09-05 22:11:49.390 DEBUG                    django.template : 878]
Exception while resolving variable 'description' in template 'ysdevices/device_form.html'.
Traceback (most recent call last):
  File "/usr/local/lib/python3.6/dist-packages/django/template/base.py", line 835, in _resolve_lookup
    current = current[bit]
KeyError: 'description'

During handling of the above exception, another exception occurred:

Traceback (most recent call last):
  File "/usr/local/lib/python3.6/dist-packages/django/template/base.py", line 843, in _resolve_lookup
    current = getattr(current, bit)
AttributeError: 'dict' object has no attribute 'description'

During handling of the above exception, another exception occurred:

Traceback (most recent call last):
  File "/usr/local/lib/python3.6/dist-packages/django/template/base.py", line 849, in _resolve_lookup
    current = current[int(bit)]
ValueError: invalid literal for int() with base 10: 'description'

During handling of the above exception, another exception occurred:

Traceback (most recent call last):
  File "/usr/local/lib/python3.6/dist-packages/django/template/base.py", line 856, in _resolve_lookup
    (bit, current))  # missing attribute
django.template.base.VariableDoesNotExist: Failed lookup for key [description] in {'label': 'RESTCONF base URL', 'type': 'string', 'default': '/restconf'}
[2021-09-05 22:11:49.390 DEBUG                    django.template : 878]
Exception while resolving variable 'required' in template 'ysdevices/device_form.html'.
Traceback (most recent call last):
  File "/usr/local/lib/python3.6/dist-packages/django/template/base.py", line 835, in _resolve_lookup
    current = current[bit]
KeyError: 'required'

During handling of the above exception, another exception occurred:

Traceback (most recent call last):
  File "/usr/local/lib/python3.6/dist-packages/django/template/base.py", line 843, in _resolve_lookup
    current = getattr(current, bit)
AttributeError: 'dict' object has no attribute 'required'

During handling of the above exception, another exception occurred:

Traceback (most recent call last):
  File "/usr/local/lib/python3.6/dist-packages/django/template/base.py", line 849, in _resolve_lookup
    current = current[int(bit)]
ValueError: invalid literal for int() with base 10: 'required'

During handling of the above exception, another exception occurred:

Traceback (most recent call last):
  File "/usr/local/lib/python3.6/dist-packages/django/template/base.py", line 856, in _resolve_lookup
    (bit, current))  # missing attribute
django.template.base.VariableDoesNotExist: Failed lookup for key [required] in {'label': 'RESTCONF base URL', 'type': 'string', 'default': '/restconf'}
[2021-09-05 22:11:49.390 DEBUG                    django.template : 878]
Exception while resolving variable 'required' in template 'ysdevices/device_form.html'.
Traceback (most recent call last):
  File "/usr/local/lib/python3.6/dist-packages/django/template/base.py", line 835, in _resolve_lookup
    current = current[bit]
KeyError: 'required'

During handling of the above exception, another exception occurred:

Traceback (most recent call last):
  File "/usr/local/lib/python3.6/dist-packages/django/template/base.py", line 843, in _resolve_lookup
    current = getattr(current, bit)
AttributeError: 'dict' object has no attribute 'required'

During handling of the above exception, another exception occurred:

Traceback (most recent call last):
  File "/usr/local/lib/python3.6/dist-packages/django/template/base.py", line 849, in _resolve_lookup
    current = current[int(bit)]
ValueError: invalid literal for int() with base 10: 'required'

During handling of the above exception, another exception occurred:

Traceback (most recent call last):
  File "/usr/local/lib/python3.6/dist-packages/django/template/base.py", line 856, in _resolve_lookup
    (bit, current))  # missing attribute
django.template.base.VariableDoesNotExist: Failed lookup for key [required] in {'label': 'RESTCONF base URL', 'type': 'string', 'default': '/restconf'}
[2021-09-05 22:11:49.391 DEBUG                    django.template : 878]
Exception while resolving variable 'minLength' in template 'ysdevices/device_form.html'.
Traceback (most recent call last):
  File "/usr/local/lib/python3.6/dist-packages/django/template/base.py", line 835, in _resolve_lookup
    current = current[bit]
KeyError: 'minLength'

During handling of the above exception, another exception occurred:

Traceback (most recent call last):
  File "/usr/local/lib/python3.6/dist-packages/django/template/base.py", line 843, in _resolve_lookup
    current = getattr(current, bit)
AttributeError: 'dict' object has no attribute 'minLength'

During handling of the above exception, another exception occurred:

Traceback (most recent call last):
  File "/usr/local/lib/python3.6/dist-packages/django/template/base.py", line 849, in _resolve_lookup
    current = current[int(bit)]
ValueError: invalid literal for int() with base 10: 'minLength'

During handling of the above exception, another exception occurred:

Traceback (most recent call last):
  File "/usr/local/lib/python3.6/dist-packages/django/template/base.py", line 856, in _resolve_lookup
    (bit, current))  # missing attribute
django.template.base.VariableDoesNotExist: Failed lookup for key [minLength] in {'label': 'RESTCONF port', 'type': 'int', 'description': 'Port number RESTCONF listens on', 'min': 1, 'max': 65535, 'default': 443, 'required': True}
[2021-09-05 22:11:49.391 DEBUG                    django.template : 878]
Exception while resolving variable 'maxLength' in template 'ysdevices/device_form.html'.
Traceback (most recent call last):
  File "/usr/local/lib/python3.6/dist-packages/django/template/base.py", line 835, in _resolve_lookup
    current = current[bit]
KeyError: 'maxLength'

During handling of the above exception, another exception occurred:

Traceback (most recent call last):
  File "/usr/local/lib/python3.6/dist-packages/django/template/base.py", line 843, in _resolve_lookup
    current = getattr(current, bit)
AttributeError: 'dict' object has no attribute 'maxLength'

During handling of the above exception, another exception occurred:

Traceback (most recent call last):
  File "/usr/local/lib/python3.6/dist-packages/django/template/base.py", line 849, in _resolve_lookup
    current = current[int(bit)]
ValueError: invalid literal for int() with base 10: 'maxLength'

During handling of the above exception, another exception occurred:

Traceback (most recent call last):
  File "/usr/local/lib/python3.6/dist-packages/django/template/base.py", line 856, in _resolve_lookup
    (bit, current))  # missing attribute
django.template.base.VariableDoesNotExist: Failed lookup for key [maxLength] in {'label': 'RESTCONF port', 'type': 'int', 'description': 'Port number RESTCONF listens on', 'min': 1, 'max': 65535, 'default': 443, 'required': True}
[2021-09-05 22:11:49.391 DEBUG                    django.template : 878]
Exception while resolving variable 'step' in template 'ysdevices/device_form.html'.
Traceback (most recent call last):
  File "/usr/local/lib/python3.6/dist-packages/django/template/base.py", line 835, in _resolve_lookup
    current = current[bit]
KeyError: 'step'

During handling of the above exception, another exception occurred:

Traceback (most recent call last):
  File "/usr/local/lib/python3.6/dist-packages/django/template/base.py", line 843, in _resolve_lookup
    current = getattr(current, bit)
AttributeError: 'dict' object has no attribute 'step'

During handling of the above exception, another exception occurred:

Traceback (most recent call last):
  File "/usr/local/lib/python3.6/dist-packages/django/template/base.py", line 849, in _resolve_lookup
    current = current[int(bit)]
ValueError: invalid literal for int() with base 10: 'step'

During handling of the above exception, another exception occurred:

Traceback (most recent call last):
  File "/usr/local/lib/python3.6/dist-packages/django/template/base.py", line 856, in _resolve_lookup
    (bit, current))  # missing attribute
django.template.base.VariableDoesNotExist: Failed lookup for key [step] in {'label': 'RESTCONF port', 'type': 'int', 'description': 'Port number RESTCONF listens on', 'min': 1, 'max': 65535, 'default': 443, 'required': True}
[2021-09-05 22:11:49.392 DEBUG                    django.template : 878]
Exception while resolving variable 'min' in template 'ysdevices/device_form.html'.
Traceback (most recent call last):
  File "/usr/local/lib/python3.6/dist-packages/django/template/base.py", line 835, in _resolve_lookup
    current = current[bit]
KeyError: 'min'

During handling of the above exception, another exception occurred:

Traceback (most recent call last):
  File "/usr/local/lib/python3.6/dist-packages/django/template/base.py", line 843, in _resolve_lookup
    current = getattr(current, bit)
AttributeError: 'dict' object has no attribute 'min'

During handling of the above exception, another exception occurred:

Traceback (most recent call last):
  File "/usr/local/lib/python3.6/dist-packages/django/template/base.py", line 849, in _resolve_lookup
    current = current[int(bit)]
ValueError: invalid literal for int() with base 10: 'min'

During handling of the above exception, another exception occurred:

Traceback (most recent call last):
  File "/usr/local/lib/python3.6/dist-packages/django/template/base.py", line 856, in _resolve_lookup
    (bit, current))  # missing attribute
django.template.base.VariableDoesNotExist: Failed lookup for key [min] in {'type': 'string', 'description': 'Address or hostname to access via RESTCONF'}
[2021-09-05 22:11:49.392 DEBUG                    django.template : 878]
Exception while resolving variable 'minLength' in template 'ysdevices/device_form.html'.
Traceback (most recent call last):
  File "/usr/local/lib/python3.6/dist-packages/django/template/base.py", line 835, in _resolve_lookup
    current = current[bit]
KeyError: 'minLength'

During handling of the above exception, another exception occurred:

Traceback (most recent call last):
  File "/usr/local/lib/python3.6/dist-packages/django/template/base.py", line 843, in _resolve_lookup
    current = getattr(current, bit)
AttributeError: 'dict' object has no attribute 'minLength'

During handling of the above exception, another exception occurred:

Traceback (most recent call last):
  File "/usr/local/lib/python3.6/dist-packages/django/template/base.py", line 849, in _resolve_lookup
    current = current[int(bit)]
ValueError: invalid literal for int() with base 10: 'minLength'

During handling of the above exception, another exception occurred:

Traceback (most recent call last):
  File "/usr/local/lib/python3.6/dist-packages/django/template/base.py", line 856, in _resolve_lookup
    (bit, current))  # missing attribute
django.template.base.VariableDoesNotExist: Failed lookup for key [minLength] in {'type': 'string', 'description': 'Address or hostname to access via RESTCONF'}
[2021-09-05 22:11:49.392 DEBUG                    django.template : 878]
Exception while resolving variable 'max' in template 'ysdevices/device_form.html'.
Traceback (most recent call last):
  File "/usr/local/lib/python3.6/dist-packages/django/template/base.py", line 835, in _resolve_lookup
    current = current[bit]
KeyError: 'max'

During handling of the above exception, another exception occurred:

Traceback (most recent call last):
  File "/usr/local/lib/python3.6/dist-packages/django/template/base.py", line 843, in _resolve_lookup
    current = getattr(current, bit)
AttributeError: 'dict' object has no attribute 'max'

During handling of the above exception, another exception occurred:

Traceback (most recent call last):
  File "/usr/local/lib/python3.6/dist-packages/django/template/base.py", line 849, in _resolve_lookup
    current = current[int(bit)]
ValueError: invalid literal for int() with base 10: 'max'

During handling of the above exception, another exception occurred:

Traceback (most recent call last):
  File "/usr/local/lib/python3.6/dist-packages/django/template/base.py", line 856, in _resolve_lookup
    (bit, current))  # missing attribute
django.template.base.VariableDoesNotExist: Failed lookup for key [max] in {'type': 'string', 'description': 'Address or hostname to access via RESTCONF'}
[2021-09-05 22:11:49.392 DEBUG                    django.template : 878]
Exception while resolving variable 'maxLength' in template 'ysdevices/device_form.html'.
Traceback (most recent call last):
  File "/usr/local/lib/python3.6/dist-packages/django/template/base.py", line 835, in _resolve_lookup
    current = current[bit]
KeyError: 'maxLength'

During handling of the above exception, another exception occurred:

Traceback (most recent call last):
  File "/usr/local/lib/python3.6/dist-packages/django/template/base.py", line 843, in _resolve_lookup
    current = getattr(current, bit)
AttributeError: 'dict' object has no attribute 'maxLength'

During handling of the above exception, another exception occurred:

Traceback (most recent call last):
  File "/usr/local/lib/python3.6/dist-packages/django/template/base.py", line 849, in _resolve_lookup
    current = current[int(bit)]
ValueError: invalid literal for int() with base 10: 'maxLength'

During handling of the above exception, another exception occurred:

Traceback (most recent call last):
  File "/usr/local/lib/python3.6/dist-packages/django/template/base.py", line 856, in _resolve_lookup
    (bit, current))  # missing attribute
django.template.base.VariableDoesNotExist: Failed lookup for key [maxLength] in {'type': 'string', 'description': 'Address or hostname to access via RESTCONF'}
[2021-09-05 22:11:49.392 DEBUG                    django.template : 878]
Exception while resolving variable 'step' in template 'ysdevices/device_form.html'.
Traceback (most recent call last):
  File "/usr/local/lib/python3.6/dist-packages/django/template/base.py", line 835, in _resolve_lookup
    current = current[bit]
KeyError: 'step'

During handling of the above exception, another exception occurred:

Traceback (most recent call last):
  File "/usr/local/lib/python3.6/dist-packages/django/template/base.py", line 843, in _resolve_lookup
    current = getattr(current, bit)
AttributeError: 'dict' object has no attribute 'step'

During handling of the above exception, another exception occurred:

Traceback (most recent call last):
  File "/usr/local/lib/python3.6/dist-packages/django/template/base.py", line 849, in _resolve_lookup
    current = current[int(bit)]
ValueError: invalid literal for int() with base 10: 'step'

During handling of the above exception, another exception occurred:

Traceback (most recent call last):
  File "/usr/local/lib/python3.6/dist-packages/django/template/base.py", line 856, in _resolve_lookup
    (bit, current))  # missing attribute
django.template.base.VariableDoesNotExist: Failed lookup for key [step] in {'type': 'string', 'description': 'Address or hostname to access via RESTCONF'}
[2021-09-05 22:11:49.393 DEBUG                    django.template : 878]
Exception while resolving variable 'default' in template 'ysdevices/device_form.html'.
Traceback (most recent call last):
  File "/usr/local/lib/python3.6/dist-packages/django/template/base.py", line 835, in _resolve_lookup
    current = current[bit]
KeyError: 'default'

During handling of the above exception, another exception occurred:

Traceback (most recent call last):
  File "/usr/local/lib/python3.6/dist-packages/django/template/base.py", line 843, in _resolve_lookup
    current = getattr(current, bit)
AttributeError: 'dict' object has no attribute 'default'

During handling of the above exception, another exception occurred:

Traceback (most recent call last):
  File "/usr/local/lib/python3.6/dist-packages/django/template/base.py", line 849, in _resolve_lookup
    current = current[int(bit)]
ValueError: invalid literal for int() with base 10: 'default'

During handling of the above exception, another exception occurred:

Traceback (most recent call last):
  File "/usr/local/lib/python3.6/dist-packages/django/template/base.py", line 856, in _resolve_lookup
    (bit, current))  # missing attribute
django.template.base.VariableDoesNotExist: Failed lookup for key [default] in {'type': 'string', 'description': 'Address or hostname to access via RESTCONF'}
[2021-09-05 22:11:49.393 DEBUG                    django.template : 878]
Exception while resolving variable 'default' in template 'ysdevices/device_form.html'.
Traceback (most recent call last):
  File "/usr/local/lib/python3.6/dist-packages/django/template/base.py", line 835, in _resolve_lookup
    current = current[bit]
KeyError: 'default'

During handling of the above exception, another exception occurred:

Traceback (most recent call last):
  File "/usr/local/lib/python3.6/dist-packages/django/template/base.py", line 843, in _resolve_lookup
    current = getattr(current, bit)
AttributeError: 'dict' object has no attribute 'default'

During handling of the above exception, another exception occurred:

Traceback (most recent call last):
  File "/usr/local/lib/python3.6/dist-packages/django/template/base.py", line 849, in _resolve_lookup
    current = current[int(bit)]
ValueError: invalid literal for int() with base 10: 'default'

During handling of the above exception, another exception occurred:

Traceback (most recent call last):
  File "/usr/local/lib/python3.6/dist-packages/django/template/base.py", line 856, in _resolve_lookup
    (bit, current))  # missing attribute
django.template.base.VariableDoesNotExist: Failed lookup for key [default] in {'type': 'string', 'description': 'Address or hostname to access via RESTCONF'}
[2021-09-05 22:11:49.393 DEBUG                    django.template : 878]
Exception while resolving variable 'required' in template 'ysdevices/device_form.html'.
Traceback (most recent call last):
  File "/usr/local/lib/python3.6/dist-packages/django/template/base.py", line 835, in _resolve_lookup
    current = current[bit]
KeyError: 'required'

During handling of the above exception, another exception occurred:

Traceback (most recent call last):
  File "/usr/local/lib/python3.6/dist-packages/django/template/base.py", line 843, in _resolve_lookup
    current = getattr(current, bit)
AttributeError: 'dict' object has no attribute 'required'

During handling of the above exception, another exception occurred:

Traceback (most recent call last):
  File "/usr/local/lib/python3.6/dist-packages/django/template/base.py", line 849, in _resolve_lookup
    current = current[int(bit)]
ValueError: invalid literal for int() with base 10: 'required'

During handling of the above exception, another exception occurred:

Traceback (most recent call last):
  File "/usr/local/lib/python3.6/dist-packages/django/template/base.py", line 856, in _resolve_lookup
    (bit, current))  # missing attribute
django.template.base.VariableDoesNotExist: Failed lookup for key [required] in {'type': 'string', 'description': 'Address or hostname to access via RESTCONF'}
[2021-09-05 22:11:49.393 DEBUG                    django.template : 878]
Exception while resolving variable 'required' in template 'ysdevices/device_form.html'.
Traceback (most recent call last):
  File "/usr/local/lib/python3.6/dist-packages/django/template/base.py", line 835, in _resolve_lookup
    current = current[bit]
KeyError: 'required'

During handling of the above exception, another exception occurred:

Traceback (most recent call last):
  File "/usr/local/lib/python3.6/dist-packages/django/template/base.py", line 843, in _resolve_lookup
    current = getattr(current, bit)
AttributeError: 'dict' object has no attribute 'required'

During handling of the above exception, another exception occurred:

Traceback (most recent call last):
  File "/usr/local/lib/python3.6/dist-packages/django/template/base.py", line 849, in _resolve_lookup
    current = current[int(bit)]
ValueError: invalid literal for int() with base 10: 'required'

During handling of the above exception, another exception occurred:

Traceback (most recent call last):
  File "/usr/local/lib/python3.6/dist-packages/django/template/base.py", line 856, in _resolve_lookup
    (bit, current))  # missing attribute
django.template.base.VariableDoesNotExist: Failed lookup for key [required] in {'type': 'string', 'description': 'Address or hostname to access via RESTCONF'}
[2021-09-05 22:11:49.394 DEBUG                    django.template : 878]
Exception while resolving variable 'label' in template 'ysdevices/device_form.html'.
Traceback (most recent call last):
  File "/usr/local/lib/python3.6/dist-packages/django/template/base.py", line 835, in _resolve_lookup
    current = current[bit]
KeyError: 'label'

During handling of the above exception, another exception occurred:

Traceback (most recent call last):
  File "/usr/local/lib/python3.6/dist-packages/django/template/base.py", line 843, in _resolve_lookup
    current = getattr(current, bit)
AttributeError: 'dict' object has no attribute 'label'

During handling of the above exception, another exception occurred:

Traceback (most recent call last):
  File "/usr/local/lib/python3.6/dist-packages/django/template/base.py", line 849, in _resolve_lookup
    current = current[int(bit)]
ValueError: invalid literal for int() with base 10: 'label'

During handling of the above exception, another exception occurred:

Traceback (most recent call last):
  File "/usr/local/lib/python3.6/dist-packages/django/template/base.py", line 856, in _resolve_lookup
    (bit, current))  # missing attribute
django.template.base.VariableDoesNotExist: Failed lookup for key [label] in {'type': 'string', 'description': 'Address or hostname to access via RESTCONF'}
[2021-09-05 22:11:49.394 DEBUG                    django.template : 878]
Exception while resolving variable 'required' in template 'ysdevices/device_form.html'.
Traceback (most recent call last):
  File "/usr/local/lib/python3.6/dist-packages/django/template/base.py", line 835, in _resolve_lookup
    current = current[bit]
KeyError: 'required'

During handling of the above exception, another exception occurred:

Traceback (most recent call last):
  File "/usr/local/lib/python3.6/dist-packages/django/template/base.py", line 843, in _resolve_lookup
    current = getattr(current, bit)
AttributeError: 'dict' object has no attribute 'required'

During handling of the above exception, another exception occurred:

Traceback (most recent call last):
  File "/usr/local/lib/python3.6/dist-packages/django/template/base.py", line 849, in _resolve_lookup
    current = current[int(bit)]
ValueError: invalid literal for int() with base 10: 'required'

During handling of the above exception, another exception occurred:

Traceback (most recent call last):
  File "/usr/local/lib/python3.6/dist-packages/django/template/base.py", line 856, in _resolve_lookup
    (bit, current))  # missing attribute
django.template.base.VariableDoesNotExist: Failed lookup for key [required] in {'type': 'string', 'description': 'Address or hostname to access via RESTCONF'}
[2021-09-05 22:11:49.394 DEBUG                    django.template : 878]
Exception while resolving variable 'min' in template 'ysdevices/device_form.html'.
Traceback (most recent call last):
  File "/usr/local/lib/python3.6/dist-packages/django/template/base.py", line 835, in _resolve_lookup
    current = current[bit]
KeyError: 'min'

During handling of the above exception, another exception occurred:

Traceback (most recent call last):
  File "/usr/local/lib/python3.6/dist-packages/django/template/base.py", line 843, in _resolve_lookup
    current = getattr(current, bit)
AttributeError: 'dict' object has no attribute 'min'

During handling of the above exception, another exception occurred:

Traceback (most recent call last):
  File "/usr/local/lib/python3.6/dist-packages/django/template/base.py", line 849, in _resolve_lookup
    current = current[int(bit)]
ValueError: invalid literal for int() with base 10: 'min'

During handling of the above exception, another exception occurred:

Traceback (most recent call last):
  File "/usr/local/lib/python3.6/dist-packages/django/template/base.py", line 856, in _resolve_lookup
    (bit, current))  # missing attribute
django.template.base.VariableDoesNotExist: Failed lookup for key [min] in {'type': 'string', 'description': 'Username to access the device via RESTCONF', 'minLength': 1, 'maxLength': 50}
[2021-09-05 22:11:49.395 DEBUG                    django.template : 878]
Exception while resolving variable 'max' in template 'ysdevices/device_form.html'.
Traceback (most recent call last):
  File "/usr/local/lib/python3.6/dist-packages/django/template/base.py", line 835, in _resolve_lookup
    current = current[bit]
KeyError: 'max'

During handling of the above exception, another exception occurred:

Traceback (most recent call last):
  File "/usr/local/lib/python3.6/dist-packages/django/template/base.py", line 843, in _resolve_lookup
    current = getattr(current, bit)
AttributeError: 'dict' object has no attribute 'max'

During handling of the above exception, another exception occurred:

Traceback (most recent call last):
  File "/usr/local/lib/python3.6/dist-packages/django/template/base.py", line 849, in _resolve_lookup
    current = current[int(bit)]
ValueError: invalid literal for int() with base 10: 'max'

During handling of the above exception, another exception occurred:

Traceback (most recent call last):
  File "/usr/local/lib/python3.6/dist-packages/django/template/base.py", line 856, in _resolve_lookup
    (bit, current))  # missing attribute
django.template.base.VariableDoesNotExist: Failed lookup for key [max] in {'type': 'string', 'description': 'Username to access the device via RESTCONF', 'minLength': 1, 'maxLength': 50}
[2021-09-05 22:11:49.395 DEBUG                    django.template : 878]
Exception while resolving variable 'step' in template 'ysdevices/device_form.html'.
Traceback (most recent call last):
  File "/usr/local/lib/python3.6/dist-packages/django/template/base.py", line 835, in _resolve_lookup
    current = current[bit]
KeyError: 'step'

During handling of the above exception, another exception occurred:

Traceback (most recent call last):
  File "/usr/local/lib/python3.6/dist-packages/django/template/base.py", line 843, in _resolve_lookup
    current = getattr(current, bit)
AttributeError: 'dict' object has no attribute 'step'

During handling of the above exception, another exception occurred:

Traceback (most recent call last):
  File "/usr/local/lib/python3.6/dist-packages/django/template/base.py", line 849, in _resolve_lookup
    current = current[int(bit)]
ValueError: invalid literal for int() with base 10: 'step'

During handling of the above exception, another exception occurred:

Traceback (most recent call last):
  File "/usr/local/lib/python3.6/dist-packages/django/template/base.py", line 856, in _resolve_lookup
    (bit, current))  # missing attribute
django.template.base.VariableDoesNotExist: Failed lookup for key [step] in {'type': 'string', 'description': 'Username to access the device via RESTCONF', 'minLength': 1, 'maxLength': 50}
[2021-09-05 22:11:49.395 DEBUG                    django.template : 878]
Exception while resolving variable 'default' in template 'ysdevices/device_form.html'.
Traceback (most recent call last):
  File "/usr/local/lib/python3.6/dist-packages/django/template/base.py", line 835, in _resolve_lookup
    current = current[bit]
KeyError: 'default'

During handling of the above exception, another exception occurred:

Traceback (most recent call last):
  File "/usr/local/lib/python3.6/dist-packages/django/template/base.py", line 843, in _resolve_lookup
    current = getattr(current, bit)
AttributeError: 'dict' object has no attribute 'default'

During handling of the above exception, another exception occurred:

Traceback (most recent call last):
  File "/usr/local/lib/python3.6/dist-packages/django/template/base.py", line 849, in _resolve_lookup
    current = current[int(bit)]
ValueError: invalid literal for int() with base 10: 'default'

During handling of the above exception, another exception occurred:

Traceback (most recent call last):
  File "/usr/local/lib/python3.6/dist-packages/django/template/base.py", line 856, in _resolve_lookup
    (bit, current))  # missing attribute
django.template.base.VariableDoesNotExist: Failed lookup for key [default] in {'type': 'string', 'description': 'Username to access the device via RESTCONF', 'minLength': 1, 'maxLength': 50}
[2021-09-05 22:11:49.395 DEBUG                    django.template : 878]
Exception while resolving variable 'default' in template 'ysdevices/device_form.html'.
Traceback (most recent call last):
  File "/usr/local/lib/python3.6/dist-packages/django/template/base.py", line 835, in _resolve_lookup
    current = current[bit]
KeyError: 'default'

During handling of the above exception, another exception occurred:

Traceback (most recent call last):
  File "/usr/local/lib/python3.6/dist-packages/django/template/base.py", line 843, in _resolve_lookup
    current = getattr(current, bit)
AttributeError: 'dict' object has no attribute 'default'

During handling of the above exception, another exception occurred:

Traceback (most recent call last):
  File "/usr/local/lib/python3.6/dist-packages/django/template/base.py", line 849, in _resolve_lookup
    current = current[int(bit)]
ValueError: invalid literal for int() with base 10: 'default'

During handling of the above exception, another exception occurred:

Traceback (most recent call last):
  File "/usr/local/lib/python3.6/dist-packages/django/template/base.py", line 856, in _resolve_lookup
    (bit, current))  # missing attribute
django.template.base.VariableDoesNotExist: Failed lookup for key [default] in {'type': 'string', 'description': 'Username to access the device via RESTCONF', 'minLength': 1, 'maxLength': 50}
[2021-09-05 22:11:49.395 DEBUG                    django.template : 878]
Exception while resolving variable 'required' in template 'ysdevices/device_form.html'.
Traceback (most recent call last):
  File "/usr/local/lib/python3.6/dist-packages/django/template/base.py", line 835, in _resolve_lookup
    current = current[bit]
KeyError: 'required'

During handling of the above exception, another exception occurred:

Traceback (most recent call last):
  File "/usr/local/lib/python3.6/dist-packages/django/template/base.py", line 843, in _resolve_lookup
    current = getattr(current, bit)
AttributeError: 'dict' object has no attribute 'required'

During handling of the above exception, another exception occurred:

Traceback (most recent call last):
  File "/usr/local/lib/python3.6/dist-packages/django/template/base.py", line 849, in _resolve_lookup
    current = current[int(bit)]
ValueError: invalid literal for int() with base 10: 'required'

During handling of the above exception, another exception occurred:

Traceback (most recent call last):
  File "/usr/local/lib/python3.6/dist-packages/django/template/base.py", line 856, in _resolve_lookup
    (bit, current))  # missing attribute
django.template.base.VariableDoesNotExist: Failed lookup for key [required] in {'type': 'string', 'description': 'Username to access the device via RESTCONF', 'minLength': 1, 'maxLength': 50}
[2021-09-05 22:11:49.396 DEBUG                    django.template : 878]
Exception while resolving variable 'required' in template 'ysdevices/device_form.html'.
Traceback (most recent call last):
  File "/usr/local/lib/python3.6/dist-packages/django/template/base.py", line 835, in _resolve_lookup
    current = current[bit]
KeyError: 'required'

During handling of the above exception, another exception occurred:

Traceback (most recent call last):
  File "/usr/local/lib/python3.6/dist-packages/django/template/base.py", line 843, in _resolve_lookup
    current = getattr(current, bit)
AttributeError: 'dict' object has no attribute 'required'

During handling of the above exception, another exception occurred:

Traceback (most recent call last):
  File "/usr/local/lib/python3.6/dist-packages/django/template/base.py", line 849, in _resolve_lookup
    current = current[int(bit)]
ValueError: invalid literal for int() with base 10: 'required'

During handling of the above exception, another exception occurred:

Traceback (most recent call last):
  File "/usr/local/lib/python3.6/dist-packages/django/template/base.py", line 856, in _resolve_lookup
    (bit, current))  # missing attribute
django.template.base.VariableDoesNotExist: Failed lookup for key [required] in {'type': 'string', 'description': 'Username to access the device via RESTCONF', 'minLength': 1, 'maxLength': 50}
[2021-09-05 22:11:49.396 DEBUG                    django.template : 878]
Exception while resolving variable 'label' in template 'ysdevices/device_form.html'.
Traceback (most recent call last):
  File "/usr/local/lib/python3.6/dist-packages/django/template/base.py", line 835, in _resolve_lookup
    current = current[bit]
KeyError: 'label'

During handling of the above exception, another exception occurred:

Traceback (most recent call last):
  File "/usr/local/lib/python3.6/dist-packages/django/template/base.py", line 843, in _resolve_lookup
    current = getattr(current, bit)
AttributeError: 'dict' object has no attribute 'label'

During handling of the above exception, another exception occurred:

Traceback (most recent call last):
  File "/usr/local/lib/python3.6/dist-packages/django/template/base.py", line 849, in _resolve_lookup
    current = current[int(bit)]
ValueError: invalid literal for int() with base 10: 'label'

During handling of the above exception, another exception occurred:

Traceback (most recent call last):
  File "/usr/local/lib/python3.6/dist-packages/django/template/base.py", line 856, in _resolve_lookup
    (bit, current))  # missing attribute
django.template.base.VariableDoesNotExist: Failed lookup for key [label] in {'type': 'string', 'description': 'Username to access the device via RESTCONF', 'minLength': 1, 'maxLength': 50}
[2021-09-05 22:11:49.396 DEBUG                    django.template : 878]
Exception while resolving variable 'required' in template 'ysdevices/device_form.html'.
Traceback (most recent call last):
  File "/usr/local/lib/python3.6/dist-packages/django/template/base.py", line 835, in _resolve_lookup
    current = current[bit]
KeyError: 'required'

During handling of the above exception, another exception occurred:

Traceback (most recent call last):
  File "/usr/local/lib/python3.6/dist-packages/django/template/base.py", line 843, in _resolve_lookup
    current = getattr(current, bit)
AttributeError: 'dict' object has no attribute 'required'

During handling of the above exception, another exception occurred:

Traceback (most recent call last):
  File "/usr/local/lib/python3.6/dist-packages/django/template/base.py", line 849, in _resolve_lookup
    current = current[int(bit)]
ValueError: invalid literal for int() with base 10: 'required'

During handling of the above exception, another exception occurred:

Traceback (most recent call last):
  File "/usr/local/lib/python3.6/dist-packages/django/template/base.py", line 856, in _resolve_lookup
    (bit, current))  # missing attribute
django.template.base.VariableDoesNotExist: Failed lookup for key [required] in {'type': 'string', 'description': 'Username to access the device via RESTCONF', 'minLength': 1, 'maxLength': 50}
[2021-09-05 22:11:49.397 DEBUG                    django.template : 878]
Exception while resolving variable 'min' in template 'ysdevices/device_form.html'.
Traceback (most recent call last):
  File "/usr/local/lib/python3.6/dist-packages/django/template/base.py", line 835, in _resolve_lookup
    current = current[bit]
KeyError: 'min'

During handling of the above exception, another exception occurred:

Traceback (most recent call last):
  File "/usr/local/lib/python3.6/dist-packages/django/template/base.py", line 843, in _resolve_lookup
    current = getattr(current, bit)
AttributeError: 'dict' object has no attribute 'min'

During handling of the above exception, another exception occurred:

Traceback (most recent call last):
  File "/usr/local/lib/python3.6/dist-packages/django/template/base.py", line 849, in _resolve_lookup
    current = current[int(bit)]
ValueError: invalid literal for int() with base 10: 'min'

During handling of the above exception, another exception occurred:

Traceback (most recent call last):
  File "/usr/local/lib/python3.6/dist-packages/django/template/base.py", line 856, in _resolve_lookup
    (bit, current))  # missing attribute
django.template.base.VariableDoesNotExist: Failed lookup for key [min] in {'type': 'password', 'description': 'Password to access the device via RESTCONF', 'minLength': 1, 'maxLength': 50}
[2021-09-05 22:11:49.397 DEBUG                    django.template : 878]
Exception while resolving variable 'max' in template 'ysdevices/device_form.html'.
Traceback (most recent call last):
  File "/usr/local/lib/python3.6/dist-packages/django/template/base.py", line 835, in _resolve_lookup
    current = current[bit]
KeyError: 'max'

During handling of the above exception, another exception occurred:

Traceback (most recent call last):
  File "/usr/local/lib/python3.6/dist-packages/django/template/base.py", line 843, in _resolve_lookup
    current = getattr(current, bit)
AttributeError: 'dict' object has no attribute 'max'

During handling of the above exception, another exception occurred:

Traceback (most recent call last):
  File "/usr/local/lib/python3.6/dist-packages/django/template/base.py", line 849, in _resolve_lookup
    current = current[int(bit)]
ValueError: invalid literal for int() with base 10: 'max'

During handling of the above exception, another exception occurred:

Traceback (most recent call last):
  File "/usr/local/lib/python3.6/dist-packages/django/template/base.py", line 856, in _resolve_lookup
    (bit, current))  # missing attribute
django.template.base.VariableDoesNotExist: Failed lookup for key [max] in {'type': 'password', 'description': 'Password to access the device via RESTCONF', 'minLength': 1, 'maxLength': 50}
[2021-09-05 22:11:49.397 DEBUG                    django.template : 878]
Exception while resolving variable 'step' in template 'ysdevices/device_form.html'.
Traceback (most recent call last):
  File "/usr/local/lib/python3.6/dist-packages/django/template/base.py", line 835, in _resolve_lookup
    current = current[bit]
KeyError: 'step'

During handling of the above exception, another exception occurred:

Traceback (most recent call last):
  File "/usr/local/lib/python3.6/dist-packages/django/template/base.py", line 843, in _resolve_lookup
    current = getattr(current, bit)
AttributeError: 'dict' object has no attribute 'step'

During handling of the above exception, another exception occurred:

Traceback (most recent call last):
  File "/usr/local/lib/python3.6/dist-packages/django/template/base.py", line 849, in _resolve_lookup
    current = current[int(bit)]
ValueError: invalid literal for int() with base 10: 'step'

During handling of the above exception, another exception occurred:

Traceback (most recent call last):
  File "/usr/local/lib/python3.6/dist-packages/django/template/base.py", line 856, in _resolve_lookup
    (bit, current))  # missing attribute
django.template.base.VariableDoesNotExist: Failed lookup for key [step] in {'type': 'password', 'description': 'Password to access the device via RESTCONF', 'minLength': 1, 'maxLength': 50}
[2021-09-05 22:11:49.397 DEBUG                    django.template : 878]
Exception while resolving variable 'default' in template 'ysdevices/device_form.html'.
Traceback (most recent call last):
  File "/usr/local/lib/python3.6/dist-packages/django/template/base.py", line 835, in _resolve_lookup
    current = current[bit]
KeyError: 'default'

During handling of the above exception, another exception occurred:

Traceback (most recent call last):
  File "/usr/local/lib/python3.6/dist-packages/django/template/base.py", line 843, in _resolve_lookup
    current = getattr(current, bit)
AttributeError: 'dict' object has no attribute 'default'

During handling of the above exception, another exception occurred:

Traceback (most recent call last):
  File "/usr/local/lib/python3.6/dist-packages/django/template/base.py", line 849, in _resolve_lookup
    current = current[int(bit)]
ValueError: invalid literal for int() with base 10: 'default'

During handling of the above exception, another exception occurred:

Traceback (most recent call last):
  File "/usr/local/lib/python3.6/dist-packages/django/template/base.py", line 856, in _resolve_lookup
    (bit, current))  # missing attribute
django.template.base.VariableDoesNotExist: Failed lookup for key [default] in {'type': 'password', 'description': 'Password to access the device via RESTCONF', 'minLength': 1, 'maxLength': 50}
